Workbook

Sheet PMR-Data
A2: MONTH | B2: (Multiple Items)
A3: YEAR | B3: (Multiple Items)
A5: PR# | B5: Purpose | C5: End-User | D5: Modality | E5: Delivery Date | F5: IAR Date | G5: Fund Code | H5: Class | I5: Status | J5: Sum of Estimated Total | K5: Sum of Total
A6: 202-013A | B6: supplies for the repair & maintenance of the building | C6: JERSHON RALPH F. CASTANO | D6: SVP | E6: August 23, 2021 | F6: August 23, 2021 | G6: 101 | H6: MOOE | I6: complete | J6: 85520 | K6: 65665
A7: 2021-001A | B7: snacks for the "Internal Quality Audit" on January 19-21, 2021 | J7: 17850 | K7: 17850
A8: 2021-002 | B8: Supply and installation of CCTV for Academic Building, Dormitory and Agriculture Building | C8: ALETH A. MEORA | D8: SVP | E8: April 27, 2021 | F8: May 26, 2021` | G8: 101 | H8: CO | I8: complete | J8: 435000 | K8: 397860
A9: 2021-002A | B9: to be used in the different activities and internet communication needs of BSC | C9: RANDALL G. CASTILLO | D9: SVP | E9: 5/19 & 7/19/2021 | F9: 5/26 & 7/21/2021 | G9: 101 | H9: (blank) | I9: complete | J9: 25500 | K9: 25480
A10: 2021-003 | B10: Purchase of Academic Equipment | C10: ALETH A. MEORA | D10: SVP | E10: 5/19 & 7/19/2021 | F10: 5/19 & 7/21/2021 | G10: 101 | H10: CO | I10: complete | J10: 947218.62 | K10: 928620
A11: 2021-003A | B11: for PBB compliance specifically transparency seal and BSC publication | C11: RANDALL G. CASTILLO | D11: SVP | E11: February 16, 2021 | F11: March 2, 2021 | G11: 165 | H11: MOOE | I11: complete | J11: 49000 | K11: 45560
A12: 2021-004 | B12: for the purchase of Academic Equipments | C12: ALETH A. MEORA | D12: SVP | E12: January 12, 2021 | F12: April 27, 2021 | G12: 101 | H12: CO | I12: complete | J12: 972105.5 | K12: 791000
A13: 2021-004A | B13: for the purchase of enrollment forms | C13: RHEA ANGELLICA B. ADDATU | D13: SVP | E13: August 23, 2021 | F13: August 23, 2021 | G13: 101 | H13: (blank) | I13: (blank) | J13: 22500 | K13: 22500
A14: 2021-005 | B14: Purchase of Academic Equipment | C14: ALETH A. MEORA | D14: SVP | E14: 44396 | F14: 44403 | G14: 101 | H14: CO | I14: reimbursement | J14: 378961.7 | K14: 359780
A15: 2021-005A | B15: to be used in the different activities and internet communication needs of BSC | C15: RANDALL G. CASTILLO | D15: SVP | E15: May 19, 2021 | F15: May 26, 2021 | G15: 101 | H15: MOOE | I15: complete | J15: 30250 | K15: 29960
A16: 2021-006 | B16: Supply and Delivery of Academic Equipment | C16: ALETH A. MEORA | D16: SVP | E16: January 12, 2021 | F16: January 25, 2021 | G16: 101 | H16: CO | I16: complete | J16: 315813.75 | K16: 195700
E17: January 25, 2021 | F17: January 25, 2021 | G17: 101 | H17: CO | I17: complete | J17: 45000 | K17: 42000
A18: 2021-006A | B18: for the ISO Activity Management Review on Feb. 3, 2021 | C18: ROMINA KATRINA C. BAYARAS | D18: SVP | E18: 44230 | F18: February 16, 2021 | G18: 164 | H18: MOOE | I18: complete | J18: 14000 | K18: 11800
A19: 2021-007A | B19: Internet data/Regular load Allocation of Administrative & Finance staff of the college to support online submission of reports & other related activities for the Fiscal Year 2021 | C19: DJOVI R. DURANTE | D19: SVP | E19: March 29, 2021 | F19: March 31, 2021 | G19: 101 | H19: MOOE | I19: complete | J19: 107880 | K19: 107880
A20: 2021-008A | B20: for the "ISO Documentation" | C20: ROMINA KATRINA C. BAYARAS | D20: SVP | E20: March 15, 2021 | F20: March 15, 2021 | G20: 164 | H20: MOOE | I20: complete | J20: 3960 | K20: 3885
A21: 2021-009 | B21: Purchase of Academic Furniture Fixtures | C21: ALETH A. MEORA | D21: SVP | E21: August 23, 2021 | F21: August 23, 2021 | G21: 101 | H21: MOOE | I21: complete | J21: 200000 | K21: 199680
A22: 2021-009A | B22: stamp use for the filing of ISO documents | C22: ROMINA KATRINA C. BAYARAS | D22: SVP | E22: - | F22: - | G22: 165 | H22: (blank) | I22: FAILED | J22: 28000 | K22: 0
A23: 2021-0100 | B23: for the Implementation of "ADOPT through Varied R & D of Ivatan Endemic Resources" research project | C23: JANE S. CASTILLO | D23: SVP | E23: August 23, 2021 | F23: August 23, 2021 | G23: 165 | H23: MOOE | I23: for delivery | J23: 30950 | K23: 29315
A24: 2021-0101 | B24: office supplies for the Administrative & Finance Services Units | C24: DJOVI R. DURANTE | D24: SVP | E24: August 23, 2021 | F24: August 23, 2021 | G24: 165 | H24: MOOE | I24: for delivery | J24: 30840 | K24: 28941.9
A25: 2021-0102 | B25: supplies for Budget office | C25: BRYAN DAVE P. REVILLA | D25: SVP | E25: August 23, 2021 | F25: August 23, 2021 | G25: 101 | H25: MOOE | I25: for delivery | J25: 3500 | K25: 2990
A26: 2021-0103 | B26: supplies for Budget office | C26: BRYAN DAVE P. REVILLA | D26: SVP | E26: July 1, 2021 | F26: July 1, 2021 | G26: 101 | H26: MOOE | I26: complete | J26: 790 | K26: 600
A27: 2021-0104 | B27: supplies for the Budget office | C27: BRYAN DAVE P. REVILLA | D27: SVP | E27: August 23, 2021 | F27: August 23, 2021 | G27: 101 | H27: MOOE | I27: for delivery | J27: 1000 | K27: 800
A28: 2021-0105 | B28: repair of 2 units floor type airconditioner at Faculty Room | C28: JERSHON RALPH F. CASTANO | D28: SVP | E28: August 23, 2021 | F28: August 23, 2021 | G28: (blank) | H28: (blank) | I28: FAILED | J28: 13000
A29: 2021-0106 | B29: GSO Supplies | C29: JERSHON RALPH F. CASTANO | D29: SVP | E29: July 19 & 26, 2021 | F29: July 21 & 26, 2021 | G29: 101 | H29: MOOE | I29: complete | J29: 10950 | K29: 8314
A30: 2021-0107 | B30: GSO Supplies | C30: JERSHON RALPH F. CASTANO | D30: SVP | E30: 44399 | F30: 44411 | G30: 101 | H30: MOOE | I30: reimbursement | J30: 18500 | K30: 15780
A31: 2021-0108 | B31: Snack for the Preparatory Board Meeting on June 25, 2021 at 10:00 a.m | C31: GERZON R. ABAD | D31: SVP | E31: August 23, 2021 | F31: August 23, 2021 | G31: (blank) | H31: (blank) | I31: FAILED | J31: 3000 | K31: 0
A32: 2021-0109 | B32: PM snack and dinner for the 52nd Board of Trustees Meeting on June 25, 2021 | C32: GERZON R. ABAD | D32: SVP | E32: June 25, 2021 | F32: 44377 | G32: 101 | H32: MOOE | I32: reimbursement | J32: 13000 | K32: 9000
A33: 2021-010A | B33: ink use for enrollment | C33: RHEA ANGELLICA B. ADDATU | D33: SVP | E33: August 23, 2021 | F33: August 23, 2021 | G33: 101 | H33: (blank) | I33: FAILED | J33: 1500
A34: 2021-0110 | B34: Lunch, PM Snack and Dinner of Commissioner Lilian A. De Las Llagas and Staff for the 52nd BOT Meeting on 25 June 2021 | C34: GERZON R. ABAD | D34: SVP | E34: August 23, 2021 | F34: August 23, 2021 | G34: (blank) | H34: (blank) | I34: reimbursement | J34: 12597.5 | K34: 12597.5
A35: 2021-0111 | B35: repair & maintenance of A/C units of Registrar's, Cashier's, Accountant's & President's office | C35: JERSHON RALPH F. CASATANO | D35: SVP | E35: August 23, 2021 | F35: August 23, 2021 | G35: 101 | H35: MOOE | I35: on-going | J35: 8000 | K35: 8000
A36: 2021-0112 | B36: supplies for the rewiring of faculty room electrical system | C36: JERSHON RALPH F. CASATANO | D36: SVP | E36: July 21, 2021 | F36: July 26, 2021 | G36: 101 | H36: MOOE | I36: complete | J36: 23700 | K36: 21624
A37: 2021-0113 | B37: for the purchase of Semi-expendable equipments purposes | C37: JERSHON RALPH F. CASATANO | D37: SVP | E37: August 23, 2021 | F37: August 23, 2021 | G37: 101 | H37: MOOE | I37: on-going | J37: 10000 | K37: 10000
A38: 2021-011A | B38: for the Pre Assessment Audit Plan on Feb. 10-11, 2021 | C38: ROMINA KATRINA C. BAYARAS | D38: SVP | E38: February 10-11, 2021 | F38: March 2, 2021 | G38: 164 | H38: MOOE | I38: complete | J38: 7500 | K38: 7125
A39: 2021-012A | B39: supplies for the repair & maintenance of transportation vehicle | C39: JERSHON RALPH F. CASTANO | D39: SVP | E39: March 31, 2021 | F39: April 5, 2021 | G39: 101 | H39: MOOE | I39: on-going | J39: 49399.99 | K39: 42550
A40: 2021-013 | B40: Puchase of drafting tables and chairs for the Academiic Furnitures and Fixtures | C40: ALETH A. MEORA | D40: SVP | E40: January 26, 2021 | F40: January 26, 2021 | G40: 101 | H40: CO | I40: complete | J40: 277500 | K40: 195000
A41: 2021-014A | B41: office machinery & equipment | C41: JERSHON RALPH F. CASTANO | D41: SVP | E41: March 29, 2021 | F41: March 30, 2021 | G41: 101 | H41: MOOE | I41: complete | J41: 47002 | K41: 42500
A42: 2021-015A | B42: supplies for janitorial services | C42: JERSHON RALPH F. CASTANO | D42: SVP | E42: April 15, 2021 | F42: April 15, 2021 | G42: 101 | H42: MOOE | I42: complete | J42: 5000 | K42: 3000
...

Sheet Suppliers TIN
B1: Business Name | C1: Name/Owner | D1: TIN #
A2: 1 | B2: Apostol General Merchandise | C2: Leo A. Apostol | D2: 183-008-448
A3: 2 | B3: Bartilad's Feeds Trading | C3: Roldan Q. Bartilad | D3: 771-272-422
A4: 3 | B4: Bitstop Network Services Inc. | C4: JC James P. Jihay | D4: 005-931-291
A5: 4 | B5: Casa Del Basco | D5: 107-549-729
A6: 5 | B6: Crisel General Merchandise | C6: Cresencio M. Verana | D6: 135-792-662
A7: 6 | B7: Claire's Drugstore | C7: Claire H. Abad | D7: 264-438-671
A8: 7 | B8: Davocol's General Merchandise | C8: Lilibeth T. Davocol | D8: 116-311-342
A9: 8 | B9: Davocol's Inn | C9: Dan Ardie T. Davocol | D9: 739-884-154
A10: 9 | B10: D' Islands Gasoline Station | C10: Lito Doroteo A. Adarme | D10: 124-072-664
A11: 10 | B11: Doque's Congie Hauz | C11: Glenda L. Gordo | D11: 922-904-311
A12: 11 | B12: D. Michael Co Industrial Supply (DMC) Corp. | C12: Eunelyn O. Ramilla | D12: 007-776-953
A13: 12 | B13: E. A. Amboy General Merchandise | C13: Cesar Edgardo Amboy | D13: 928-655-269
A14: 13 | B14: Enrinar Trading | C14: Narcisa Co Melad | D14: 123-394-221
A15: 14 | B15: FMG Trading & Construction Supply | C15: Frederick Gari | D15: 219-884-940
A16: 15 | B16: GDP Trading | C16: George D. Peralta | D16: 150-214-534
A17: 16 | B17: Hubalde's Drugstore | C17: Marilyn G. Hubalde | D17: 914-979-941
A18: 17 | B18: Hudzan Café & Catering Services | C18: Susan Villegas | D18: 290-315-057 | E18: **
A19: 18 | B19: I.B.S Pharmacy & General Merchadise | C19: Dale Anthony C. Gutierrez | D19: 411-599-160
A20: 19 | B20: IAM'J Graphic Design & Printing | C20: Jaycy S. Alina | D20: 318-666-833
A21: 20 | B21: JPM General Merchandise & Hardware | C21: Emma P. Adarme | D21: 160-183-814
A22: 21 | B22: J-Tech Trading & Services | C22: Cecilia C. De Sagon | D22: 933-429-635
A23: 22 | B23: M.G. Hubalde's General Merchandise | C23: Marilyn G. Hubalde | D23: 914-979-941-001
A24: 23 | B24: MDAC Trading & Compuserve | C24: Florescita A. Cruz | D24: 100-194-776
A25: 24 | B25: NRA Hardware | C25: Neil Bernardo Ordas | D25: 196-062-499
A26: 25 | B26: One-Touch Technology Trading | C26: Janice A. Alasco | D26: 283-009-327
A27: 26 | B27: Pension Ivatan | C27: Teresita D. Valiente | D27: 106-115-883
A28: 27 | B28: Sophia Marie Store | C28: Regina B. Gabaldon | D28: 279-057-542
A29: 28 | B29: Twixbiz General Merchandise | C29: Charles B. Domingo | D29: 118-687-531
A30: 29 | B30: Northern Star General Merchandise | C30: Cesar A. Calma | D30: 151-407-774
... A37: 36 | B37: MKM Hardware | C37: Enrique Abuyo Melad Jr. | D37: 148-780-907
A38: 37 | B38: NSGB Books Trading | C38: Nica Sandra Go Banag
A39: 38 | B39: ONPREM2CLOUD IT SOLUTIONS CO. | C39: Emmanuel B. Mamayson | D39: 101-626-582
A40: 39 | B40: Petonio's Kitchen Food Services | C40: Ramona C. Tabuso | D40: 013-000-080-045-720-21
A41: 40 | B41: Tiger Consulting and Software Devt Inc. | D41: 007-073-548
A42: 41 | B42: MOJR Construction Trading & General Services, Ltd, Co. | C42: Manuel S. Obedoza Jr.
A43: 42 | B43: Batanes Electric Cooperative Inc. | C43: Victoria A. Mata | D43: 005-641-216-000
A44: 43 | B44: Maddies Fashion Design Services | C44: Madeline Palencia Palustre
A45: 44 | B45: CMVILL Trading | C45: Zariffe G. Villanueva | D45: 421-603-862-000
A46: 45 | B46: VL Mini Canteen | C46: Estela N. Lizardo | D46: 930-779-799
...

Sheet FundCodes
A1: CODE | B1: CATEGORY | C1: OFFICE/UNIT
A2: GAS1 | B2: General Administration Services | C2: Office of the President
A3: GAS2 | B3: General Administration Services | C3: Office of the Board Secretary
A4: GAS3 | B4: General Administration Services | C4: Office of the College Secretary | G4: Fund
A5: GAS4 | B5: General Administration Services | C5: Information & Communications Technology Unit | G5: 01-101
A6: GAS5 | B6: General Administration Services | C6: Information Unit | G6: 05-164
A7: GAS6 | B7: General Administration Services | C7: Internal Audit Unit | G7: 06-162
A8: GAS7 | B8: General Administration Services | C8: Legal Unit | G8: 07-165
A9: GAS8 | B9: General Administration Services | C9: Planning Unit
A10: GAS9 | B10: General Administration Services | C10: Project Management Unit
A11: GAS10 | B11: General Administration Services | C11: Quality Assurance Office
A12: GAS11 | B12: General Administration Services | C12: Administrative Office
A13: GAS12 | B13: General Administration Services | C13: Cash Unit
A14: GAS13 | B14: General Administration Services | C14: General Services Unit
A15: GAS14 | B15: General Administration Services | C15: Human Resource Management Unit
A16: GAS15 | B16: General Administration Services | C16: Procurement Unit
A17: GAS16 | B17: General Administration Services | C17: Records Unit
A18: GAS17 | B18: General Administration Services | C18: Supply & Property Management Unit
A19: GAS18 | B19: General Administration Services | C19: Accounting Unit
A20: GAS19 | B20: General Administration Services | C20: Budget Unit
... A45: Acad9 | B45: Director for Instruction | C45: DI
A46: 1005 | B46: Research & Extension Services | C46: Research & Extension Office
A47: 1006 | B47: Business Affairs Office | C47: CBAO
A48: 1006A | B48: College Assessment Center | C48: CAC
A49: 1006B | B49: College Business Affairs Office | C49: CBAO-IGP
A50: 1006C | B50: College Business Affairs Office | C50: CBAO-Dorm
A51: 1006D | B51: College Business Affairs Office | C51: CBAO-Hostel

Sheet DATA
A1: YEAR | B1: MONTH | C1: End-User | D1: Position/Designation | E1: Fund Code | F1: Class | G1: PR# | H1: Modality | I1: Item | J1: Qty | K1: Unit of Issue | L1: Unit Budget | M1: Estimated Total | N1: Unit LCRB | O1: Total | P1: Purpose | Q1: Office | R1: Date of LON | S1: Date of BAC Award | T1: PO/Contract Date | U1: PO/Contract Date Received | V1: Delivery Date | W1: Supplier | X1: IAR Date | Y1: Section Code/Dept. | Z1: Released Date | AA1: Status | AB1: Remarks | AC1: ObR # | AD1: # of RFQ's printed | AE1: Sales/Charge Invoice/Billing
A2: 2025 | B2: October | C2: ALFRED VINCENT D. BACCAY | D2: SSC President | G2: 2025-347 | I2: Wooden Plaque | J2: 4 | K2: pcs | L2: 1000 | M2: =SUM(J2*L2) -> 4000 | N2: 1000 | O2: =SUM(J2*N2) -> 4000 | P2: "A Tribute to our Teachers: Guiding BSCians, Building a Brighter Tomorrow | Q2: SSC | R2: October 20, 2025 | S2: October 22, 2025 | T2: October 22, 2025 | W2: SKE Souvenir Trading | Y2: SS09 | AD2: 3 RFQ's
A3: 2025 | B3: October | C3: ALFRED VINCENT D. BACCAY | D3: SSC President | E3: 165 | G3: 2025-348 | I3: Specialty Paper, A4 | J3: 20 | K3: ballots | L3: 150 | M3: =SUM(J3*L3) -> 3000 | N3: 65 | O3: =SUM(J3*N3) -> 1300 | P3: "A Tribute to our Teachers: Guiding BSCians, Building a Brighter Tomorrow | Q3: SSC | R3: October 7, 2025 | S3: October 13, 2025 | T3: October 14, 2025 | U3: October 16, 2026 | W3: JPM General Merchandise & Hardware | X3: March 3, 2026 | Y3: SS09 | Z3: March 10, 2026 | AA3: complete | AB3: for payment-Acctg. | AC3: 07-02-2025-10-0363 | AD3: 4 RFQ's | AE3: 13438/3/8/2026
A4: 2025 | B4: October | C4: JENNY S. ALINA | D4: College Nurse | E4: 165 | G4: 2025-349 | I4: Diphenhydramine 50mg/capsule | J4: 3 | K4: boxes | L4: 500 | M4: =SUM(J4*L4) -> 1500 | N4: 110 | O4: =SUM(J4*N4) -> 330 | P4: for the program/activity intended to strengthen the healthcare services of the BSC Clinic through the procurement of medicines and medical supplies | Q4: Medical-Clinic | R4: October 28, 2025 | S4: November 7, 2025 | T4: November 11, 2025 | U4: November 17, 2025 | V4: Oct. 29,Dec. 5,10 & 23, 2025 & Jan. 15, 2026 | W4: Claire's Drugstore | X4: Nov. 20,Dec. 10,& 23, 2025 & Jan. 15, 2026 | Y4: SS02 | Z4: January 27, 2026 | AA4: complete | AB4: for payment-Acctg. | AC4: 07-02-2025-11-0397A | AD4: 5 RFQ's | AE4: 0719-0721/1/13/2026
A5: 2025 | B5: October | C5: JENNY S. ALINA | D5: College Nurse | E5: 165 | G5: 2025-349 | I5: Hydrogen Peroxide 120ml | J5: 30 | K5: bottles | L5: 120 | M5: =SUM(J5*L5) -> 3600 | N5: 45 | O5: =SUM(J5*N5) -> 1350 | P5: for the program/activity intended to strengthen the healthcare services of the BSC Clinic through the procurement of medicines and medical supplies | Q5: Medical-Clinic | R5: October 28, 2025 | S5: November 7, 2025 | T5: November 11, 2025 | U5: November 17, 2025 | V5: Oct. 29,Dec. 5,10 & 23, 2025 & Jan. 15, 2026 | W5: Claire's Drugstore | X5: Nov. 20,Dec. 10,& 23, 2025 & Jan. 15, 2026 | Y5: SS02 | Z5: January 27, 2026 | AA5: complete | AB5: for payment-Acctg. | AC5: 07-02-2025-11-0397A
A6: 2025 | B6: October | C6: JENNY S. ALINA | D6: College Nurse | E6: 165 | G6: 2025-349 | I6: Paracetamol 500mg. | J6: 5 | K6: boxes (100's) | L6: 500 | M6: =SUM(J6*L6) -> 2500 | N6: 70 | O6: =SUM(J6*N6) -> 350 | P6: for the program/activity intended to strengthen the healthcare services of the BSC Clinic through the procurement of medicines and medical supplies | Q6: Medical-Clinic | R6: October 28, 2025 | S6: November 7, 2025 | T6: November 11, 2025 | U6: November 17, 2025 | V6: Oct. 29,Dec. 5,10 & 23, 2025 & Jan. 15, 2026 | W6: Claire's Drugstore | X6: Nov. 20,Dec. 10,& 23, 2025 & Jan. 15, 2026 | Y6: SS02 | Z6: January 27, 2026 | AA6: complete | AB6: for payment-Acctg. | AC6: 07-02-2025-11-0397A
A7: 2025 | B7: October | C7: JENNY S. ALINA | D7: College Nurse | E7: 165 | G7: 2025-349 | I7: Mefenamic Acid 500mg/capsule | J7: 5 | K7: boxes | L7: 1000 | M7: =SUM(J7*L7) -> 5000 | N7: 125 | O7: =SUM(J7*N7) -> 625 | P7: for the program/activity intended to strengthen the healthcare services of the BSC Clinic through the procurement of medicines and medical supplies | Q7: Medical-Clinic | R7: October 28, 2025 | S7: November 7, 2025 | T7: November 11, 2025 | U7: November 17, 2025 | V7: Oct. 29,Dec. 5,10 & 23, 2025 & Jan. 15, 2026 | W7: Claire's Drugstore | X7: Nov. 20,Dec. 10,& 23, 2025 & Jan. 15, 2026 | Y7: SS02 | Z7: January 27, 2026 | AA7: complete | AB7: for payment-Acctg. | AC7: 07-02-2025-11-0397A
A8: 2025 | B8: October | C8: JENNY S. ALINA | D8: College Nurse | E8: 165 | G8: 2025-349 | I8: Salmeterol+Fluticasone Inhaler 25mcg/125mcg metered dose inhaler | J8: 10 | K8: pcs. | L8: 650 | M8: =SUM(J8*L8) -> 6500 | N8: 400 | O8: =SUM(J8*N8) -> 4000 | P8: for the program/activity intended to strengthen the healthcare services of the BSC Clinic through the procurement of medicines and medical supplies | Q8: Medical-Clinic | R8: October 28, 2025 | S8: November 7, 2025 | T8: November 11, 2025 | U8: November 17, 2025 | V8: Oct. 29,Dec. 5,10 & 23, 2025 & Jan. 15, 2026 | W8: Claire's Drugstore | X8: Nov. 20,Dec. 10,& 23, 2025 & Jan. 15, 2026 | Y8: SS02 | Z8: January 27, 2026 | AA8: complete | AB8: for payment-Acctg. | AC8: 07-02-2025-11-0397A
A9: 2025 | B9: October | C9: JENNY S. ALINA | D9: College Nurse | E9: 165 | G9: 2025-349 | I9: Providine Iodine 60ml | J9: 30 | K9: bottles | L9: 200 | M9: =SUM(J9*L9) -> 6000 | N9: 60 | O9: =SUM(J9*N9) -> 1800 | P9: for the program/activity intended to strengthen the healthcare services of the BSC Clinic through the procurement of medicines and medical supplies | Q9: Medical-Clinic | R9: October 28, 2025 | S9: November 7, 2025 | T9: November 11, 2025 | U9: November 17, 2025 | V9: Oct. 29,Dec. 5,10 & 23, 2025 & Jan. 15, 2026 | W9: Claire's Drugstore | X9: Nov. 20,Dec. 10,& 23, 2025 & Jan. 15, 2026 | Y9: SS02 | Z9: January 27, 2026 | AA9: complete | AB9: for payment-Acctg. | AC9: 07-02-2025-11-0397A
A10: 2025 | B10: October | C10: JENNY S. ALINA | D10: College Nurse | E10: 165 | G10: 2025-349 | I10: Loperamide | J10: 10 | K10: boxes | L10: 500 | M10: =SUM(J10*L10) -> 5000 | N10: 80 | O10: =SUM(J10*N10) -> 800 | P10: for the program/activity intended to strengthen the healthcare services of the BSC Clinic through the procurement of medicines and medical supplies | Q10: Medical-Clinic | R10: October 28, 2025 | S10: November 7, 2025 | T10: November 11, 2025 | U10: November 17, 2025 | V10: Oct. 29,Dec. 5,10 & 23, 2025 & Jan. 15, 2026 | W10: Claire's Drugstore | X10: Nov. 20,Dec. 10,& 23, 2025 & Jan. 15, 2026 | Y10: SS02 | Z10: January 27, 2026 | AA10: complete | AB10: for payment-Acctg. | AC10: 07-02-2025-11-0397A
A11: 2025 | B11: October | C11: JENNY S. ALINA | D11: College Nurse | E11: 165 | G11: 2025-349 | I11: Band Aid (Waterproof) | J11: 15 | K11: boxes | L11: 200 | M11: =SUM(J11*L11) -> 3000 | N11: 110 | O11: =SUM(J11*N11) -> 1650 | P11: for the program/activity intended to strengthen the healthcare services of the BSC Clinic through the procurement of medicines and medical supplies | Q11: Medical-Clinic | R11: October 28, 2025 | S11: November 7, 2025 | T11: November 11, 2025 | U11: November 17, 2025 | V11: Oct. 29,Dec. 5,10 & 23, 2025 & Jan. 15, 2026 | W11: Claire's Drugstore | X11: Nov. 20,Dec. 10,& 23, 2025 & Jan. 15, 2026 | Y11: SS02 | Z11: January 27, 2026 | AA11: complete | AB11: for payment-Acctg. | AC11: 07-02-2025-11-0397A
A12: 2025 | B12: October | C12: JENNY S. ALINA | D12: College Nurse | E12: 165 | G12: 2025-349 | I12: Ice Bag (big) 9’’ | J12: 6 | K12: pc | L12: 150 | M12: =SUM(J12*L12) -> 900 | N12: 160 | O12: =SUM(J12*N12) -> 960 | P12: for the program/activity intended to strengthen the healthcare services of the BSC Clinic through the procurement of medicines and medical supplies | Q12: Medical-Clinic | R12: October 28, 2025 | S12: November 7, 2025 | T12: November 11, 2025 | U12: November 17, 2025 | V12: Oct. 29,Dec. 5,10 & 23, 2025 & Jan. 15, 2026 | W12: Claire's Drugstore | X12: Nov. 20,Dec. 10,& 23, 2025 & Jan. 15, 2026 | Y12: SS02 | Z12: January 27, 2026 | AA12: complete | AB12: for payment-Acctg. | AC12: 07-02-2025-11-0397A
A13: 2025 | B13: October | C13: JENNY S. ALINA | D13: College Nurse | E13: 165 | G13: 2025-349 | I13: Mupirocin 2omg/g/ 5g | J13: 10 | K13: pcs. | L13: 200 | M13: =SUM(J13*L13) -> 2000 | N13: 60 | O13: =SUM(J13*N13) -> 600 | P13: for the program/activity intended to strengthen the healthcare services of the BSC Clinic through the procurement of medicines and medical supplies | Q13: Medical-Clinic | R13: October 28, 2025 | S13: November 7, 2025 | T13: November 11, 2025 | U13: November 17, 2025 | V13: Oct. 29,Dec. 5,10 & 23, 2025 & Jan. 15, 2026 | W13: Claire's Drugstore | X13: Nov. 20,Dec. 10,& 23, 2025 & Jan. 15, 2026 | Y13: SS02 | Z13: January 27, 2026 | AA13: complete | AB13: for payment-Acctg. | AC13: 07-02-2025-11-0397A
A14: 2025 | B14: October | C14: JENNY S. ALINA | D14: College Nurse | E14: 165 | G14: 2025-349 | I14: Clean gloves(large) | J14: 10 | K14: boxes | L14: 400 | M14: =SUM(J14*L14) -> 4000 | N14: 330 | O14: =SUM(J14*N14) -> 3300 | P14: for the program/activity intended to strengthen the healthcare services of the BSC Clinic through the procurement of medicines and medical supplies | Q14: Medical-Clinic | R14: October 28, 2025 | S14: November 7, 2025 | T14: November 11, 2025 | U14: November 17, 2025 | V14: Oct. 29,Dec. 5,10 & 23, 2025 & Jan. 15, 2026 | W14: Claire's Drugstore | X14: Nov. 20,Dec. 10,& 23, 2025 & Jan. 15, 2026 | Y14: SS02 | Z14: January 27, 2026 | AA14: complete | AB14: for payment-Acctg. | AC14: 07-02-2025-11-0397A
A15: 2025 | B15: October | C15: JENNY S. ALINA | D15: College Nurse | E15: 165 | G15: 2025-349 | I15: Naproxen Sodium 550mg(blue) | J15: 200 | K15: tablet | L15: 33 | M15: =SUM(J15*L15) -> 6600 | N15: 33 | O15: =SUM(J15*N15) -> 6600 | P15: for the program/activity intended to strengthen the healthcare services of the BSC Clinic through the procurement of medicines and medical supplies | Q15: Medical-Clinic | R15: October 28, 2025 | S15: November 7, 2025 | T15: November 11, 2025 | U15: November 17, 2025 | V15: Oct. 29,Dec. 5,10 & 23, 2025 & Jan. 15, 2026 | W15: Claire's Drugstore | X15: Nov. 20,Dec. 10,& 23, 2025 & Jan. 15, 2026 | Y15: SS02 | Z15: January 27, 2026 | AA15: complete | AB15: for payment-Acctg. | AC15: 07-02-2025-11-0397A
A16: 2025 | B16: October | C16: JENNY S. ALINA | D16: College Nurse | E16: 165 | G16: 2025-349 | I16: Multi Insect Killer 700ml (Odorless/Lemon) | J16: 3 | K16: Cannister | L16: 700 | M16: =SUM(J16*L16) -> 2100 | N16: 780 | O16: =SUM(J16*N16) -> 2340 | P16: for the program/activity intended to strengthen the healthcare services of the BSC Clinic through the procurement of medicines and medical supplies | Q16: Medical-Clinic | R16: October 28, 2025 | S16: November 7, 2025 | T16: November 11, 2025 | U16: November 17, 2025 | V16: Oct. 29,Dec. 5,10 & 23, 2025 & Jan. 15, 2026 | W16: Claire's Drugstore | X16: Nov. 20,Dec. 10,& 23, 2025 & Jan. 15, 2026 | Y16: SS02 | Z16: January 27, 2026 | AA16: complete | AB16: for payment-Acctg. | AC16: 07-02-2025-11-0397A
... A45: 2025 | B45: October | C45: JENNY S. ALINA | D45: College Nurse | E45: 165 | G45: 2025-349 | I45: Bleach lemon 1 Liter | J45: 3 | K45: boxes | L45: 500 | M45: =SUM(J45*L45) -> 1500 | N45: 2300 | O45: =SUM(J45*N45) -> 6900 | P45: for the program/activity intended to strengthen the healthcare services of the BSC Clinic through the procurement of medicines and medical supplies | Q45: Medical-Clinic | R45: October 28, 2025 | S45: November 7, 2025 | T45: November 11, 2025 | U45: November 17, 2025 | V45: Oct. 29,Dec. 5,10 & 23, 2025 & Jan. 15, 2026 | W45: Claire's Drugstore | X45: Nov. 20,Dec. 10,& 23, 2025 & Jan. 15, 2026 | Y45: SS02 | Z45: January 27, 2026 | AA45: complete | AB45: for payment-Acctg. | AC45: 07-02-2025-11-0397A
A46: 2025 | B46: October | C46: DOREEN C. CASTILLO | D46: Director for CBAO | G46: 2025-350 | I46: Spicy Seafood Cup Noodles 48's | J46: 2 | K46: box | L46: 1480 | M46: =SUM(J46*L46) -> 2960 | O46: =SUM(J46*N46) -> 0 | P46: for canteen operation | Q46: CBAO | Y46: 1006 | AA46: FAILED | AB46: quotation exceeded the budget | AD46: 3 RFQ's
A47: 2025 | B47: October | C47: DOREEN C. CASTILLO | D47: Director for CBAO | G47: 2025-350 | I47: Spicy Beef Cup Noodles 48's | J47: 2 | K47: box | L47: 1480 | M47: =SUM(J47*L47) -> 2960 | O47: =SUM(J47*N47) -> 0 | P47: for canteen operation | Q47: CBAO | Y47: 1006
A48: 2025 | B48: October | C48: DOREEN C. CASTILLO | D48: Director for CBAO | G48: 2025-350 | I48: Beef Flavor Cup Noodles 48's | J48: 2 | K48: box | L48: 1480 | M48: =SUM(J48*L48) -> 2960 | O48: =SUM(J48*N48) -> 0 | P48: for canteen operation | Q48: CBAO | Y48: 1006
A49: 2025 | B49: October | C49: DOREEN C. CASTILLO | D49: Director for CBAO | G49: 2025-350 | I49: Batchoy Flavor Cup Noodles 48's | J49: 2 | K49: box | L49: 1480 | M49: =SUM(J49*L49) -> 2960 | O49: =SUM(J49*N49) -> 0 | P49: for canteen operation | Q49: CBAO | Y49: 1006
A50: 2025 | B50: October | C50: DOREEN C. CASTILLO | D50: Director for CBAO | G50: 2025-350 | I50: Creamy Seafood Flavor Cup Noodles 48's | J50: 2 | K50: box | L50: 1480 | M50: =SUM(J50*L50) -> 2960 | O50: =SUM(J50*N50) -> 0 | P50: for canteen operation | Q50: CBAO | Y50: 1006
A51: 2025 | B51: October | C51: DOREEN C. CASTILLO | D51: Director for CBAO | G51: 2025-350 | I51: Seafood Flavor Cup Noodles 48's | J51: 2 | K51: box | L51: 1480 | M51: =SUM(J51*L51) -> 2960 | O51: =SUM(J51*N51) -> 0 | P51: for canteen operation | Q51: CBAO | Y51: 1006
A52: 2025 | B52: October | C52: DOREEN C. CASTILLO | D52: Director for CBAO | G52: 2025-350 | I52: Bulalo Flavor Cup Noodles 48's | J52: 2 | K52: box | L52: 1480 | M52: =SUM(J52*L52) -> 2960 | O52: =SUM(J52*N52) -> 0 | P52: for canteen operation | Q52: CBAO | Y52: 1006
A53: 2025 | B53: October | C53: DOREEN C. CASTILLO | D53: Director for CBAO | G53: 2025-350 | I53: Coke in Can | J53: 5 | K53: case | L53: 1260 | M53: =SUM(J53*L53) -> 6300 | O53: =SUM(J53*N53) -> 0 | P53: for canteen operation | Q53: CBAO | Y53: 1006
A54: 2025 | B54: October | C54: DOREEN C. CASTILLO | D54: Director for CBAO | G54: 2025-350 | I54: Royal in can | J54: 5 | K54: case | L54: 1260 | M54: =SUM(J54*L54) -> 6300 | O54: =SUM(J54*N54) -> 0 | P54: for canteen operation | Q54: CBAO | Y54: 1006
A55: 2025 | B55: October | C55: DOREEN C. CASTILLO | D55: Director for CBAO | G55: 2025-350 | I55: Sprite in can | J55: 5 | K55: case | L55: 1260 | M55: =SUM(J55*L55) -> 6300 | O55: =SUM(J55*N55) -> 0 | P55: for canteen operation | Q55: CBAO | Y55: 1006
A56: 2025 | B56: October | C56: DOREEN C. CASTILLO | D56: Director for CBAO | G56: 2025-350 | I56: Mountain Dew 500ml | J56: 5 | K56: case | L56: 1095 | M56: =SUM(J56*L56) -> 5475 | O56: =SUM(J56*N56) -> 0 | P56: for canteen operation | Q56: CBAO | Y56: 1006
A57: 2025 | B57: October | C57: DOREEN C. CASTILLO | D57: Director for CBAO | G57: 2025-350 | I57: Bottled Water 500ml | J57: 10 | K57: case | L57: 580 | M57: =SUM(J57*L57) -> 5800 | O57: =SUM(J57*N57) -> 0 | P57: for canteen operation | Q57: CBAO | Y57: 1006
A58: 2025 | B58: October | C58: DOREEN C. CASTILLO | D58: Director for CBAO | G58: 2025-350 | I58: Tetra Pack Juice | J58: 15 | K58: box | L58: 245 | M58: =SUM(J58*L58) -> 3675 | O58: =SUM(J58*N58) -> 0 | P58: for canteen operation | Q58: CBAO | Y58: 1006
... A85: 2025 | B85: October | C85: DOREEN C. CASTILLO | D85: Director for CBAO | G85: 2025-350 | I85: Cling Wrap | J85: 2 | K85: roll | L85: 500 | M85: =SUM(J85*L85) -> 1000 | O85: =SUM(J85*N85) -> 0 | P85: for canteen operation | Q85: CBAO | Y85: 1006
A86: 2025 | B86: October | C86: MARIE FE E. PABLEO | D86: Board Secretary I | E86: 101 | F86: Toss Coin | G86: 2025-351 | I86: Tarpaulin Printing (4ft x 6ft) | J86: 1 | K86: pc | L86: 1500 | M86: =SUM(J86*L86) -> 1500 | N86: 720 | O86: =SUM(J86*N86) -> 720 | P86: announcement for the opening of search for private sector representatives to the BSC Board of Trustees | Q86: OBS | R86: October 22, 2025 | S86: October 24, 2025 | T86: October 28, 2025 | U86: November 13, 2025 | V86: November 26, 2025 | W86: YCA Printing Services | X86: November 26, 2025 | Y86: GAS2 | Z86: December 4, 2025 | AA86: complete | AB86: for payment-Acctg. | AC86: 02-101101-2025-10-00881 | AD86: 3 RFQ's | AE86: 379/11/26/2025
A87: 2025 | B87: October | C87: ZOE DYMPNA H. CARTAŇO | D87: AO V/GAD Focal Person | E87: 101 | F87: Dir. Acq. | G87: 2025-352 | I87: Rice (25kgs) | J87: 13 | K87: sack | L87: 1800 | M87: =SUM(J87*L87) -> 23400 | N87: 1800 | O87: =SUM(J87*N87) -> 23400 | P87: for the distribution of food packs for the elderly and person with special needs of the BSC employees | Q87: GAD | T87: October 8, 2025 | U87: October 14, 2025 | V87: October 3, 2025 | W87: CMJ Shop & Snack | X87: October 6, 2025 | Y87: GAS21 | Z87: October 28, 2025 | AA87: complete | AB87: for payment-Acctg. | AC87: 02-101101-2025-10-00814 | AE87: 0008157/10/06/2025
A88: 2025 | B88: October | C88: ZOE DYMPNA H. CARTAŇO | D88: AO V/GAD Focal Person | E88: 101 | G88: 2025-352 | I88: Assorted Biscuits | J88: 100 | K88: pack | L88: 95 | M88: =SUM(J88*L88) -> 9500 | N88: 95 | O88: =SUM(J88*N88) -> 9500 | P88: for the distribution of food packs for the elderly and person with special needs of the BSC employees | Q88: GAD | T88: October 8, 2025 | U88: October 14, 2025 | V88: October 3, 2025 | W88: CMJ Shop & Snack | X88: October 6, 2025 | Y88: GAS21 | Z88: October 28, 2025 | AA88: complete | AB88: for payment-Acctg. | AC88: 02-101101-2025-10-00814
A89: 2025 | B89: October | C89: ZOE DYMPNA H. CARTAŇO | D89: AO V/GAD Focal Person | E89: 101 | G89: 2025-352 | I89: Washed Sugar | J89: 100 | K89: kg | L89: 115 | M89: =SUM(J89*L89) -> 11500 | N89: 115 | O89: =SUM(J89*N89) -> 11500 | P89: for the distribution of food packs for the elderly and person with special needs of the BSC employees | Q89: GAD | T89: October 8, 2025 | U89: October 14, 2025 | V89: October 3, 2025 | W89: CMJ Shop & Snack | X89: October 6, 2025 | Y89: GAS21 | Z89: October 28, 2025 | AA89: complete | AB89: for payment-Acctg. | AC89: 02-101101-2025-10-00814
A90: 2025 | B90: October | C90: ZOE DYMPNA H. CARTAŇO | D90: AO V/GAD Focal Person | E90: 101 | G90: 2025-352 | I90: Eco Bag 25pc/pack (large) | J90: 4 | K90: pack | L90: 1400 | M90: =SUM(J90*L90) -> 5600 | N90: 1400 | O90: =SUM(J90*N90) -> 5600 | P90: for the distribution of food packs for the elderly and person with special needs of the BSC employees | Q90: GAD | T90: October 8, 2025 | U90: October 14, 2025 | V90: October 3, 2025 | W90: CMJ Shop & Snack | X90: October 6, 2025 | Y90: GAS21 | Z90: October 28, 2025 | AA90: complete | AB90: for payment-Acctg. | AC90: 02-101101-2025-10-00814
A91: 2025 | B91: October | C91: ZOE DYMPNA H. CARTAŇO | D91: AO V/GAD Focal Person | E91: 101 | G91: 2025-352 | I91: Sando Bag | J91: 1 | K91: pack | L91: 200 | M91: =SUM(J91*L91) -> 200 | N91: 200 | O91: =SUM(J91*N91) -> 200 | P91: for the distribution of food packs for the elderly and person with special needs of the BSC employees | Q91: GAD | T91: October 8, 2025 | U91: October 14, 2025 | V91: October 3, 2025 | W91: CMJ Shop & Snack | X91: October 6, 2025 | Y91: GAS21 | Z91: October 28, 2025 | AA91: complete | AB91: for payment-Acctg. | AC91: 02-101101-2025-10-00814
A92: 2025 | B92: October | C92: ZOE DYMPNA H. CARTAŇO | D92: AO V/GAD Focal Person | E92: 101 | G92: 2025-352 | I92: Instant Oats | J92: 100 | K92: pack | L92: 125 | M92: =SUM(J92*L92) -> 12500 | N92: 125 | O92: =SUM(J92*N92) -> 12500 | P92: for the distribution of food packs for the elderly and person with special needs of the BSC employees | Q92: GAD | T92: October 8, 2025 | U92: October 14, 2025 | V92: October 3, 2025 | W92: CMJ Shop & Snack | X92: October 6, 2025 | Y92: GAS21 | Z92: October 28, 2025 | AA92: complete | AB92: for payment-Acctg. | AC92: 02-101101-2025-10-00814
A93: 2025 | B93: October | C93: ZOE DYMPNA H. CARTAŇO | D93: AO V/GAD Focal Person | E93: 101 | G93: 2025-352 | I93: Powdered Milk (600grams) | J93: 69 | K93: pack | L93: 450 | M93: =SUM(J93*L93) -> 31050 | N93: 450 | O93: =SUM(J93*N93) -> 31050 | P93: for the distribution of food packs for the elderly and person with special needs of the BSC employees | Q93: GAD | T93: October 8, 2025 | U93: October 14, 2025 | V93: October 3, 2025 | W93: CMJ Shop & Snack | X93: October 6, 2025 | Y93: GAS21 | Z93: October 28, 2025 | AA93: complete | AB93: for payment-Acctg. | AC93: 02-101101-2025-10-00814
A94: 2025 | B94: October | C94: ZOE DYMPNA H. CARTAŇO | D94: AO V/GAD Focal Person | E94: 101 | G94: 2025-352 | I94: Powdered Milk (680grams) | J94: 31 | K94: pack | L94: 415 | M94: =SUM(J94*L94) -> 12865 | N94: 415 | O94: =SUM(J94*N94) -> 12865 | P94: for the distribution of food packs for the elderly and person with special needs of the BSC employees | Q94: GAD | T94: October 8, 2025 | U94: October 14, 2025 | V94: October 3, 2025 | W94: CMJ Shop & Snack | X94: October 6, 2025 | Y94: GAS21 | Z94: October 28, 2025 | AA94: complete | AB94: for payment-Acctg. | AC94: 02-101101-2025-10-00814
...

Sheet PR
A3: Republic of the Philippines
A4: BATANES STATE COLLEGE
A5: Basco, Batanes
A7: PURCHASE REQUEST
D9: PR No. | E9: =DATA!G200 -> 2025-380 | F9: Date
A10: Department: | D10: SAI No.:
A11: Section: | B11: =DATA!Y200 -> 1005 | D11: OBR#
A12: Ref. No.: | B12: 2510-1005-380
A14: Qty | B14: Unit of Issue | D14: Item Description | F14: Stock No. | G14: Estimated
G15: Unit Cost | H15: Total Cost
A16: =DATA!J200 -> 60 | B16: =DATA!K200 -> copies | D16: =DATA!I200 -> Printing of Training Manual (Hardbound cover, laminated, colored,15.5 x 23 cm, 70 pages, 80gsm, colored, glossy with ISSN/ISBN number) | G16: =DATA!L200 -> 1350 | H16: =SUM(A16*G16) -> 81000
H17: =SUM(A17*G17) -> 0
H18: =SUM(A18*G18) -> 0
H19: =SUM(A19*G19) -> 0
H20: =SUM(A20*G20) -> 0
H21: =SUM(A21*G21) -> 0
H22: =SUM(A22*G22) -> 0
H23: =SUM(A23*G23) -> 0
H24: =SUM(A24*G24) -> 0
H25: =SUM(A25*G25) -> 0
H26: =SUM(A26*G26) -> 0
H27: =SUM(A27*G27) -> 0
H28: =SUM(A28*G28) -> 0
... H34: =SUM(A34*G34) -> 0
A35: =DATA!J398 -> 5 | B35: =DATA!K398 -> set | D35: =DATA!I398 -> Laddle with wooden handle with hole | G35: =DATA!L398 -> 88.5 | H35: =SUM(A35*G35) -> 442.5
A36: =DATA!J399 -> 5 | B36: =DATA!K399 -> set | D36: =DATA!I399 -> Laddle with wooden handle without hole | G36: =DATA!L399 -> 88.5 | H36: =SUM(A36*G36) -> 442.5
A37: =DATA!J400 -> 5 | B37: =DATA!K400 -> pc | D37: =DATA!I400 -> Measuring Cup Glass | G37: =DATA!L400 -> 349.5 | H37: =SUM(A37*G37) -> 1747.5
A38: =DATA!J401 -> 5 | B38: =DATA!K401 -> set | D38: =DATA!I401 -> Measuring Cup Set Set Includes: 1/4 cup,1/3 cup, 1/2 cup,1 cup | G38: =DATA!L401 -> 198 | H38: =SUM(A38*G38) -> 990
A39: =DATA!J402 -> 5 | B39: =DATA!K402 -> set | D39: =DATA!I402 -> Measuring Spoon Set sets include: 1/8 teaspoon, 1/4 teaspoon, 1/2 teaspoon, 1 teaspoon, 1/ 2 tbsp, 1 tbsp | G39: =DATA!L402 -> 429 | H39: =SUM(A39*G39) -> 2145
A40: =DATA!J403 -> 3 | B40: =DATA!K403 -> set | D40: =DATA!I403 -> Mixing Bowl with Cover 5pcs | G40: =DATA!L403 -> 6547.23 | H40: =SUM(A40*G40) -> 19641.69
A41: =DATA!J404 -> 5 | B41: =DATA!K404 -> set | D41: =DATA!I404 -> Fruit and Vegetable Peeler Stainless Steel 13 cm (5 ") | G41: =DATA!L404 -> 240 | H41: =SUM(A41*G41) -> 1200
A42: =DATA!J405 -> 5 | B42: =DATA!K405 -> set | D42: =DATA!I405 -> Pot Holder Cloth 3pcs/set | G42: =DATA!L405 -> 45 | H42: =SUM(A42*G42) -> 225
A43: =DATA!J406 -> 10 | B43: =DATA!K406 -> pc | D43: =DATA!I406 -> Pot Holder Heat Insulated Gloves Specifications: Color: Grey Material: silicone Size: 20.5x16.5cm | G43: =DATA!L406 -> 118.5 | H43: =SUM(A43*G43) -> 1185
A44: =DATA!J407 -> 2 | B44: =DATA!K407 -> pc | D44: =DATA!I407 -> Knife Sharpener | G44: =DATA!L407 -> 523.5 | H44: =SUM(A44*G44) -> 1047
A45: =DATA!J408 -> 5 | B45: =DATA!K408 -> pc | D45: =DATA!I408 -> Sifter Stainless Steel 270 x 70mm Mesh: #30 (0.595mm) | G45: =DATA!L408 -> 450 | H45: =SUM(A45*G45) -> 2250
A46: =DATA!J409 -> 5 | B46: =DATA!K409 -> pc | D46: =DATA!I409 -> Pitcher Stainless Steel 2000 ml | G46: =DATA!L409 -> 898.5 | H46: =SUM(A46*G46) -> 4492.5
... A73: =DATA!J436 -> 3 | B73: =DATA!K436 -> pc | D73: =DATA!I436 -> Wok Pan 2mm (thickness) 60cm diameter | G73: =DATA!L436 -> 4125 | H73: =SUM(A73*G73) -> 12375
A74: =DATA!J210 -> 1 | B74: =DATA!K437 -> pcs | D74: =DATA!I437 -> Office Desk/Table Material: MDF Color: Walnut Dimensions of Table: 47.24" W x 30.31" H x 23.63" D Drawer Dimensions: 11" W x 23" H x 18.75" D | G74: =DATA!L62 -> 60 | H74: =SUM(A74*G74) -> 60
A75: =DATA!J211 -> 1 | B75: =DATA!K438 -> pcs | D75: =DATA!I438 -> Office Chair - Junior Executive Chair Black Leatherette Ergonomic with padded armrests Chrome base with smooth-rolling caster wheels Seat Dimensions: 21" L x 21" W Backrest Dimensions: 26.5" L x 21" W Full Dimensions: 25" W x 42" - 45" H | G75: =DATA!L63 -> 125 | H75: =SUM(A75*G75) -> 125
A76: =DATA!J212 -> 2 | B76: =DATA!K439 -> pcs | D76: =DATA!I439 -> Portable Projector with bag and stand Product Details: Android 11,500 ANSI DRM L1 Certification nnovative 120°rotating projection ASA 3.0(AF+KS+ScrnFit+Avoid) Dual-bass diaphragms ≤30 dB/m Ultra-low decibel Specifications: Product Color: White Product Weight: 1.5Kg Product Size: 145*142*219 mm Display Technology: LCD Brightness: 500 ANSI Lumens Physical Resolution: 1920 * 1080 FHD Lens： 3 Pcs aspherical pure glass lens Projection Features Zoom Function：50%-100% Projection Ratio: 1.2: 1 Projection Size: 45-140 Inch Projection Distance: 1.2-3.8m Intelligent Adjustment Keystone Correction： Auto Focus Adjustment： Auto Obstacle Avoidance： Auto Screen Alignment： Auto Audio & Connectivity Speaker: 5W * 2 Noise: ≤30dB/m Cavity Volume：370CC Bluetooth: 5.0 WiFi: Dual Band 2.4/5G Hz Interface HDMI：*1 USB：*1 AUX3.5mm：*1 | G76: =DATA!L64 -> 150 | H76: =SUM(A76*G76) -> 300
...

Sheet ResoSVP (2)
A6: BAC Resolution Recommending Alternative Mode of Procurement under Small Value Procurement
B7: BAC Resolution No. | D7: =PR!B12 -> 2510-1005-380
A9: WHEREAS, Section 48 Rule XVI of the Revised Implementing Rules and Regulations of RA 9184 allows Alternative Mode of Procurement subject to prior approval of the HOPE thru Annual Procurement Plan (APP) and only to promote economy and efficiency;
A10: WHEREAS, Section 53.9 allows Small Value Procurement provided that the procurement does not fall under shopping in Section 52 of this IRR and the amount involved does not exceed the thresholds prescribed in Annex "H" of this IRR;
A11: WHEREAS, Appendix 18, Section 3.e on the Guidelines for Shopping and Small Value Procurement provides an Abstract of Quotations shall be prepared setting forth the names of those who responded to the RFQ's right after the deadline for submission except for shopping under Section 52.1(b), where at least three (3) price quotations (RFQ) must be obtained;
A12: WHEREAS, Annex "H" of the Consolidated Guidelines for the Alternative Methods of Procurement prescribed under Section V, Paragraph D.8.b.ii that the BAC shall prepare and send the RFQs/RFPs to at least three (3) suppliers, contractors or consultants of known qualifications where receipt of at least one (1) quotations is sufficient to proceed with the evaluation thererof;
A13: WHEREAS, Purchase Request No. | D13: =PR!E9 -> 2025-380 | E13: involves the procurement of
A14: AM and PM Snack and Lunch --snacks & lunch for the Joint Academic & Admin meeting
A15: with the approved budget of | D15: =PR!H110 -> 81000
A16: WHEREAS, the default mode of evaluation shall be on a lot basis which means that the determination of the single/lowest calculated and responsive bid (S/LCRB) is the total amount of offered unit price multiply by the required quantity;
A18: NOW THEREFORE, we, the members of the Bids and Awards Committee hereby RESOLVE as it is hereby RESOLVED to recommend to the College President to adopt Alternative Mode of Procurement under Small Value Procurement for the said transaction;
A20: RESOLVED FINALLY, at the Batanes State College, this
A21: Recommending Approval:
A24: RHOUPHELINE AYA A. CADIZ | C24: RANDALL G. CASTILLO | E24: EMILYN D. ALUETA
A25: BAC Member | C25: BAC Member | E25: BAC Member
A28: =PR!B115 -> JANE S. CASTILLO | C28: FORTUNATO PHILIP A. CABUGAO | E28: DOREEN C. CASTILLO
A29: End-User/Provisional Member | C29: BAC Vice Chairperson | E29: BAC Chairperson
A30: BRYAN H. CIELO
A31: DELMA G. MALUPA-ABAD
A32: EDWIN F.MACABALLUG, Ph.D.
A33: LIEZL P. DELA CRUZ
A34: RODERICK Y. ABAD
A35: VILMA D. BACCAY
A36: ESTEBAN C. BADAJOS
A37: LEOBERT L. BANZALI
A38: MIAH DAPHNIE B. BUENAFE
A39: GLORIA N. CABIZON
A40: FORTUNATO PHILIP A. CABUGAO
A41: RICARDO Q. CABUGAO, JR.
... A83: LEONARDO CABRERA

Sheet AResoSVP (2)
A6: Approval of BAC Resolution Recommending Alternative Mode of Procurement under Small Value Procurement
B7: BAC Resolution No. | D7: =PR!B12 -> 2510-1005-380
A9: WHEREAS, Section 48 Rule XVI of the Revised Implementing Rules and Regulations of RA 9184 allows Alternative Mode of Procurement subject to prior approval of the HOPE thru Annual Procurement Plan (APP) and only to promote economy and efficiency;
A10: WHEREAS, Section 53.9 allows Small Value Procurement provided that the procurement does not fall under shopping in Section 52 of this IRR and the amount involved does not exceed the thresholds prescribed in Annex "H" of this IRR;
A11: WHEREAS, Appendix 18, Section 3.e on the Guidelines for Shopping and Small Value Procurement provides an Abstract of Quotations shall be prepared setting forth the names of those who responded to the RFQ's right after the deadline for submission except for shopping under Section 52.1(b), where at least three (3) price quotations (RFQ) must be obtained;
A12: WHEREAS, Annex "H" of the Consolidated Guidelines for the Alternative Methods of Procurement prescribed under Section V, Paragraph D.8.b.ii that the BAC shall prepare and send the RFQs/RFPs to at least three (3) suppliers, contractors or consultants of known qualifications where receipt of at least one (1) quotations is sufficient to proceed with the evaluation thererof;
A13: WHEREAS, Purchase Request No. | D13: =PR!E9 -> 2025-380 | E13: involves the procurement of
A14: AM and PM Snack and Lunch --snacks & lunch for the Joint Academic & Admin meeting | H14: Items:
A15: with the approved budget of | D15: =PR!H110 -> 81000
A16: WHEREAS, the default mode of evaluation shall be on a lot basis which means that the determination of the single/lowest calculated and responsive bid (S/LCRB) is the total amount of offered unit price multiply by the required quantity;
A17: NOW THEREFORE, I,DR.DJOVI R. DURANTE, Head of the Procuring Entity (HOPE) by virtue of the authority vested in me by the Board of Trustees of this Institution and after taking into consideration the merits and legal bases of the recommendation of the members of the Bids and Awards Committee (BAC) do hereby APPROVE the foregoing recommendation and adoption of Alternative Mode of Procurement under Small Value Procurement;
A19: APPROVED FINALLY, at the Batanes State College, this | F19: ___________________
B25: DJOVI REGALA DURANTE,DPA
B26: SUC President I
A31: BRYAN H. CIELO
A32: DELMA G. MALUPA-ABAD
A33: EDWIN F.MACABALLUG, Ph.D.
A34: LIEZL P. DELA CRUZ
A35: RODERICK Y. ABAD
A36: VILMA D. BACCAY
A37: ESTEBAN C. BADAJOS
A38: LEOBERT L. BANZALI
A39: MIAH DAPHNIE B. BUENAFE
A40: GLORIA N. CABIZON
A41: FORTUNATO PHILIP A. CABUGAO
A42: RICARDO Q. CABUGAO, JR.
... A87: EMILYN D. ALUETA

Sheet RFQ_ (2)
E6: Date: | F6: 10/20/25
A7: REQUEST FOR PRICE QUOTATION
A8: YCA Printing Services
A9: Please give us your best and final price offer for the item/s listed below, have this signed and submit this by you or by your duly authorized representative WITHIN SEVEN (7) CALENDAR DAYS upon receipt to Procurement Section, Batanes State College.
A11: NOTE: | B11: 1. THE DEFAULT MODE OF PRICE EVALUATION SHALL BE ON A LOT BASIS, OTHERWISE PER ITEMS EVALUATION SHALL BE USED IF THERE WILL BE LACKING ITEMS IN ALL RFQ's AND SUBJECT TO END-USER APPROVAL., (Clause 15.2, Section I, Instruction to Bidders of the Philippine Bidding Documents for goods and infrastructure projects)
B12: 2. DELIVERY PERIOD: Thirty (30) calendar days.
B13: 3. Submission of price quotation shall be in sealed envelope.
B14: 4. THE APPROVED BUDGET FOR THIS PROCUREMENT IS
B15: =PR!H110 -> 81000 | D15: (GPPB Resolution No. 09-2009)
B16: 5. PURSUANT TO ANNEX "H", APPENDIX A, SECTION II, SUBMISSION OF APPLICABLE DOCUMENTS (e.g.MAYORS/BUSINESS PERMIT, PROFESSIONAL LICENSE/CURRICULUM VITAE (CONSULTING SEERVICES),PHILGEPS CERT. NO., PCAB LICENSE (INFRA), INCOME/BUSINESS TAX RETURN,OMNIBUS SWORN STATEMENT SHALL BE REQUIRED BEFORE THE ISSUANCE OF NOA OR PRIOR TO PAYMENT.
B17: 6. In case the item is not availble, please write "None".
A18: Item # | B18: Qty. | C18: Unit | D18: PARTICULAR | E18: Unit Price | F18: Total
A19: 001 | B19: =PR!A16 -> 60 | C19: =PR!B16 -> copies | D19: =PR!D16 -> Printing of Training Manual (Hardbound cover, laminated, colored,15.5 x 23 cm, 70 pages, 80gsm, colored, glossy with ISSN/ISBN number)
A20: 002
A21: 003
A22: 004
A23: 005
A24: 006
A25: 007
A26: 008
A27: 009
A28: 010
A29: 011 | B29: =PR!A26 -> 0 | C29: =PR!B26 -> 0 | D29: =PR!D26 -> 0
A30: 012 | B30: =PR!A27 -> 0 | C30: =PR!B27 -> 0 | D30: =PR!D27 -> 0
A31: 013 | B31: =PR!A28 -> 0 | C31: =PR!B28 -> 0 | D31: =PR!D28 -> 0
A32: 014 | B32: =PR!A29 -> 0 | D32: =PR!D29 -> 0
A33: 015 | B33: =PR!A30 -> 0 | D33: =PR!D30 -> 0
A34: 016 | B34: =PR!A31 -> 0 | D34: =PR!D31 -> 0
A35: 017 | B35: =PR!A32 -> 0 | C35: =PR!B32 -> 0 | D35: =PR!D32 -> 0
A36: 018 | B36: =PR!A33 -> 0 | C36: =PR!B33 -> 0 | D36: =PR!D33 -> 0
A37: 019 | B37: =PR!A34 -> 0 | C37: =PR!B34 -> 0 | D37: =PR!D34 -> 0
A38: 020 | B38: =PR!A35 -> 5 | C38: =PR!B35 -> set | D38: =PR!D35 -> Laddle with wooden handle with hole
A39: 021 | B39: =PR!A36 -> 5 | C39: =PR!B36 -> set | D39: =PR!D36 -> Laddle with wooden handle without hole
A40: 022 | B40: =PR!A37 -> 5 | C40: =PR!B37 -> pc | D40: =PR!D37 -> Measuring Cup Glass
A41: 023 | B41: =PR!A38 -> 5 | C41: =PR!B38 -> set | D41: =PR!D38 -> Measuring Cup Set Set Includes: 1/4 cup,1/3 cup, 1/2 cup,1 cup
A42: 024 | B42: =PR!A39 -> 5 | C42: =PR!B39 -> set | D42: =PR!D39 -> Measuring Spoon Set sets include: 1/8 teaspoon, 1/4 teaspoon, 1/2 teaspoon, 1 teaspoon, 1/ 2 tbsp, 1 tbsp
A43: 025 | B43: =PR!A40 -> 3 | C43: =PR!B40 -> set | D43: =PR!D40 -> Mixing Bowl with Cover 5pcs
A44: 026 | B44: =PR!A41 -> 5 | C44: =PR!B41 -> set | D44: =PR!D41 -> Fruit and Vegetable Peeler Stainless Steel 13 cm (5 ")
A45: 027 | B45: =PR!A42 -> 5 | C45: =PR!B42 -> set | D45: =PR!D42 -> Pot Holder Cloth 3pcs/set
A46: 028 | B46: =PR!A43 -> 10 | C46: =PR!B43 -> pc | D46: =PR!D43 -> Pot Holder Heat Insulated Gloves Specifications: Color: Grey Material: silicone Size: 20.5x16.5cm
...

Sheet RFQ_ (3)
E6: Date: | F6: =NOW() -> 46181.383
A7: REQUEST FOR PRICE QUOTATION
A8: Apostol General Merchandise
A9: Please give us your best and final price offer for the item/s listed below, have this signed and submit this by you or by your duly authorized representative WITHIN SEVEN (7) CALENDAR DAYS upon receipt to Procurement Section, Batanes State College.
A11: NOTE: | B11: 1. THE DEFAULT MODE OF PRICE EVALUATION SHALL BE ON A LOT BASIS, OTHERWISE PER ITEMS EVALUATION SHALL BE USED IF THERE WILL BE LACKING ITEMS IN ALL RFQ's AND SUBJECT TO END-USER APPROVAL., (Clause 15.2, Section I, Instruction to Bidders of the Philippine Bidding Documents for goods and infrastructure projects)
B12: 2. DELIVERY PERIOD: Thirty (30) calendar days.
B13: 3. Submission of price quotation shall be in sealed envelope.
B14: 4. THE APPROVED BUDGET FOR THIS PROCUREMENT IS
B15: =PR!H110 -> 81000 | D15: (GPPB Resolution No. 09-2009)
B16: 5. PURSUANT TO ANNEX "H", APPENDIX A, SECTION II, SUBMISSION OF APPLICABLE DOCUMENTS (e.g.MAYORS/BUSINESS PERMIT, PROFESSIONAL LICENSE/CURRICULUM VITAE (CONSULTING SEERVICES),PHILGEPS CERT. NO., PCAB LICENSE (INFRA), INCOME/BUSINESS TAX RETURN,OMNIBUS SWORN STATEMENT SHALL BE REQUIRED BEFORE THE ISSUANCE OF NOA OR PRIOR TO PAYMENT.
B17: 6. In case the item is not availble, please write "None".
A18: Item # | B18: Qty. | C18: Unit | D18: PARTICULAR | E18: Unit Price | F18: Total
A19: 001 | B19: =PR!A16 -> 60 | C19: =PR!B16 -> copies | D19: =PR!D16 -> Printing of Training Manual (Hardbound cover, laminated, colored,15.5 x 23 cm, 70 pages, 80gsm, colored, glossy with ISSN/ISBN number)
A20: 002 | B20: =PR!A17 -> 0 | C20: =PR!B17 -> 0 | D20: =PR!D17 -> 0
A21: 003 | B21: =PR!A18 -> 0 | C21: =PR!B18 -> 0 | D21: =PR!D18 -> 0
A22: 004 | B22: =PR!A19 -> 0 | C22: =PR!B19 -> 0 | D22: =PR!D19 -> 0
A23: 005 | B23: =PR!A20 -> 0 | C23: =PR!B20 -> 0 | D23: =PR!D20 -> 0
A24: 006 | B24: =PR!A21 -> 0 | C24: =PR!B21 -> 0 | D24: =PR!D21 -> 0
A25: 007 | B25: =PR!A22 -> 0 | C25: =PR!B22 -> 0 | D25: =PR!D22 -> 0
A26: 008 | B26: =PR!A23 -> 0 | C26: =PR!B23 -> 0 | D26: =PR!D23 -> 0
A27: 009 | B27: =PR!A24 -> 0 | C27: =PR!B24 -> 0 | D27: =PR!D24 -> 0
A28: 010 | B28: =PR!A25 -> 0 | C28: =PR!B25 -> 0 | D28: =PR!D25 -> 0
A29: 011 | B29: =PR!A26 -> 0 | C29: =PR!B26 -> 0 | D29: =PR!D26 -> 0
A30: 012 | B30: =PR!A27 -> 0 | C30: =PR!B27 -> 0 | D30: =PR!D27 -> 0
... A76: 058 | B76: =PR!A73 -> 3 | C76: =PR!B73 -> pc | D76: =PR!D73 -> Wok Pan 2mm (thickness) 60cm diameter
A77: 060 | B77: =[1]PR!A74 -> 1 | C77: =PR!B74 -> pcs | D77: =PR!D74 -> Office Desk/Table Material: MDF Color: Walnut Dimensions of Table: 47.24" W x 30.31" H x 23.63" D Drawer Dimensions: 11" W x 23" H x 18.75" D
A78: 061 | B78: =[1]PR!A75 -> 1 | C78: =PR!B75 -> pcs | D78: =PR!D75 -> Office Chair - Junior Executive Chair Black Leatherette Ergonomic with padded armrests Chrome base with smooth-rolling caster wheels Seat Dimensions: 21" L x 21" W Backrest Dimensions: 26.5" L x 21" W Full Dimensions: 25" W x 42" - 45" H
A79: 062 | B79: =[1]PR!A76 -> 1 | C79: =PR!B76 -> pcs | D79: =PR!D76 -> Portable Projector with bag and stand Product Details: Android 11,500 ANSI DRM L1 Certification nnovative 120°rotating projection ASA 3.0(AF+KS+ScrnFit+Avoid) Dual-bass diaphragms ≤30 dB/m Ultra-low decibel Specifications: Product Color: White Product Weight: 1.5Kg Product Size: 145*142*219 mm Display Technology: LCD Brightness: 500 ANSI Lumens Physical Resolution: 1920 * 1080 FHD Lens： 3 Pcs aspherical pure glass lens Projection Features Zoom Function：50%-100% Projection Ratio: 1.2: 1 Projection Size: 45-140 Inch Projection Distance: 1.2-3.8m Intelligent Adjustment Keystone Correction： Auto Focus Adjustment： Auto Obstacle Avoidance： Auto Screen Alignment： Auto Audio & Connectivity Speaker: 5W * 2 Noise: ≤30dB/m Cavity Volume：370CC Bluetooth: 5.0 WiFi: Dual Band 2.4/5G Hz Interface HDMI：*1 USB：*1 AUX3.5mm：*1
A80: 063 | B80: =[1]PR!A77 -> 1 | C80: =PR!B77 -> 0 | D80: =PR!D77 -> 0
A81: 064 | B81: =[1]PR!A78 -> 1 | C81: =PR!B78 -> pcs | D81: =PR!D78 -> Assorted Coffee 3 in 1
A82: 065 | B82: =[1]PR!A79 -> 1 | C82: =PR!B79 -> 0 | D82: =PR!D79 -> Coke 1.7L
A83: 066 | B83: =[1]PR!A80 -> 1 | C83: =PR!B80 -> pcs | D83: =PR!D80 -> Bottled Water 1L
A84: 067 | B84: =[1]PR!A81 -> 1 | C84: =PR!B81 -> pcs | D84: =PR!D81 -> Dutchmill 90ml 4's
A85: 068 | B85: =[1]PR!A82 -> 1 | C85: =PR!B82 -> 0 | D85: =PR!D82 -> Dutchmill 180ml 4's
A86: 069 | B86: =[1]PR!A83 -> 1 | C86: =PR!B83 -> pcs | D86: =PR!D83 -> Chuckie 180ml 6's
A87: 070 | B87: =[1]PR!A84 -> 1 | C87: =PR!B84 -> pcs | D87: =PR!D84 -> Cupkeyk
A88: 071 | B88: =[1]PR!A85 -> 1 | C88: =PR!B85 -> pcs | D88: =PR!D85 -> Fudgee Bar
... A101: 084 | B101: =[1]PR!A98 -> 1 | C101: =PR!B98 -> pc | D101: =PR!D98 -> Tarpaulin Printing (4ft x 6ft)
E102: Total
A103: After having carefully read and accepted your conditions, I/We have place my /our best and final price offer on the item/s listed above.
...

Sheet AckReceipt (3)
A3: Acknowledgement for Request for Quotation
A4: RIS# | B4: =PR!B12 -> 2510-1005-380
A5: No. | B5: Supplier | F5: Received by: | G5: Date & Time:
B6: JPM Gen. Mdse. & Hardware
B7: Thine-line Trading
B8: J-Tech Trading & Services
B9: MDAC Trading & Compuserve
B10: FVA Gen Mdse & Construction Supply
B12: GDP Trading
B13: EA Amboy Gen Mdse
B14: L & R's Hontomin Gen Mdse
B15: Davocol's Gen. Mdse.
B16: RCJ Hardware & Gen Mdse
B17: Fitero's Gen Mdse & Electronic Supply
B18: Lar & San's Store
... B20: Wilmerson Gen Mdse
B21: FMG Trading & Construction Supply | C21: q
B22: MG Hubalde Gen Mdse
B23: Basco Cable TV Services, Inc.
B24: Berlen's Store
B25: Melad's Gen. Mdse
B26: R. A. Electronics
B27: RJ General Merchandise
B28: Batanes Multi-Purpose Cooperative, Inc.
B29: Romy & Ava's Store
B30: J-nell's Gen Mdse
B31: Impression Digital Printing Solutions
B32: Golden Press
B33: Tawsen's Agri-Venture & Souvenirs
... B62: Sophia Marie Store
A63: 1 | B63: Swift Development & Supplies Corp.
A64: 2 | B64: JF Gabotero, In
A65: 3 | B65: GMPI Construction OPC
A66: 4
A67: 5 | J67: zz
A68: 6
A69: 7
A70: NOTE: | B70: 1. MODE OF PRICE EVALUATION SHALL BE ON A LOT BASIS, OTHERWISE PER ITEMS EVALUATION SHALL BE USED IF THERE WILL BE LACKING ITEMS IN ALL RFQ'S AND THE END-USER AGREED, . (Clause 15.2, Section II, Instructions to Bidders of the Philippine Bidding Documents for goods and infrastructure projects)
B71: 2. DELIVERY PERIOD: Thirty (30) calendar days.
B72: 3. WARRANTY SHALL BE FOR A PERIOD OF SIX (6) MONTHS FOR SUPPLIES AND MATERIALS, ONE (1) YEAR FOR EQUIPMENT, FROM THE DATE OF ACCEPTANCE BY THE PROCURING ENTITY.
...

Sheet Abstract 
B2: ABSTRACT OF QUOTATIONS
B4: (x) Furnishing/delivery of supplies, and materials or equipment | G4: Bids opened at Basco, Batanes
B5: ( x ) Furnishing Labor, services, etc. | I5: =NOW() -> 46181.383
B6: ( ) Rental or use of transportation facilities equipment, quarters, rooms, lot or space, etc.
B8: To be furnished at the | D8: BATANES STATE COLLEGE
D9: (State place or site of Office or project where articles or services be furnished or returned)
A11: NAME OF ARTICLES OR SERVICES TO BE FURNISHED, RENDERED OR FACILITIES TO BE RENTED
F14: JPM Gen. Mdse. & Hardware
F15: Thine-line Trading
F16: J-Tech Trading & Services
F17: Mulong Ydel
F18: MDAC Trading & Compuserve
F19: FVA Gen Mdse & Construction Supply
F20: MKM Hardware
F21: GDP Trading
F22: EA Amboy Gen Mdse
F23: L & R's Hontomin Gen Mdse
F24: Davocol's Gen. Mdse.
F25: RCJ Hardware & Gen Mdse
... F86: Valiente Food Producer
F87: =DATA!W200 -> YCA Printing Services | G87: Golden Press | H87: CMVILL Trading | I87: One-Touch Technology Trading
A89: =PR!D16 -> Printing of Training Manual (Hardbound cover, laminated, colored,15.5 x 23 cm, 70 pages, 80gsm, colored, glossy with ISSN/ISBN number) | F89: =DATA!O200 -> 81000 | G89: 87500 | H89: 90000 | I89: none
A105: =PR!D32 -> 0 | F105: =DATA!O20 -> 1940 | G105: 3000 | H105: 1900
A106: =PR!D33 -> 0 | F106: =DATA!O21 -> 520 | G106: 590 | H106: 2800
A107: =PR!D34 -> 0 | B107: Bond paper, A4 size | C107: Bond paper, A4 size | D107: Bond paper, A4 size | E107: Bond paper, A4 size | F107: =DATA!O22 -> 1500 | G107: 1200 | H107: 7500
A108: =PR!D35 -> Laddle with wooden handle with hole | B108: Bond paper, A4 size | C108: Bond paper, A4 size | D108: Bond paper, A4 size | E108: Bond paper, A4 size | F108: =DATA!O23 -> 1980 | G108: 2800 | H108: 3500
A109: =PR!D36 -> Laddle with wooden handle without hole | B109: Bond paper, A4 size | C109: Bond paper, A4 size | D109: Bond paper, A4 size | E109: Bond paper, A4 size | F109: =DATA!O24 -> 900 | G109: 1500 | H109: 1200
A110: =PR!D37 -> Measuring Cup Glass | B110: Bond paper, A4 size | C110: Bond paper, A4 size | D110: Bond paper, A4 size | E110: Bond paper, A4 size | F110: =DATA!O25 -> 800 | G110: 1800 | H110: 1100
A111: =PR!D38 -> Measuring Cup Set Set Includes: 1/4 cup,1/3 cup, 1/2 cup,1 cup | B111: Bond paper, A4 size | C111: Bond paper, A4 size | D111: Bond paper, A4 size | E111: Bond paper, A4 size | F111: =DATA!O26 -> 550 | G111: 800 | H111: 1200
A112: =PR!D39 -> Measuring Spoon Set sets include: 1/8 teaspoon, 1/4 teaspoon, 1/2 teaspoon, 1 teaspoon, 1/ 2 tbsp, 1 tbsp | B112: Bond paper, A4 size | C112: Bond paper, A4 size | D112: Bond paper, A4 size | E112: Bond paper, A4 size | F112: =DATA!O27 -> 4500 | G112: 4500 | H112: 4600
A113: =PR!D40 -> Mixing Bowl with Cover 5pcs | B113: Bond paper, A4 size | C113: Bond paper, A4 size | D113: Bond paper, A4 size | E113: Bond paper, A4 size | F113: =DATA!O28 -> 8600 | G113: 16000 | H113: 11000
A114: =PR!D41 -> Fruit and Vegetable Peeler Stainless Steel 13 cm (5 ") | B114: Bond paper, A4 size | C114: Bond paper, A4 size | D114: Bond paper, A4 size | E114: Bond paper, A4 size | F114: =DATA!O29 -> 1400 | G114: 1600 | H114: 3600
A115: =PR!D42 -> Pot Holder Cloth 3pcs/set | B115: Bond paper, A4 size | C115: Bond paper, A4 size | D115: Bond paper, A4 size | E115: Bond paper, A4 size | F115: =DATA!O30 -> 1900 | G115: 1800 | H115: 2000
A116: =PR!D43 -> Pot Holder Heat Insulated Gloves Specifications: Color: Grey Material: silicone Size: 20.5x16.5cm | B116: Bond paper, A4 size | C116: Bond paper, A4 size | D116: Bond paper, A4 size | E116: Bond paper, A4 size | F116: =DATA!O31 -> 2800 | G116: 800 | H116: 5200
A117: =PR!D44 -> Knife Sharpener | B117: Bond paper, A4 size | C117: Bond paper, A4 size | D117: Bond paper, A4 size | E117: Bond paper, A4 size | F117: =DATA!O32 -> 2240 | G117: 2000 | H117: 5200
A118: =PR!D45 -> Sifter Stainless Steel 270 x 70mm Mesh: #30 (0.595mm) | B118: Bond paper, A4 size | C118: Bond paper, A4 size | D118: Bond paper, A4 size | E118: Bond paper, A4 size | F118: =DATA!O33 -> 2580 | G118: 1620 | H118: 4500
... A130: =PR!D57 -> Fire Extinguisher ABC Dry Chemical 10LBS | B130: Bond paper, A4 size | C130: Bond paper, A4 size | D130: Bond paper, A4 size | E130: Bond paper, A4 size | F130: =DATA!O45 -> 6900 | G130: 6840 | H130: 5760
A131: =PR!D58 -> Fruit and Vegetables Brush Soft Bristle | B131: Bond paper, A4 size | C131: Bond paper, A4 size | D131: Bond paper, A4 size | E131: Bond paper, A4 size
A132: =DATA!I317 -> Heavy Duty Nylon Rope (Dia;12mm ,200meters) | B132: Bond paper, A4 size | C132: Bond paper, A4 size | D132: Bond paper, A4 size | E132: Bond paper, A4 size
A133: =DATA!I318 -> Garden shade Net (70% shading rate) black length;100meters | B133: Bond paper, A4 size | C133: Bond paper, A4 size | D133: Bond paper, A4 size | E133: Bond paper, A4 size
...

