Workbook

Sheet PMR-Data
A2: MONTH | B2: (Multiple Items)
A3: YEAR | B3: (Multiple Items)
A5: PR# | B5: Purpose | C5: End-User | D5: Modality | E5: Delivery Date | F5: IAR Date | G5: Fund Code | H5: Class | I5: Status | J5: Sum of Estimated Total | K5: Sum of Total
A6: 202-013A | B6: supplies for the repair & maintenance of the building | C6: JERSHON RALPH F. CASTANO | D6: SVP | E6: August 23, 2021 | F6: August 23, 2021 | G6: 101 | H6: MOOE | I6: complete | J6: 85520 | K6: 65665
A7: 2021-001A | B7: snacks for the "Internal Quality Audit" on January 19-21, 2021 | J7: 17850 | K7: 17850
A8: 2021-002 | B8: Supply and installation of CCTV for Academic Building, Dormitory and Agriculture Building | C8: ALETH A. MEORA | D8: SVP | E8: April 27, 2021 | F8: May 26, 2021` | G8: 101 | H8: CO | I8: complete | J8: 435000 | K8: 397860
A9: 2021-002A | B9: to be used in the different activities and internet communication needs of BSC | C9: RANDALL G. CASTILLO | D9: SVP | E9: 5/19 & 7/19/2021 | F9: 5/26 & 7/21/2021 | G9: 101 | H9: (blank) | I9: complete | J9: 25500 | K9: 25480
A10: 2021-003 | B10: Purchase of Academic Equipment | C10: ALETH A. MEORA | D10: SVP | E10: 5/19 & 7/19/2021 | F10: 5/19 & 7/21/2021 | G10: 101 | H10: CO | I10: complete | J10: 947218.62 | K10: 928620
A11: 2021-003A | B11: for PBB compliance specifically transparency seal and BSC publication | C11: RANDALL G. CASTILLO | D11: SVP | E11: February 16, 2021 | F11: March 2, 2021 | G11: 165 | H11: MOOE | I11: complete | J11: 49000 | K11: 45560
A12: 2021-004 | B12: for the purchase of Academic Equipments | C12: ALETH A. MEORA | D12: SVP | E12: January 12, 2021 | F12: April 27, 2021 | G12: 101 | H12: CO | I12: complete | J12: 972105.5 | K12: 791000
A13: 2021-004A | B13: for the purchase of enrollment forms | C13: RHEA ANGELLICA B. ADDATU | D13: SVP | E13: August 23, 2021 | F13: August 23, 2021 | G13: 101 | H13: (blank) | I13: (blank) | J13: 22500 | K13: 22500
A14: 2021-005 | B14: Purchase of Academic Equipment | C14: ALETH A. MEORA | D14: SVP | E14: 44396 | F14: 44403 | G14: 101 | H14: CO | I14: reimbursement | J14: 378961.7 | K14: 359780
A15: 2021-005A | B15: to be used in the different activities and internet communication needs of BSC | C15: RANDALL G. CASTILLO | D15: SVP | E15: May 19, 2021 | F15: May 26, 2021 | G15: 101 | H15: MOOE | I15: complete | J15: 30250 | K15: 29960
A16: 2021-006 | B16: Supply and Delivery of Academic Equipment | C16: ALETH A. MEORA | D16: SVP | E16: January 12, 2021 | F16: January 25, 2021 | G16: 101 | H16: CO | I16: complete | J16: 315813.75 | K16: 195700
E17: January 25, 2021 | F17: January 25, 2021 | G17: 101 | H17: CO | I17: complete | J17: 45000 | K17: 42000
A18: 2021-006A | B18: for the ISO Activity Management Review on Feb. 3, 2021 | C18: ROMINA KATRINA C. BAYARAS | D18: SVP | E18: 44230 | F18: February 16, 2021 | G18: 164 | H18: MOOE | I18: complete | J18: 14000 | K18: 11800
A19: 2021-007A | B19: Internet data/Regular load Allocation of Administrative & Finance staff of the college to support online submission of reports & other related activities for the Fiscal Year 2021 | C19: DJOVI R. DURANTE | D19: SVP | E19: March 29, 2021 | F19: March 31, 2021 | G19: 101 | H19: MOOE | I19: complete | J19: 107880 | K19: 107880
A20: 2021-008A | B20: for the "ISO Documentation" | C20: ROMINA KATRINA C. BAYARAS | D20: SVP | E20: March 15, 2021 | F20: March 15, 2021 | G20: 164 | H20: MOOE | I20: complete | J20: 3960 | K20: 3885
A21: 2021-009 | B21: Purchase of Academic Furniture Fixtures | C21: ALETH A. MEORA | D21: SVP | E21: August 23, 2021 | F21: August 23, 2021 | G21: 101 | H21: MOOE | I21: complete | J21: 200000 | K21: 199680
A22: 2021-009A | B22: stamp use for the filing of ISO documents | C22: ROMINA KATRINA C. BAYARAS | D22: SVP | E22: - | F22: - | G22: 165 | H22: (blank) | I22: FAILED | J22: 28000 | K22: 0
A23: 2021-0100 | B23: for the Implementation of "ADOPT through Varied R & D of Ivatan Endemic Resources" research project | C23: JANE S. CASTILLO | D23: SVP | E23: August 23, 2021 | F23: August 23, 2021 | G23: 165 | H23: MOOE | I23: for delivery | J23: 30950 | K23: 29315
A24: 2021-0101 | B24: office supplies for the Administrative & Finance Services Units | C24: DJOVI R. DURANTE | D24: SVP | E24: August 23, 2021 | F24: August 23, 2021 | G24: 165 | H24: MOOE | I24: for delivery | J24: 30840 | K24: 28941.9
A25: 2021-0102 | B25: supplies for Budget office | C25: BRYAN DAVE P. REVILLA | D25: SVP | E25: August 23, 2021 | F25: August 23, 2021 | G25: 101 | H25: MOOE | I25: for delivery | J25: 3500 | K25: 2990
A26: 2021-0103 | B26: supplies for Budget office | C26: BRYAN DAVE P. REVILLA | D26: SVP | E26: July 1, 2021 | F26: July 1, 2021 | G26: 101 | H26: MOOE | I26: complete | J26: 790 | K26: 600
A27: 2021-0104 | B27: supplies for the Budget office | C27: BRYAN DAVE P. REVILLA | D27: SVP | E27: August 23, 2021 | F27: August 23, 2021 | G27: 101 | H27: MOOE | I27: for delivery | J27: 1000 | K27: 800
A28: 2021-0105 | B28: repair of 2 units floor type airconditioner at Faculty Room | C28: JERSHON RALPH F. CASTANO | D28: SVP | E28: August 23, 2021 | F28: August 23, 2021 | G28: (blank) | H28: (blank) | I28: FAILED | J28: 13000
A29: 2021-0106 | B29: GSO Supplies | C29: JERSHON RALPH F. CASTANO | D29: SVP | E29: July 19 & 26, 2021 | F29: July 21 & 26, 2021 | G29: 101 | H29: MOOE | I29: complete | J29: 10950 | K29: 8314
A30: 2021-0107 | B30: GSO Supplies | C30: JERSHON RALPH F. CASTANO | D30: SVP | E30: 44399 | F30: 44411 | G30: 101 | H30: MOOE | I30: reimbursement | J30: 18500 | K30: 15780
A31: 2021-0108 | B31: Snack for the Preparatory Board Meeting on June 25, 2021 at 10:00 a.m | C31: GERZON R. ABAD | D31: SVP | E31: August 23, 2021 | F31: August 23, 2021 | G31: (blank) | H31: (blank) | I31: FAILED | J31: 3000 | K31: 0
A32: 2021-0109 | B32: PM snack and dinner for the 52nd Board of Trustees Meeting on June 25, 2021 | C32: GERZON R. ABAD | D32: SVP | E32: June 25, 2021 | F32: 44377 | G32: 101 | H32: MOOE | I32: reimbursement | J32: 13000 | K32: 9000
A33: 2021-010A | B33: ink use for enrollment | C33: RHEA ANGELLICA B. ADDATU | D33: SVP | E33: August 23, 2021 | F33: August 23, 2021 | G33: 101 | H33: (blank) | I33: FAILED | J33: 1500
A34: 2021-0110 | B34: Lunch, PM Snack and Dinner of Commissioner Lilian A. De Las Llagas and Staff for the 52nd BOT Meeting on 25 June 2021 | C34: GERZON R. ABAD | D34: SVP | E34: August 23, 2021 | F34: August 23, 2021 | G34: (blank) | H34: (blank) | I34: reimbursement | J34: 12597.5 | K34: 12597.5
A35: 2021-0111 | B35: repair & maintenance of A/C units of Registrar's, Cashier's, Accountant's & President's office | C35: JERSHON RALPH F. CASATANO | D35: SVP | E35: August 23, 2021 | F35: August 23, 2021 | G35: 101 | H35: MOOE | I35: on-going | J35: 8000 | K35: 8000
A36: 2021-0112 | B36: supplies for the rewiring of faculty room electrical system | C36: JERSHON RALPH F. CASATANO | D36: SVP | E36: July 21, 2021 | F36: July 26, 2021 | G36: 101 | H36: MOOE | I36: complete | J36: 23700 | K36: 21624
A37: 2021-0113 | B37: for the purchase of Semi-expendable equipments purposes | C37: JERSHON RALPH F. CASATANO | D37: SVP | E37: August 23, 2021 | F37: August 23, 2021 | G37: 101 | H37: MOOE | I37: on-going | J37: 10000 | K37: 10000
A38: 2021-011A | B38: for the Pre Assessment Audit Plan on Feb. 10-11, 2021 | C38: ROMINA KATRINA C. BAYARAS | D38: SVP | E38: February 10-11, 2021 | F38: March 2, 2021 | G38: 164 | H38: MOOE | I38: complete | J38: 7500 | K38: 7125
A39: 2021-012A | B39: supplies for the repair & maintenance of transportation vehicle | C39: JERSHON RALPH F. CASTANO | D39: SVP | E39: March 31, 2021 | F39: April 5, 2021 | G39: 101 | H39: MOOE | I39: on-going | J39: 49399.99 | K39: 42550
A40: 2021-013 | B40: Puchase of drafting tables and chairs for the Academiic Furnitures and Fixtures | C40: ALETH A. MEORA | D40: SVP | E40: January 26, 2021 | F40: January 26, 2021 | G40: 101 | H40: CO | I40: complete | J40: 277500 | K40: 195000
A41: 2021-014A | B41: office machinery & equipment | C41: JERSHON RALPH F. CASTANO | D41: SVP | E41: March 29, 2021 | F41: March 30, 2021 | G41: 101 | H41: MOOE | I41: complete | J41: 47002 | K41: 42500
A42: 2021-015A | B42: supplies for janitorial services | C42: JERSHON RALPH F. CASTANO | D42: SVP | E42: April 15, 2021 | F42: April 15, 2021 | G42: 101 | H42: MOOE | I42: complete | J42: 5000 | K42: 3000
...

Sheet Suppliers TIN
B1: Business Name | C1: Name/Owner | D1: TIN #
A2: 1 | B2: Apostol General Merchandise | C2: Leo A. Apostol | D2: 183-008-448
A3: 2 | B3: Bartilad's Feeds Trading | C3: Roldan Q. Bartilad | D3: 771-272-422
A4: 3 | B4: Bitstop Network Services Inc. | C4: JC James P. Jihay | D4: 005-931-291
A5: 4 | B5: Casa Del Basco | D5: 107-549-729
A6: 5 | B6: Crisel General Merchandise | C6: Cresencio M. Verana | D6: 135-792-662
A7: 6 | B7: Claire's Drugstore | C7: Claire H. Abad | D7: 264-438-671
A8: 7 | B8: Davocol's General Merchandise | C8: Lilibeth T. Davocol | D8: 116-311-342
A9: 8 | B9: Davocol's Inn | C9: Dan Ardie T. Davocol | D9: 739-884-154
A10: 9 | B10: D' Islands Gasoline Station | C10: Lito Doroteo A. Adarme | D10: 124-072-664
A11: 10 | B11: Doque's Congie Hauz | C11: Glenda L. Gordo | D11: 922-904-311
A12: 11 | B12: D. Michael Co Industrial Supply (DMC) Corp. | C12: Eunelyn O. Ramilla | D12: 007-776-953
A13: 12 | B13: E. A. Amboy General Merchandise | C13: Cesar Edgardo Amboy | D13: 928-655-269
A14: 13 | B14: Enrinar Trading | C14: Narcisa Co Melad | D14: 123-394-221
A15: 14 | B15: FMG Trading & Construction Supply | C15: Frederick Gari | D15: 219-884-940
A16: 15 | B16: GDP Trading | C16: George D. Peralta | D16: 150-214-534
A17: 16 | B17: Hubalde's Drugstore | C17: Marilyn G. Hubalde | D17: 914-979-941
A18: 17 | B18: Hudzan Café & Catering Services | C18: Susan Villegas | D18: 290-315-057 | E18: **
A19: 18 | B19: I.B.S Pharmacy & General Merchadise | C19: Dale Anthony C. Gutierrez | D19: 411-599-160
A20: 19 | B20: IAM'J Graphic Design & Printing | C20: Jaycy S. Alina | D20: 318-666-833
A21: 20 | B21: JPM General Merchandise & Hardware | C21: Emma P. Adarme | D21: 160-183-814
A22: 21 | B22: J-Tech Trading & Services | C22: Cecilia C. De Sagon | D22: 933-429-635
A23: 22 | B23: M.G. Hubalde's General Merchandise | C23: Marilyn G. Hubalde | D23: 914-979-941-001
A24: 23 | B24: MDAC Trading & Compuserve | C24: Florescita A. Cruz | D24: 100-194-776
A25: 24 | B25: NRA Hardware | C25: Neil Bernardo Ordas | D25: 196-062-499
A26: 25 | B26: One-Touch Technology Trading | C26: Janice A. Alasco | D26: 283-009-327
A27: 26 | B27: Pension Ivatan | C27: Teresita D. Valiente | D27: 106-115-883
A28: 27 | B28: Sophia Marie Store | C28: Regina B. Gabaldon | D28: 279-057-542
A29: 28 | B29: Twixbiz General Merchandise | C29: Charles B. Domingo | D29: 118-687-531
A30: 29 | B30: Northern Star General Merchandise | C30: Cesar A. Calma | D30: 151-407-774
... A37: 36 | B37: MKM Hardware | C37: Enrique Abuyo Melad Jr. | D37: 148-780-907
A38: 37 | B38: NSGB Books Trading | C38: Nica Sandra Go Banag
A39: 38 | B39: ONPREM2CLOUD IT SOLUTIONS CO. | C39: Emmanuel B. Mamayson | D39: 101-626-582
A40: 39 | B40: Petonio's Kitchen Food Services | C40: Ramona C. Tabuso | D40: 013-000-080-045-720-21
A41: 40 | B41: Tiger Consulting and Software Devt Inc. | D41: 007-073-548
A42: 41 | B42: MOJR Construction Trading & General Services, Ltd, Co. | C42: Manuel S. Obedoza Jr.
A43: 42 | B43: Batanes Electric Cooperative Inc. | C43: Victoria A. Mata | D43: 005-641-216-000
A44: 43 | B44: Maddies Fashion Design Services | C44: Madeline Palencia Palustre
A45: 44 | B45: CMVILL Trading | C45: Zariffe G. Villanueva | D45: 421-603-862-000
A46: 45 | B46: VL Mini Canteen | C46: Estela N. Lizardo | D46: 930-779-799
...

Sheet FundCodes
A1: CODE | B1: CATEGORY | C1: OFFICE/UNIT
A2: GAS1 | B2: General Administration Services | C2: Office of the President
A3: GAS2 | B3: General Administration Services | C3: Office of the Board Secretary
A4: GAS3 | B4: General Administration Services | C4: Office of the College Secretary | G4: Fund
A5: GAS4 | B5: General Administration Services | C5: Information & Communications Technology Unit | G5: 01-101
A6: GAS5 | B6: General Administration Services | C6: Information Unit | G6: 05-164
A7: GAS6 | B7: General Administration Services | C7: Internal Audit Unit | G7: 06-162
A8: GAS7 | B8: General Administration Services | C8: Legal Unit | G8: 07-165
A9: GAS8 | B9: General Administration Services | C9: Planning Unit
A10: GAS9 | B10: General Administration Services | C10: Project Management Unit
A11: GAS10 | B11: General Administration Services | C11: Quality Assurance Office
A12: GAS11 | B12: General Administration Services | C12: Administrative Office
A13: GAS12 | B13: General Administration Services | C13: Cash Unit
A14: GAS13 | B14: General Administration Services | C14: General Services Unit
A15: GAS14 | B15: General Administration Services | C15: Human Resource Management Unit
A16: GAS15 | B16: General Administration Services | C16: Procurement Unit
A17: GAS16 | B17: General Administration Services | C17: Records Unit
A18: GAS17 | B18: General Administration Services | C18: Supply & Property Management Unit
A19: GAS18 | B19: General Administration Services | C19: Accounting Unit
A20: GAS19 | B20: General Administration Services | C20: Budget Unit
... A42: Acad9 | B42: Director for Instruction | C42: DI
A43: 1005 | B43: Research & Extension Services | C43: Research & Extension Office
A44: 1006 | B44: Business Affairs Office | C44: Business Affairs Office
A45: 1006A | B45: College Assessment Center | C45: College Assessment Center
A46: 1006B | C46: CBAO-IGP
A47: 1006C | C47: CBAO-Dorm
A48: 1006D | C48: CBAO-Hostel

Sheet DATA
A1: YEAR | B1: MONTH | C1: End-User | D1: Position/Designation | E1: Fund Code | F1: Class | G1: PR# | H1: Modality | I1: Item | J1: Quantity | K1: Unit of Issue | L1: Unit Budget | M1: Estimated Total | N1: Unit LCRB | O1: Total | P1: Purpose | Q1: Office | R1: Date of LON | S1: Date of BAC Award | T1: PO/Contract Date Received | U1: Delivery Date | V1: Supplier | W1: IAR Date | X1: Section Code/Dept. | Y1: Released Date | Z1: Status | AA1: Remarks | AB1: ObR # | AC1: # of RFQ's printed | AD1: Sales/Charge Invoice/Billing
A2: 2025 | B2: May | C2: JANE S. CASTILLO | D2: Chair,Program Committee | E2: 101 | G2: 2025-173 | H2: SVP | I2: Wooden Plaque (A4), see attached content | J2: 9 | K2: pcs | L2: 1000 | M2: =SUM(J2*L2) -> 9000 | N2: 1000 | O2: =SUM(J2*N2) -> 9000 | P2: supplies & materials for the conduct of 2025 Commencement Excercises,Recognition Rites & Parents Night | Q2: DI | R2: May 22, 2025 | S2: June 3, 2025 | T2: June 4, 2025 | U2: June 16, 2025 | V2: SKE Souvenir Trading | W2: June 16, 2025 | X2: Acad9 | Y2: August 22, 2025 | Z2: complete | AA2: for payment-Acctg. | AB2: 02-101101-2025-06-00357 | AC2: 3 RFQ's | AD2: 0230/6/16/2025
A3: 2025 | B3: May | C3: JANE S. CASTILLO | D3: Chair,Program Committee | E3: 101 | G3: 2025-174 | H3: SVP | I3: Tarpaulin (6ft x 4ft) | J3: 1 | K3: pcs | L3: 1000 | M3: =SUM(J3*L3) -> 1000 | N3: 720 | O3: =SUM(J3*N3) -> 720 | P3: supplies & materials for the conduct of 2025 Commencement Excercises,Recognition Rites & Parents Night | Q3: DI | R3: May 16, 2025 | S3: May 20, 2025 | T3: May 21, 2025 | U3: May 21, 2025 | V3: YCA Printing Services | W3: May 21, 2025 | X3: Acad9 | Y3: August 26, 2025 | Z3: complete | AA3: for payment-Acctg. | AB3: 02-101101-2025-05-00309 | AC3: 3 RFQ's | AD3: 336/5/21/2025
A4: 2025 | B4: May | C4: JANE S. CASTILLO | D4: Chair,Program Committee | E4: 101 | G4: 2025-175 | H4: SVP | I4: Specialty Paper(10 pcs per pack),A4-size, Color: white,GSM-200 | J4: 150 | K4: packs | L4: 150 | M4: =SUM(J4*L4) -> 22500 | N4: 65 | O4: =SUM(J4*N4) -> 9750 | P4: supplies & materials for the conduct of 2025 Commencement Excercises,Recognition Rites & Parents Night | Q4: DI | R4: May 22, 2025 | S4: June 3, 2025 | T4: June 4, 2025 | U4: June 16, 2025 | V4: JPM General Merchandise & Hardware | W4: June 16, 2025 | X4: Acad9 | Y4: June 25, 2025 | Z4: complete | AA4: for payment-Acctg. | AB4: 02-101101-2025-06-00358 | AC4: 5 RFQ's + 1blank | AD4: 12921/
A5: 2025 | B5: May | C5: JANE S. CASTILLO | D5: Chair,Program Committee | E5: 101 | G5: 2025-175 | H5: SVP | I5: Ink (003,black,yellow,cyan,magenta) | J5: 3 | K5: set | L5: 4500 | M5: =SUM(J5*L5) -> 13500 | N5: 1800 | O5: =SUM(J5*N5) -> 5400 | P5: supplies & materials for the conduct of 2025 Commencement Excercises,Recognition Rites & Parents Night | Q5: DI | R5: May 22, 2025 | S5: June 3, 2025 | T5: June 4, 2025 | U5: June 16, 2025 | V5: JPM General Merchandise & Hardware | W5: June 16, 2025 | X5: Acad9 | Y5: June 25, 2025 | Z5: complete | AA5: for payment-Acctg. | AB5: 02-101101-2025-06-00358
A6: 2025 | B6: May | C6: JANE S. CASTILLO | D6: Chair,Program Committee | E6: 101 | G6: 2025-175 | H6: SVP | I6: Certificate Holder (A4) | J6: 300 | K6: pcs | L6: 100 | M6: =SUM(J6*L6) -> 30000 | N6: 80 | O6: =SUM(J6*N6) -> 24000 | P6: supplies & materials for the conduct of 2025 Commencement Excercises,Recognition Rites & Parents Night | Q6: DI | R6: May 22, 2025 | S6: June 3, 2025 | T6: June 4, 2025 | U6: June 16, 2025 | V6: JPM General Merchandise & Hardware | W6: June 16, 2025 | X6: Acad9 | Y6: June 25, 2025 | Z6: complete | AA6: for payment-Acctg. | AB6: 02-101101-2025-06-00358
A7: 2025 | B7: May | C7: JANE S. CASTILLO | D7: Chair,Program Committee | E7: 101 | G7: 2025-175 | H7: SVP | I7: Bondpaper (A4,70 gsm, 5 reams/box) | J7: 4 | K7: box | L7: 1450 | M7: =SUM(J7*L7) -> 5800 | N7: 1325 | O7: =SUM(J7*N7) -> 5300 | P7: supplies & materials for the conduct of 2025 Commencement Excercises,Recognition Rites & Parents Night | Q7: DI | R7: May 22, 2025 | S7: June 3, 2025 | T7: June 4, 2025 | U7: June 16, 2025 | V7: JPM General Merchandise & Hardware | W7: June 16, 2025 | X7: Acad9 | Y7: June 25, 2025 | Z7: complete | AA7: for payment-Acctg. | AB7: 02-101101-2025-06-00358
A8: 2025 | B8: May | C8: VILMA D. BACCAY | D8: Acting College Registrar | G8: 2025-176 | H8: SVP | I8: Graduation Medal (diameter; 9cm, maroon-black gradient border) Summa Cum Laude | J8: 2 | K8: pcs | L8: 400 | M8: =SUM(J8*L8) -> 800 | O8: =SUM(J8*N8) -> 0 | P8: medals for Academic Awardees for Graduation 2025 Ceremony | Q8: DI | X8: Acad9 | Z8: CANCELLED | AA8: by the end-user (use the remaining supplies for last year)
A9: 2025 | B9: May | C9: VILMA D. BACCAY | D9: Acting College Registrar | G9: 2025-176 | H9: SVP | I9: Graduation Medal (diameter; 8cm, maroon-black gradient border) Magna Cum Laude | J9: 5 | K9: pcs | L9: 390 | M9: =SUM(J9*L9) -> 1950 | O9: =SUM(J9*N9) -> 0 | P9: medals for Academic Awardees for Graduation 2025 Ceremony | Q9: DI | X9: Acad9
A10: 2025 | B10: May | C10: VILMA D. BACCAY | D10: Acting College Registrar | G10: 2025-176 | H10: SVP | I10: Graduation Medal (diameter; 7cm, maroon-black gradient border) Cum Laude | J10: 20 | K10: pcs | L10: 350 | M10: =SUM(J10*L10) -> 7000 | O10: =SUM(J10*N10) -> 0 | P10: medals for Academic Awardees for Graduation 2025 Ceremony | Q10: DI | X10: Acad9
A11: 2025 | B11: May | C11: VILMA D. BACCAY | D11: Acting College Registrar | G11: 2025-176 | H11: SVP | I11: Graduation Medal (diameter; 7cm, maroon-black gradient border) with Academic Distinction | J11: 5 | K11: pcs | L11: 350 | M11: =SUM(J11*L11) -> 1750 | O11: =SUM(J11*N11) -> 0 | P11: medals for Academic Awardees for Graduation 2025 Ceremony | Q11: DI | X11: Acad9
A12: 2025 | B12: May | C12: VILMA D. BACCAY | D12: Acting College Registrar | G12: 2025-177 | H12: SVP | I12: Emerald Green Satin Ribbon (1") | J12: 1 | K12: roll | L12: 250 | M12: =SUM(J12*L12) -> 250 | O12: =SUM(J12*N12) -> 0 | P12: for use in preparing academic medals for Graduation 2025 | Q12: DI | X12: Acad9 | Z12: CANCELLED
A13: 2025 | B13: May | C13: VILMA D. BACCAY | D13: Acting College Registrar | G13: 2025-177 | H13: SVP | I13: Metallic Gold Satin Ribbon (1/2") | J13: 1 | K13: roll | L13: 200 | M13: =SUM(J13*L13) -> 200 | O13: =SUM(J13*N13) -> 0 | P13: for use in preparing academic medals for Graduation 2025 | Q13: DI
A14: 2025 | B14: May | C14: VILMA D. BACCAY | D14: Acting College Registrar | G14: 2025-177 | H14: SVP | I14: Button Lock/Rematche Hand Press machine | J14: 1 | K14: pc | L14: 3000 | M14: =SUM(J14*L14) -> 3000 | O14: =SUM(J14*N14) -> 0 | P14: for use in preparing academic medals for Graduation 2025 | Q14: DI | X14: Acad9
A15: 2025 | B15: May | C15: JOHN MICHAEL A. VILLASPIR | D15: Administrative Officer I | G15: 2025-178 | H15: SVP | I15: 1/2 Copper Tube | J15: 6 | K15: rolls | L15: 4100 | M15: =SUM(J15*L15) -> 24600 | O15: =SUM(J15*N15) -> 0 | P15: use for installation of Airconditioning Unit | Q15: GSO | X15: GAS20 | Z15: FAILED | AA15: qoutation exceeded the budget | AC15: 4 RFQ's + 1blank
A16: 2025 | B16: May | C16: JOHN MICHAEL A. VILLASPIR | D16: Administrative Officer I | G16: 2025-178 | H16: SVP | I16: 1/4 Copper Tube | J16: 9 | K16: rolls | L16: 1990 | M16: =SUM(J16*L16) -> 17910 | O16: =SUM(J16*N16) -> 0 | P16: use for installation of Airconditioning Unit | Q16: GSO | X16: GAS20
A17: 2025 | B17: May | C17: JOHN MICHAEL A. VILLASPIR | D17: Administrative Officer I | G17: 2025-178 | H17: SVP | I17: 1 1/2 Stainless Dyna Bolt | J17: 50 | K17: pcs | L17: 20 | M17: =SUM(J17*L17) -> 1000 | O17: =SUM(J17*N17) -> 0 | P17: use for installation of Airconditioning Unit | Q17: GSO | X17: GAS20
A18: 2025 | B18: May | C18: JOHN MICHAEL A. VILLASPIR | D18: Administrative Officer I | G18: 2025-178 | H18: SVP | I18: Mapro Gas | J18: 5 | K18: pcs | L18: 580 | M18: =SUM(J18*L18) -> 2900 | O18: =SUM(J18*N18) -> 0 | P18: use for installation of Airconditioning Unit | Q18: GSO | X18: GAS20
A19: 2025 | B19: May | C19: JOHN MICHAEL A. VILLASPIR | D19: Administrative Officer I | G19: 2025-178 | H19: SVP | I19: #12 AWG THHN Wire | J19: 3 | K19: rolls | L19: 5500 | M19: =SUM(J19*L19) -> 16500 | O19: =SUM(J19*N19) -> 0 | P19: use for installation of Airconditioning Unit | Q19: GSO | X19: GAS20
A20: 2025 | B20: May | C20: MICHEL A. CABRERA | D20: Assistant Professor IV | E20: 165 | G20: 2025-179 | H20: SVP | I20: Black Ink Refill (774) 140ml | J20: 4 | K20: bottle | L20: 900 | M20: =SUM(J20*L20) -> 3600 | N20: 800 | O20: =SUM(J20*N20) -> 3200 | P20: to be used for instruction and office supplies | Q20: ICT | R20: May 30, 2025 | S20: June 3, 2025 | T20: June 4, 2025 | U20: July 3, 2025 | V20: One-Touch Technology Trading | W20: July 3, 2025 | X20: GAS4 | Y20: 45883 | Z20: complete | AA20: for payment-Acctg. | AB20: 07-02-2025-06-0201 | AC20: 5 RFQ's | AD20: 7799/7/3/2025
A21: 2025 | B21: May | C21: MICHEL A. CABRERA | D21: Assistant Professor IV | E21: 165 | G21: 2025-179 | H21: SVP | I21: Cyan Ink Refill (664) 70ml | J21: 2 | K21: bottle | L21: 450 | M21: =SUM(J21*L21) -> 900 | N21: 450 | O21: =SUM(J21*N21) -> 900 | P21: to be used for instruction and office supplies | Q21: ICT | R21: May 30, 2025 | S21: June 3, 2025 | T21: June 4, 2025 | U21: July 3, 2025 | V21: One-Touch Technology Trading | W21: July 3, 2025 | X21: GAS4 | Y21: 45883 | Z21: complete | AA21: for payment-Acctg. | AB21: 07-02-2025-06-0201
A22: 2025 | B22: May | C22: MICHEL A. CABRERA | D22: Assistant Professor IV | E22: 165 | G22: 2025-179 | H22: SVP | I22: Cyan Ink Refill (664) 70ml | J22: 2 | K22: bottle | L22: 450 | M22: =SUM(J22*L22) -> 900 | N22: 450 | O22: =SUM(J22*N22) -> 900 | P22: to be used for instruction and office supplies | Q22: ICT | R22: May 30, 2025 | S22: June 3, 2025 | T22: June 4, 2025 | U22: July 3, 2025 | V22: One-Touch Technology Trading | W22: July 3, 2025 | X22: GAS4 | Y22: 45883 | Z22: complete | AA22: for payment-Acctg. | AB22: 07-02-2025-06-0201
A23: 2025 | B23: May | C23: MICHEL A. CABRERA | D23: Assistant Professor IV | E23: 165 | G23: 2025-179 | H23: SVP | I23: Magenta Ink Refill (664) 70ml | J23: 2 | K23: bottle | L23: 450 | M23: =SUM(J23*L23) -> 900 | N23: 450 | O23: =SUM(J23*N23) -> 900 | P23: to be used for instruction and office supplies | Q23: ICT | R23: May 30, 2025 | S23: June 3, 2025 | T23: June 4, 2025 | U23: July 3, 2025 | V23: One-Touch Technology Trading | W23: July 3, 2025 | X23: GAS4 | Y23: 45883 | Z23: complete | AA23: for payment-Acctg. | AB23: 07-02-2025-06-0201
A24: 2025 | B24: May | C24: MICHEL A. CABRERA | D24: Assistant Professor IV | E24: 165 | G24: 2025-179 | H24: SVP | I24: L14150 Ink Refill 001 (CMYK) 65ml | J24: 3 | K24: set | L24: 2000 | M24: =SUM(J24*L24) -> 6000 | N24: 2220 | O24: =SUM(J24*N24) -> 6660 | P24: to be used for instruction and office supplies | Q24: ICT | R24: May 30, 2025 | S24: June 3, 2025 | T24: June 4, 2025 | U24: July 3, 2025 | V24: One-Touch Technology Trading | W24: July 3, 2025 | X24: GAS4 | Y24: 45883 | Z24: complete | AA24: for payment-Acctg. | AB24: 07-02-2025-06-0201
A25: 2025 | B25: May | C25: MICHEL A. CABRERA | D25: Assistant Professor IV | E25: 165 | G25: 2025-179 | H25: SVP | I25: Specialty Paper (white,A4) | J25: 15 | K25: packs | L25: 200 | M25: =SUM(J25*L25) -> 3000 | N25: 65 | O25: =SUM(J25*N25) -> 975 | P25: to be used for instruction and office supplies | Q25: ICT | R25: May 30, 2025 | S25: June 3, 2025 | T25: June 4, 2025 | U25: July 3, 2025 | V25: One-Touch Technology Trading | W25: July 3, 2025 | X25: GAS4 | Y25: 45883 | Z25: complete | AA25: for payment-Acctg. | AB25: 07-02-2025-06-0201
A26: 2025 | B26: May | C26: MICHEL A. CABRERA | D26: Assistant Professor IV | E26: 165 | G26: 2025-179 | H26: SVP | I26: L3110 Ink Refill 003 (CMYK) 65ml | J26: 2 | K26: set | L26: 2000 | M26: =SUM(J26*L26) -> 4000 | N26: 1880 | O26: =SUM(J26*N26) -> 3760 | P26: to be used for instruction and office supplies | Q26: ICT | R26: May 30, 2025 | S26: June 3, 2025 | T26: June 4, 2025 | U26: July 3, 2025 | V26: One-Touch Technology Trading | W26: July 3, 2025 | X26: GAS4 | Y26: 45883 | Z26: complete | AA26: for payment-Acctg. | AB26: 07-02-2025-06-0201
A27: 2025 | B27: May | C27: MICHEL A. CABRERA | D27: Assistant Professor IV | G27: 2025-180 | H27: SVP | I27: Routerboard RouterOS L5 1U 8-port gigabit router (RB5009UG+S+IN) | J27: 2 | K27: pcs | L27: 18525 | M27: =SUM(J27*L27) -> 37050 | O27: =SUM(J27*N27) -> 0 | P27: to be used for instruction and office supplies | Q27: ICT | X27: GAS4 | Z27: FAILED | AA27: quotation exceeded the budget | AC27: 4 RFQ's + 1blank
A28: 2025 | B28: May | C28: MICHEL A. CABRERA | D28: Assistant Professor IV | G28: 2025-180 | H28: SVP | I28: Router Board | J28: 5 | K28: pcs | L28: 2250 | M28: =SUM(J28*L28) -> 11250 | O28: =SUM(J28*N28) -> 0 | P28: to be used for instruction and office supplies | Q28: ICT | X28: GAS4
A29: 2025 | B29: May | C29: MICHEL A. CABRERA | D29: Assistant Professor IV | G29: 2025-180 | H29: SVP | I29: Canon Lens EF-S 55-250mm (f4-5.6 lS STM | J29: 1 | K29: pc | L29: 29250 | M29: =SUM(J29*L29) -> 29250 | O29: =SUM(J29*N29) -> 0 | P29: to be used for instruction and office supplies | Q29: ICT | X29: GAS4
A30: 2025 | B30: May | C30: MICHEL A. CABRERA | D30: Assistant Professor IV | G30: 2025-180 | H30: SVP | I30: Canon LP-E17 battery for camera EOS 200D | J30: 1 | K30: pc | L30: 3300 | M30: =SUM(J30*L30) -> 3300 | O30: =SUM(J30*N30) -> 0 | P30: to be used for instruction and office supplies | Q30: ICT | X30: GAS4
A31: 2025 | B31: May | C31: MICHEL A. CABRERA | D31: Assistant Professor IV | G31: 2025-180 | H31: SVP | I31: Expansion Portable Drive 2TB XHDD | J31: 1 | K31: pc | L31: 3450 | M31: =SUM(J31*L31) -> 3450 | O31: =SUM(J31*N31) -> 0 | P31: to be used for instruction and office supplies | Q31: ICT | X31: GAS4
A32: 2025 | B32: May | C32: PHILIP ULYSSES T. CASTILLO | D32: Attorney IV | E32: 101 | G32: 2025-181 | H32: SVP | I32: Heavy Duty Extension Cord Set with individual switch (4 gang) | J32: 1 | K32: pc | L32: 1000 | M32: =SUM(J32*L32) -> 1000 | N32: 1680 | O32: =SUM(J32*N32) -> 1680 | P32: for office use | Q32: Legal | R32: May 30, 2025 | S32: June 3, 2025 | T32: June 4, 2025 | U32: July 3, 2025 | V32: One-Touch Technology Trading | W32: July 3, 2025 | X32: GAS7 | Y32: 45883 | Z32: complete | AA32: for payment-Acctg. | AB32: 02-101101-2025-06-00359 | AC32: 4 RFQ's | AD32: 7800/7/3/2025
A33: 2025 | B33: May | C33: PHILIP ULYSSES T. CASTILLO | D33: Attorney IV | E33: 101 | G33: 2025-181 | H33: SVP | I33: Staple Wire (26/6) | J33: 2 | K33: box | L33: 300 | M33: =SUM(J33*L33) -> 600 | N33: 50 | O33: =SUM(J33*N33) -> 100 | P33: for office use | Q33: Legal | R33: May 30, 2025 | S33: June 3, 2025 | T33: June 4, 2025 | U33: July 3, 2025 | V33: One-Touch Technology Trading | W33: July 3, 2025 | X33: GAS7 | Y33: 45883 | Z33: complete | AA33: for payment-Acctg. | AB33: 02-101101-2025-06-00359
A34: 2025 | B34: May | C34: PHILIP ULYSSES T. CASTILLO | D34: Attorney IV | E34: 101 | G34: 2025-181 | H34: SVP | I34: Red Ballpen (0.5) | J34: 1 | K34: doz | L34: 250 | M34: =SUM(J34*L34) -> 250 | N34: 180 | O34: =SUM(J34*N34) -> 180 | P34: for office use | Q34: Legal | R34: May 30, 2025 | S34: June 3, 2025 | T34: June 4, 2025 | U34: July 3, 2025 | V34: One-Touch Technology Trading | W34: July 3, 2025 | X34: GAS7 | Y34: 45883 | Z34: complete | AA34: for payment-Acctg. | AB34: 02-101101-2025-06-00359
A35: 2025 | B35: May | C35: PHILIP ULYSSES T. CASTILLO | D35: Attorney IV | E35: 101 | G35: 2025-181 | H35: SVP | I35: USB 64GB | J35: 2 | K35: pcs | L35: 500 | M35: =SUM(J35*L35) -> 1000 | N35: 580 | O35: =SUM(J35*N35) -> 1160 | P35: for office use | Q35: Legal | R35: May 30, 2025 | S35: June 3, 2025 | T35: June 4, 2025 | U35: July 3, 2025 | V35: One-Touch Technology Trading | W35: July 3, 2025 | X35: GAS7 | Y35: 45883 | Z35: complete | AA35: for payment-Acctg. | AB35: 02-101101-2025-06-00359
A36: 2025 | B36: May | C36: PHILIP ULYSSES T. CASTILLO | D36: Attorney IV | E36: 101 | G36: 2025-181 | H36: SVP | I36: Self Ink Stamp (Receive with date) | J36: 1 | K36: pc | L36: 500 | M36: =SUM(J36*L36) -> 500 | N36: 980 | O36: =SUM(J36*N36) -> 980 | P36: for office use | Q36: Legal | R36: May 30, 2025 | S36: June 3, 2025 | T36: June 4, 2025 | U36: July 3, 2025 | V36: One-Touch Technology Trading | W36: July 3, 2025 | X36: GAS7 | Y36: 45883 | Z36: complete | AA36: for payment-Acctg. | AB36: 02-101101-2025-06-00359
A37: 2025 | B37: May | C37: PHILIP ULYSSES T. CASTILLO | D37: Attorney IV | E37: 101 | G37: 2025-181 | H37: SVP | I37: Whiteboard (40*60cm) | J37: 1 | K37: pc | L37: 800 | M37: =SUM(J37*L37) -> 800 | N37: 600 | O37: =SUM(J37*N37) -> 600 | P37: for office use | Q37: Legal | R37: May 30, 2025 | S37: June 3, 2025 | T37: June 4, 2025 | U37: July 3, 2025 | V37: One-Touch Technology Trading | W37: July 3, 2025 | X37: GAS7 | Y37: 45883 | Z37: complete | AA37: for payment-Acctg. | AB37: 02-101101-2025-06-00359
A38: 2025 | B38: May | C38: PHILIP ULYSSES T. CASTILLO | D38: Attorney IV | E38: 101 | G38: 2025-181 | H38: SVP | I38: Whiteboard Marker (2 red, 2 black, 2 blue) | J38: 6 | K38: pcs | L38: 85 | M38: =SUM(J38*L38) -> 510 | N38: 50 | O38: =SUM(J38*N38) -> 300 | P38: for office use | Q38: Legal | R38: May 30, 2025 | S38: June 3, 2025 | T38: June 4, 2025 | U38: July 3, 2025 | V38: One-Touch Technology Trading | W38: July 3, 2025 | X38: GAS7 | Y38: 45883 | Z38: complete | AA38: for payment-Acctg. | AB38: 02-101101-2025-06-00359
A39: 2025 | B39: May | C39: PHILIP ULYSSES T. CASTILLO | D39: Attorney IV | E39: 101 | G39: 2025-181 | H39: SVP | I39: Magnetic Whiteboard Eraser | J39: 1 | K39: pc | L39: 250 | M39: =SUM(J39*L39) -> 250 | N39: 80 | O39: =SUM(J39*N39) -> 80 | P39: for office use | Q39: Legal | R39: May 30, 2025 | S39: June 3, 2025 | T39: June 4, 2025 | U39: July 3, 2025 | V39: One-Touch Technology Trading | W39: July 3, 2025 | X39: GAS7 | Y39: 45883 | Z39: complete | AA39: for payment-Acctg. | AB39: 02-101101-2025-06-00359
A40: 2025 | B40: May | C40: PHILIP ULYSSES T. CASTILLO | D40: Attorney IV | E40: 101 | G40: 2025-181 | H40: SVP | I40: Assorted Highlighter | J40: 1 | K40: set | L40: 350 | M40: =SUM(J40*L40) -> 350 | N40: 180 | O40: =SUM(J40*N40) -> 180 | P40: for office use | Q40: Legal | R40: May 30, 2025 | S40: June 3, 2025 | T40: June 4, 2025 | U40: July 3, 2025 | V40: One-Touch Technology Trading | W40: July 3, 2025 | X40: GAS7 | Y40: 45883 | Z40: complete | AA40: for payment-Acctg. | AB40: 02-101101-2025-06-00359
...

Sheet PR
A7: PURCHASE REQUEST
D9: PR No. | E9: =DATA!G60 -> 2025-190 | F9: Date
A10: Department: | D10: SAI No.: | E10: .
A11: Section: | B11: =DATA!X60 -> GAS5 | D11: OBR#
A12: Ref. No.: | B12: 2505-GAS5-190
A14: Qty | B14: Unit of Issue | D14: Item Description | F14: Stock No. | G14: Estimated
G15: Unit Cost | H15: Total Cost
A16: =DATA!J60 -> 1 | B16: =DATA!K60 -> set | D16: =DATA!I60 -> Single Face P4 HD Outdoor LED Screen (rear maintenance), Full Set Up including controller (Novastar) & receiving card (Novastar) warranty, after sales support & training controller (novastar) & receiving card (novastar)warranty , after sales support & training size: 2.88M x 2.88M (9 panels) screen resolution; 720 pixels (W) x 720 pixels (H) Type; movable frame Accessories: replacement module , replacemenr power supply,replacement receiving card,power cable,signal cable FREE: LED control software Training and Support | G16: =DATA!L60 -> 650000 | H16: =SUM(A16*G16) -> 650000
H17: =SUM(A17*G17) -> 0
H18: =SUM(A18*G18) -> 0
H19: =SUM(A19*G19) -> 0
H20: =SUM(A20*G20) -> 0
H21: =SUM(A21*G21) -> 0
H22: =SUM(A22*G22) -> 0
H23: =SUM(A23*G23) -> 0
H24: =SUM(A24*G24) -> 0
H25: =SUM(A25*G25) -> 0
H26: =SUM(A26*G26) -> 0
H27: =SUM(A27*G27) -> 0
H28: =SUM(A28*G28) -> 0
H29: =SUM(A29*G29) -> 0
A30: =DATA!J252 -> 1 | B30: =DATA!K252 -> copy | D30: =DATA!I252 -> Design and Implement the Curriculum to Foster Children's Learning and Development, 3G E-Leraning, 2022, Wiseman's Book Trading, Inc. | G30: =DATA!L252 -> 4998 | H30: =SUM(A30*G30) -> 4998
A31: =DATA!J253 -> 1 | B31: =DATA!K253 -> copy | D31: =DATA!I253 -> Designing of Applied Qualitative Research, Davies, 2024, 9781984658661, Wiseman's Book Trading, Inc. | G31: =DATA!L253 -> 6998 | H31: =SUM(A31*G31) -> 6998
A32: =DATA!J254 -> 1 | B32: =DATA!K254 -> copy | D32: =DATA!I254 -> Encyclopedia of Earth Science, Malode, 2024, 9781774693902, Wiseman's Book Trading, Inc. | G32: =DATA!L254 -> 6998 | H32: =SUM(A32*G32) -> 6998
A33: =DATA!J255 -> 1 | B33: =DATA!K255 -> copy | D33: =DATA!I255 -> Assessment in learning 1 (Traditional Assessment) OBE Approach, Abrogena, 2024, Big Faith Trading | G33: =DATA!L255 -> 640 | H33: =SUM(A33*G33) -> 640
A34: =DATA!J256 -> 1 | B34: =DATA!K256 -> copy | D34: =DATA!I256 -> Assessment Learning 1 : A Modular Approach, 2ed, Boholano, 2023, Big Faith Trading | G34: =DATA!L256 -> 880 | H34: =SUM(A34*G34) -> 880
A35: =DATA!J257 -> 1 | B35: =DATA!K257 -> copy | D35: =DATA!I257 -> Assessment Learning 2 : A Modular Approach, Sanchez, 2023, Big Faith Trading | G35: =DATA!L257 -> 825 | H35: =SUM(A35*G35) -> 825
A36: =DATA!J258 -> 1 | B36: =DATA!K258 -> copy | D36: =DATA!I258 -> Assessment of Learning 1 Obe Approach, Manas, 2024, Big Faith Trading | G36: =DATA!L258 -> 440 | H36: =SUM(A36*G36) -> 440
A37: =DATA!J259 -> 1 | B37: =DATA!K259 -> copy | D37: =DATA!I259 -> Building and enhancing New Literacies Across the Curriculum OBE-& PPST-based, De Leon, 2020, Big Faith Trading | G37: =DATA!L259 -> 650 | H37: =SUM(A37*G37) -> 650
A38: =DATA!J260 -> 1 | B38: =DATA!K260 -> copy | D38: =DATA!I260 -> Facilitating Learner-Centered Teaching 5e OBE-&PPST-Based, Lucas & Corpuz, 2020, Big Faith Trading | G38: =DATA!L260 -> 620 | H38: =SUM(A38*G38) -> 620
A39: =DATA!J261 -> 1 | B39: =DATA!K261 -> copy | D39: =DATA!I261 -> Facilitating Student-Centered Teaching & Learning, Larioque, et al., 2024, Big Faith Trading | G39: =DATA!L261 -> 760 | H39: =SUM(A39*G39) -> 760
A40: =DATA!J262 -> 1 | B40: =DATA!K262 -> copy | D40: =DATA!I262 -> Field Study 2, Boholano, et al, 2022, Big Faith Trading | G40: =DATA!L262 -> 825 | H40: =SUM(A40*G40) -> 825
A41: =DATA!J263 -> 1 | B41: =DATA!K263 -> copy | D41: =DATA!I263 -> Field Study 2 Participation and Teaching Assistanship OBE- & PPST, Lucas, et al., 2021, Big Faith Trading | G41: =DATA!L263 -> 670 | H41: =SUM(A41*G41) -> 670
... A67: =DATA!J289 -> 1 | B67: =DATA!K289 -> copy | D67: =DATA!I289 -> Environmental Geology \5ed., Reichard, Jim, 2024, 9781266132261, Forefront Book | G67: =DATA!L289 -> 5393 | H67: =SUM(A67*G67) -> 5393
H68: =SUM(H16:H21) -> 650000
A69: Purpose: | B69: =DATA!P60 -> for program/projects/activities of information Technology Unit charged to cost to operate of admin. Bldg.
F70: Approved By:
A72: Signature:
A73: Printed Name: | B73: =DATA!C60 -> JOHN MICHAEL A. VILLASPIR | F73: DJOVI REGALA DURANTE,DPA
A74: Designation: | B74: =DATA!D60 -> Administrative Officer I | F74: SUC President I
...

Sheet ResoSVP
A5: BAC Resolution Recommending Alternative Mode of Procurement under Small Value Procurement
B7: BAC Resolution No. | D7: =AResoSVP!D6 -> 2505-GAS5-190
A9: WHEREAS, Section 48 Rule XVI of the Revised Implementing Rules and Regulations of RA 9184 allows Alternative Mode of Procurement subject to prior approval of the HOPE thru Annual Procurement Plan (APP) and only to promote economy and efficiency;
A10: WHEREAS, Section 53.9 allows Small Value Procurement provided that the procurement does not fall under shopping in Section 52 of this IRR and the amount involved does not exceed the thresholds prescribed in Annex "H" of this IRR;
A11: WHEREAS, Appendix 18, Section 3.e on the Guidelines for Shopping and Small Value Procurement provides an Abstract of Quotations shall be prepared setting forth the names of those who responded to the RFQ's right after the deadline for submission except for shopping under Section 52.1(b), where at least three (3) price quotations (RFQ) must be obtained;
A12: WHEREAS, Annex "H" of the Consolidated Guidelines for the Alternative Methods of Procurement prescribed under Section V, Paragraph D.8.b.ii that the BAC shall prepare and send the RFQs/RFPs to at least three (3) suppliers, contractors or consultants of known qualifications where receipt of at least one (1) quotations is sufficient to proceed with the evaluation thererof;
A13: WHEREAS, Purchase Request No. | D13: =AResoSVP!D12 -> 2025-190 | E13: involves the procurement of
A14: 4 Layered Steel Filling Cabinet with central lock--to ensure proper organization and secure storage of CBAO documents
A15: with the approved budget of | D15: =AResoSVP!D14 -> 650000
A16: WHEREAS, the default mode of evaluation shall be on a lot basis which means that the determination of the single/lowest calculated and responsive bid (S/LCRB) is the total amount of offered unit price multiply by the required quantity;
A18: NOW THEREFORE, we, the members of the Bids and Awards Committee hereby RESOLVE as it is hereby RESOLVED to recommend to the College President to adopt Alternative Mode of Procurement under Small Value Procurement for the said transaction;
A20: RESOLVED FINALLY, at the Batanes State College, this
A21: Recommending Approval:
A24: RHOUPHELINE AYA A.. CADIZ | C24: FORTUNATO PHILIP A. CABUGAO | E24: EMILYN D. ALUETA
A25: BAC Member | C25: BAC Member | E25: BAC Member
A28: =PR!B73 -> JOHN MICHAEL A. VILLASPIR | C28: PHILIP ULYSSES T. CASTILLO | E28: DOREEN C. CASTILLO
A29: End-User/Provisional Member | C29: BAC Vice Chairperson | E29: BAC Chairperson

Sheet AResoSVP
A4: Approval of BAC Resolution Recommending Alternative Mode of Procurement under Small Value Procurement
B6: BAC Resolution No. | D6: =PR!B12 -> 2505-GAS5-190
A8: WHEREAS, Section 48 Rule XVI of the Revised Implementing Rules and Regulations of RA 9184 allows Alternative Mode of Procurement subject to prior approval of the HOPE thru Annual Procurement Plan (APP) and only to promote economy and efficiency;
A9: WHEREAS, Section 53.9 allows Small Value Procurement provided that the procurement does not fall under shopping in Section 52 of this IRR and the amount involved does not exceed the thresholds prescribed in Annex "H" of this IRR;
A10: WHEREAS, Appendix 18, Section 3.e on the Guidelines for Shopping and Small Value Procurement provides an Abstract of Quotations shall be prepared setting forth the names of those who responded to the RFQ's right after the deadline for submission except for shopping under Section 52.1(b), where at least three (3) price quotations (RFQ) must be obtained;
A11: WHEREAS, Annex "H" of the Consolidated Guidelines for the Alternative Methods of Procurement prescribed under Section V, Paragraph D.8.b.ii that the BAC shall prepare and send the RFQs/RFPs to at least three (3) suppliers, contractors or consultants of known qualifications where receipt of at least one (1) quotations is sufficient to proceed with the evaluation thererof;
A12: WHEREAS, Purchase Request No. | D12: =PR!E9 -> 2025-190 | E12: involves the procurement of
A13: 4 Layered Steel Filling Cabinet with central lock--to ensure proper organization and secure storage of CBAO documents | H13: Items:
A14: with the approved budget of | D14: =PR!H68 -> 650000
A15: WHEREAS, the default mode of evaluation shall be on a lot basis which means that the determination of the single/lowest calculated and responsive bid (S/LCRB) is the total amount of offered unit price multiply by the required quantity;
A16: NOW THEREFORE, I,DR.DJOVI R. DURANTE, Head of the Procuring Entity (HOPE) by virtue of the authority vested in me by the Board of Trustees of this Institution and after taking into consideration the merits and legal bases of the recommendation of the members of the Bids and Awards Committee (BAC) do hereby APPROVE the foregoing recommendation and adoption of Alternative Mode of Procurement under Small Value Procurement;
A18: APPROVED FINALLY, at the Batanes State College, this | F18: ___________________
A22: DJOVI REGALA DURANTE,DPA
A23: SUC President I
A30: BRYAN H. CIELO
A85: EMILYN D. ALUETA
A86: EMILYN D. ALUETA

Sheet RFQ_
E1: Date: | F1: =NOW() -> 46148.737
A2: REQUEST FOR PRICE QUOTATION
A3: FVA Trading
A4: Please give us your best and final price offer for the item/s listed below, have this signed and submit this by you or by your duly authorized representative WITHIN SEVEN (7) CALENDAR DAYS upon receipt to Procurement Section, Batanes State College.
A6: NOTE: | B6: 1. THE DEFAULT MODE OF PRICE EVALUATION SHALL BE ON A LOT BASIS, OTHERWISE PER ITEMS EVALUATION SHALL BE USED IF THERE WILL BE LACKING ITEMS IN ALL RFQ's AND SUBJECT TO END-USER APPROVAL., (Clause 15.2, Section I, Instruction to Bidders of the Philippine Bidding Documents for goods and infrastructure projects)
B7: 2. DELIVERY PERIOD: Thirty (30) calendar days
B8: 3. Submission of price quotation shall be in sealed envelope.
B9: 4. THE APPROVED BUDGET FOR THIS PROCUREMENT IS
B10: =PR!H68 -> 650000 | D10: (GPPB Resolution No. 09-2009)
B11: 5. PURSUANT TO ANNEX "H", APPENDIX A, SECTION II, SUBMISSION OF APPLICABLE DOCUMENTS (e.g.MAYORS/BUSINESS PERMIT, PROFESSIONAL LICENSE/CURRICULUM VITAE (CONSULTING SEERVICES),PHILGEPS CERT. NO., PCAB LICENSE (INFRA), INCOME/BUSINESS TAX RETURN,OMNIBUS SWORN STATEMENT SHALL BE REQUIRED BEFORE THE ISSUANCE OF NOA OR PRIOR TO PAYMENT.
B12: 6. In case the item is not availble, please write "None".
A13: Item # | B13: Qty. | C13: Unit | D13: PARTICULAR | E13: Unit Price | F13: Total
A14: 001 | B14: =PR!A16 -> 1 | C14: =PR!B16 -> set | D14: =PR!D16 -> Single Face P4 HD Outdoor LED Screen (rear maintenance), Full Set Up including controller (Novastar) & receiving card (Novastar) warranty, after sales support & training controller (novastar) & receiving card (novastar)warranty , after sales support & training size: 2.88M x 2.88M (9 panels) screen resolution; 720 pixels (W) x 720 pixels (H) Type; movable frame Accessories: replacement module , replacemenr power supply,replacement receiving card,power cable,signal cable FREE: LED control software Training and Support
A15: 002 | B15: =PR!A17 -> 0 | C15: =PR!B17 -> 0 | D15: =PR!D17 -> 0
A16: 003 | B16: =PR!A18 -> 0 | C16: =PR!B18 -> 0 | D16: =PR!D18 -> 0
A17: 004 | B17: =PR!A19 -> 0 | C17: =PR!B19 -> 0 | D17: =PR!D19 -> 0
A18: 005 | B18: =PR!A20 -> 0 | C18: =PR!B20 -> 0 | D18: =PR!D20 -> 0
A19: 006 | B19: =PR!A21 -> 0 | C19: =PR!B21 -> 0 | D19: =PR!D21 -> 0
A20: 007 | B20: =PR!A22 -> 0 | C20: =PR!B22 -> 0 | D20: =PR!D22 -> 0
A21: 008 | B21: =PR!A23 -> 0 | C21: =PR!B23 -> 0 | D21: =PR!D23 -> 0
A22: 009 | B22: =PR!A24 -> 0 | C22: =PR!B24 -> 0 | D22: =PR!D24 -> 0
A23: 010 | B23: =PR!A25 -> 0 | C23: =PR!B25 -> 0 | D23: =PR!D25 -> 0
A24: 011 | B24: =PR!A26 -> 0 | C24: =PR!B26 -> 0 | D24: =PR!D26 -> 0
A25: 012 | B25: =PR!A27 -> 0 | C25: =PR!B27 -> 0 | D25: =PR!D27 -> 0
... A28: 015 | B28: =PR!A30 -> 1 | C28: =PR!B30 -> copy | D28: =PR!D30 -> Design and Implement the Curriculum to Foster Children's Learning and Development, 3G E-Leraning, 2022, Wiseman's Book Trading, Inc.
A29: 016 | B29: =PR!A52 -> 1 | C29: =PR!B52 -> copy | D29: =PR!D52 -> The Teacher and the School Curriculum Obe Approach, Otinero-Gallardo, 2024, Big Faith Trading
A30: 017 | B30: =PR!A53 -> 1 | C30: =PR!B53 -> copy | D30: =PR!D53 -> The Teaching Profession, Fernando, et al., 2024, Big Faith Trading
A31: 018 | B31: =PR!A54 -> 1 | C31: =PR!B54 -> copy | D31: =PR!D54 -> English/Purposive Communication (A Modular Approach), Gutierrez-Ang, 2023, Big Faith Trading
A32: 019 | B32: =PR!A55 -> 1 | C32: =PR!B55 -> copy | D32: =PR!D55 -> Artificial Intelligence and Quantum Computing, Schweinfurth, 2025, 9789362241931, Wiseman's Book Trading, Inc.
A33: 020 | B33: =PR!A56 -> 1 | C33: =PR!B56 -> copy | D33: =PR!D56 -> Basic Computer Coding: Java Script 3rd/ed, Gbadegesin, 2024, 9781984689337, Wiseman's Book Trading, Inc.
A34: 021 | B34: =PR!A57 -> 1 | C34: =PR!B57 -> copy | D34: =PR!D57 -> Electronics All-in-One For Dummies, 3rd edition, Lowe, 2022, 978-1119822110, https://www.amazon.com
A35: 022 | B35: =PR!A58 -> 1 | C35: =PR!B58 -> copy | D35: =PR!D58 -> Practical Electronics for Inventors, 4th Edition, Scherz & Monk, 2016, 9.78126E+12, https://www.amazon.com
A36: 023 | B36: =PR!A59 -> 1 | C36: =PR!B59 -> copy | D36: =PR!D59 -> Make: Electronics: Learning by Discovery: A hands-on primer for the new electronics enthusiast 3rd Edition, Platt, 2021, 978-1680456875, https://www.amazon.com
A37: 024 | B37: =PR!A60 -> 1 | C37: =PR!B60 -> copy | D37: =PR!D60 -> Electronic Devices and Curcuits Theory, Boylestad & Nashelsky, latest ed., https://www.amazon.com
A38: 046 | B38: =PR!A61 -> 1 | C38: =PR!B61 -> copy | D38: =PR!D61 -> Digital Fundamentals, Floyd, latest ed., https://www.amazon.com/Digital-Fundamentals-11th-Thomas-Floyd/dp/0132737965
A39: 047 | B39: =PR!A62 -> 1 | C39: =PR!B62 -> copy | D39: =PR!D62 -> Microelectronics circuits, Sedra & Smith, latest ed., https://www.amazon.com/Microelectronic-Circuits-Electrical-Computer-Engineering/dp/0195323033
A40: 048 | B40: =PR!A63 -> 1 | C40: =PR!B63 -> copy | D40: =PR!D63 -> The art of electronics, Horowitz & Hill, latest ed., https://www.amazon.com/Art-Electronics-Paul-Horowitz/dp/0521809266
... A44: 052 | B44: =PR!A67 -> 1 | C44: =PR!B67 -> copy | D44: =PR!D67 -> Environmental Geology \5ed., Reichard, Jim, 2024, 9781266132261, Forefront Book
A45: 053 | B45: =PR!#REF! -> #REF! | C45: =PR!#REF! -> #REF! | D45: =PR!#REF! -> #REF!
A46: 054 | B46: =PR!#REF! -> #REF! | C46: =PR!#REF! -> #REF! | D46: =PR!#REF! -> #REF!
...

Sheet RFQ_ (2)
A1: Republic of the Philippines
A2: BATANES STATE COLLEGE
A3: Basco, Batanes
E4: Date:
A5: REQUEST FOR PRICE QUOTATION
B6: MOJR Construction Trading & General Services, Ltd, Co. | C6: MOJR Construction Trading & General Services, Ltd, Co. | D6: MOJR Construction Trading & General Services, Ltd, Co.
A7: Please give us your best and final price offer for the item/s listed below, have this signed and submit this by you or by your duly authorized representative WITHIN SEVEN (7) CALENDAR DAYS upon receipt to Procurement Section, Batanes State College.
A9: NOTE: | B9: 1. THE DEFAULT MODE OF PRICE EVALUATION SHALL BE ON A LOT BASIS, OTHERWISE PER ITEMS EVALUATION SHALL BE USED IF THERE WILL BE LACKING ITEMS IN ALL RFQ's AND SUBJECT TO END-USER APPROVAL., (Clause 15.2, Section I, Instruction to Bidders of the Philippine Bidding Documents for goods and infrastructure projects)
B10: 2. DELIVERY PERIOD: Thirty (30) calendar days.
B11: 3. Submission of price quotation shall be in sealed envelope.
B12: 4. THE APPROVED BUDGET FOR THIS PROCUREMENT IS
B13: =PR!H68 -> 650000 | D13: (GPPB Resolution No. 09-2009)
B14: 5. PURSUANT TO ANNEX "H", APPENDIX A, SECTION II, SUBMISSION OF APPLICABLE DOCUMENTS (e.g.MAYORS/BUSINESS PERMIT, PROFESSIONAL LICENSE/CURRICULUM VITAE (CONSULTING SEERVICES),PHILGEPS CERT. NO., PCAB LICENSE (INFRA), INCOME/BUSINESS TAX RETURN,OMNIBUS SWORN STATEMENT SHALL BE REQUIRED BEFORE THE ISSUANCE OF NOA OR PRIOR TO PAYMENT.
B15: 6. In case the item is not availble, please write "None".
A16: Item # | B16: Qty. | C16: Unit | D16: PARTICULAR | E16: Unit Price | F16: Total
A17: 001
A18: 002
A19: 003
A20: 004
A21: 005
A22: 006
A23: 007
A24: 008
A25: 009
A26: 010
A27: 011
A28: 012
... A33: 017
A34: 018 | B34: =PR!A33 -> 1 | C34: =PR!B33 -> copy | D34: graphite pencil 12b | J34: graphite pencil 12b
A35: 019 | B35: =PR!A34 -> 1 | C35: =PR!B34 -> copy | D35: graphite pencil 8b | J35: graphite pencil 8b
A36: 020 | B36: =PR!A41 -> 1 | C36: =PR!B41 -> copy | D36: graphite pencil 6b | J36: graphite pencil 6b
A37: 021 | B37: =PR!A42 -> 1 | C37: =PR!B42 -> copy | D37: graphite pencil 4b | J37: graphite pencil 4b
A38: 022 | B38: =PR!A43 -> 1 | C38: =PR!B43 -> copy | D38: graphite pencil 2b | J38: graphite pencil 2b
A39: 023 | B39: =PR!A44 -> 1 | C39: =PR!B44 -> copy | D39: graphite pencil HB | J39: graphite pencil HB
A40: 024 | B40: =PR!A45 -> 1 | C40: =PR!B45 -> copy | D40: =PR!D45 -> Physical Activity Towards Health and Fitness PATHFIT( Dance, Fitness, Tradition), Aquino, 2024, Big Faith Trading
A41: 025 | B41: =PR!A46 -> 1 | C41: =PR!B46 -> copy | D41: =PR!D46 -> Physical Activity Towards Health and Fitness PATHFIT(Arnis), Dela Cruz, 2024, Big Faith Trading
A42: 026 | B42: =PR!A47 -> 1 | C42: =PR!B47 -> copy | D42: =PR!D47 -> Qualitative Research, Macapagal/Sombilo, 2024, Big Faith Trading
A43: 027 | B43: =PR!A48 -> 1 | C43: =PR!B48 -> copy | D43: =PR!D48 -> Teaching Science in the Elementary Grades Vol. 2: Physics, Earth and Space OBE- & PPST based, Bilbao, 2024, Big Faith Trading
A44: 028 | B44: =PR!A49 -> 1 | C44: =PR!B49 -> copy | D44: =PR!D49 -> The Teacher and the Community, School Culture and Organizational Leadership, Serrano, 2020, Big Faith Trading
A45: 029 | B45: =PR!A50 -> 1 | C45: =PR!B50 -> copy | D45: illustration board 20”x30” | J45: illustration board 20”x30”
...

Sheet AckReceipt (2)
A1: Acknowledgement for Request for Quotation
A2: RIS# | B2: =PR!B12 -> 2505-GAS5-190
A3: No. | B3: Supplier | F3: Received by: | G3: Date & Time:
B4: JPM Gen. Mdse. & Hardware
B5: Thine-line Trading
B6: J-Tech Trading & Services
B7: MDAC Trading & Compuserve
B8: FVA Gen Mdse & Construction Supply
B10: GDP Trading
B11: EA Amboy Gen Mdse
B12: L & R's Hontomin Gen Mdse
B13: Davocol's Gen. Mdse.
B14: RCJ Hardware & Gen Mdse
B15: Fitero's Gen Mdse & Electronic Supply
B16: Lar & San's Store
... B18: Wilmerson Gen Mdse
B19: FMG Trading & Construction Supply | C19: q
B20: MG Hubalde Gen Mdse
B21: Basco Cable TV Services, Inc.
B22: Berlen's Store
B23: Melad's Gen. Mdse
B24: R. A. Electronics
B25: RJ General Merchandise
B26: Batanes Multi-Purpose Cooperative, Inc.
B27: Romy & Ava's Store
B28: J-nell's Gen Mdse
B29: Impression Digital Printing Solutions
B30: Golden Press
B31: Tawsen's Agri-Venture & Souvenirs
... B60: Sophia Marie Store
A61: 1 | B61: GDP Trading
A62: 2 | B62: JPM Gen. Mdse. & Hardware
A63: 3 | B63: FVA Trading
A64: 4
A65: 5 | J65: zz
A66: 6
A67: 7
A68: NOTE: | B68: 1. MODE OF PRICE EVALUATION SHALL BE ON A LOT BASIS, OTHERWISE PER ITEMS EVALUATION SHALL BE USED IF THERE WILL BE LACKING ITEMS IN ALL RFQ'S AND THE END-USER AGREED, . (Clause 15.2, Section II, Instructions to Bidders of the Philippine Bidding Documents for goods and infrastructure projects)
B69: 2. DELIVERY PERIOD: Thirty (30) calendar days.
B70: 3. WARRANTY SHALL BE FOR A PERIOD OF SIX (6) MONTHS FOR SUPPLIES AND MATERIALS, ONE (1) YEAR FOR EQUIPMENT, FROM THE DATE OF ACCEPTANCE BY THE PROCURING ENTITY.
...

Sheet Abstract 
B3: ABSTRACT OF QUOTATIONS
I4: 6750
B5: (x) Furnishing/delivery of supplies, and materials or equipment | H5: Bids opened at Basco, Batanes
B6: ( x ) Furnishing Labor, services, etc. | I6: =NOW() -> 46148.737
B7: ( ) Rental or use of transportation facilities equipment, quarters, rooms, lot or space, etc.
B9: To be furnished at the | D9: BATANES STATE COLLEGE
D10: (State place or site of Office or project where articles or services be furnished or returned)
A12: NAME OF ARTICLES OR SERVICES TO BE FURNISHED, RENDERED OR FACILITIES TO BE RENTED
F15: JPM Gen. Mdse. & Hardware
F16: Thine-line Trading
F17: J-Tech Trading & Services
F18: Mulong Ydel
F19: MDAC Trading & Compuserve
F20: FVA Gen Mdse & Construction Supply
F21: MKM Hardware
F22: GDP Trading
F23: EA Amboy Gen Mdse
F24: L & R's Hontomin Gen Mdse
F25: Davocol's Gen. Mdse.
F26: RCJ Hardware & Gen Mdse
... F87: Valiente Food Producer
F88: =DATA!V298 -> Apostol General Merchandise | G88: M.G. Hubalde's General Merchandise | H88: JPM General Merchandise & Hardware | I88: E.A. General Merchandise
A90: =PR!D16 -> Single Face P4 HD Outdoor LED Screen (rear maintenance), Full Set Up including controller (Novastar) & receiving card (Novastar) warranty, after sales support & training controller (novastar) & receiving card (novastar)warranty , after sales support & training size: 2.88M x 2.88M (9 panels) screen resolution; 720 pixels (W) x 720 pixels (H) Type; movable frame Accessories: replacement module , replacemenr power supply,replacement receiving card,power cable,signal cable FREE: LED control software Training and Support | F90: =DATA!O298 -> 12000 | G90: 14800 | H90: 22000 | I90: none
M92: =DATA!W479 -> 0
M93: =DATA!W480 -> 0
M94: =DATA!W481 -> 0
A99: =PR!D25 -> 0 | F99: =DATA!O157 -> 770
A100: =PR!D26 -> 0 | F100: =DATA!O158 -> 880
A101: =DATA!I483 -> 0 | B101: Bond paper, A4 size | C101: Bond paper, A4 size | D101: Bond paper, A4 size | E101: Bond paper, A4 size | F101: =DATA!O159 -> 1325
A102: =DATA!I484 -> 0 | B102: Bond paper, A4 size | C102: Bond paper, A4 size | D102: Bond paper, A4 size | E102: Bond paper, A4 size | F102: =DATA!O160 -> 0
A103: =DATA!I485 -> 0 | B103: Bond paper, A4 size | C103: Bond paper, A4 size | D103: Bond paper, A4 size | E103: Bond paper, A4 size | F103: =DATA!O161 -> 0
A104: =DATA!I486 -> 0 | B104: Bond paper, A4 size | C104: Bond paper, A4 size | D104: Bond paper, A4 size | E104: Bond paper, A4 size | F104: =DATA!O162 -> 0
A105: =DATA!I487 -> 0 | B105: Bond paper, A4 size | C105: Bond paper, A4 size | D105: Bond paper, A4 size | E105: Bond paper, A4 size | F105: =DATA!O163 -> 0
A106: =DATA!I488 -> 0 | B106: Bond paper, A4 size | C106: Bond paper, A4 size | D106: Bond paper, A4 size | E106: Bond paper, A4 size | F106: =DATA!O164 -> 0
A107: =DATA!I489 -> 0 | B107: Bond paper, A4 size | C107: Bond paper, A4 size | D107: Bond paper, A4 size | E107: Bond paper, A4 size | F107: =DATA!O165 -> 0
A108: =DATA!I490 -> 0 | B108: Bond paper, A4 size | C108: Bond paper, A4 size | D108: Bond paper, A4 size | E108: Bond paper, A4 size | F108: =DATA!O166 -> 0
A109: =DATA!I491 -> 0 | B109: Bond paper, A4 size | C109: Bond paper, A4 size | D109: Bond paper, A4 size | E109: Bond paper, A4 size | F109: =DATA!O167 -> 0
A110: =DATA!I492 -> 0 | B110: Bond paper, A4 size | C110: Bond paper, A4 size | D110: Bond paper, A4 size | E110: Bond paper, A4 size | F110: =DATA!O168 -> 0
A111: =DATA!I493 -> 0 | B111: Bond paper, A4 size | C111: Bond paper, A4 size | D111: Bond paper, A4 size | E111: Bond paper, A4 size | F111: =DATA!O169 -> 0
A112: =DATA!I494 -> 0 | B112: Bond paper, A4 size | C112: Bond paper, A4 size | D112: Bond paper, A4 size | E112: Bond paper, A4 size | F112: =DATA!O170 -> 0
...

Sheet  LON-
A6: BIDS AND AWARDS COMMITTEE
A8: LETTER OF NOTICE
A11: LEO A. APOSTOL
A12: Owner
A13: Apostol General Merchandise
A14: Brgy. Kayhuvokan,Batanes
A17: Madam/Sir:
A18: We are happy to notify you that your quotation dated June 4 2025 for the 4 Layered Steel Filling Cabinet with central lock with PR # 2505-1006-211 with contract price equivalent to TWELVE THOUSAND PESOS ONLY (Php 12,000.00) is hereby accepted.
A19: You are hereby required to provide within Ten (10) days a certified photocopy of the following requirements:
A20: .
B21: 1. Updated Mayor's Permit/Business Permit
B22: 2. PhilGEPS Registration no.
B23: 3. Latest Income/Business Tax Return
B24: 4. Duly Notarized Omnibus Sworn Statement
B25: 5. BIR 2302 Certificate of Registration
B26: 6. Updated DTI Registration
B27: 7. Landbank Account details of the business (for payment purposes)
A30: However, If you already have a maintaining and updated file of the above-mentioned requirements in the BAC Office you may no longer require its re-submission (Annex "H", Appendix "A" Section III)
A32: *For individuals engaged under Sec. 53.6, 53.7, and 53.9 of the IRR of RA 9184, only the BIR Certificate of Registration shall be submitted in lieu of DTI Registration and Mayor’s Permit.
A33: Thank you
A35: Very truly yours,
A38: DOREEN C. CASTILLO
A39: BAC Chairperson
A41: Received by:
A44: (Signature over printed name)
A45: Date: ___________________
A46: Ref. No.: | B46: =PR!B12 -> 2505-GAS5-190

Sheet BAC RESO 2022
E3: OFFICE OF THE BIDS AND AWARDS COMMITTEE | N3: OFFICE OF THE BIDS AND AWARDS COMMITTEE
E4: bac resolution No: | M4: =E4 -> bac resolution No:
D5: =PR!B12 -> 2505-GAS5-190 | M5: =D5 -> 2505-GAS5-190
E7: BAC RESOLUTION RECOMMENDING FOR AWARD | N7: APPROVAL OF THE BAC RECOMMENDATION FOR AWARD
A9: WHEREAS, the BATANES STATE COLLEGE advertised the Request for Price Quotation (RFQ) for the 4 Layered Steel Filling Cabinet with central lock with PR # 2505-1006-211 dated June 4, 2025. | J9: WHEREAS, the BATANES STATE COLLEGE advertised the Request for Price Quotation (RFQ) for the BT5000-yellow,cyan,magenta with PR # 2505-GAS1-209 dated May 30, 2025.
A11: WHEREAS, from the period the Request for Price Quotation (RFQ) has started up to the time of bid submission and opening, Four(4) prospective bidder were able to submit the RFQ; | J11: WHEREAS, from the period the Request for Price Quotation (RFQ) has started up to the time of bid submission and opening, Five (5) prospective bidder were able to submit the RFQ;
A13: WHEREAS, the Price Quotation based on the Lowest Calculated & Responsive Bid (LCRB) format of the bidders were opened and its bid price was read as follows: | J13: WHEREAS, the Price Quotation based on the Lowest Calculated & Responsive Bid (LCRB) format of the bidders were opened and its bid price was read as follows:
A16: ITEM NO. | B16: BIDDER WITH CALCULATED BID | G16: ABC | I16: BID AMOUNT | J16: ITEM NO. | K16: BIDDER WITH CALCULATED BID | P16: ABC | R16: BID AMOUNT
A17: 1 | B17: =DATA!V298 -> Apostol General Merchandise | G17: =PR!H68 -> 650000 | I17: 12000 | J17: 1 | K17: =B17 -> Apostol General Merchandise | P17: =G17 -> 650000 | R17: =I17 -> 12000
A18: 2 | B18: M.G. Hubalde's General Merchandise | G18: 20000 | I18: 14800 | J18: 2 | K18: =B18 -> M.G. Hubalde's General Merchandise | P18: =G18 -> 20000 | R18: =I18 -> 14800
A19: 3 | B19: JPM General Mdse. & Hardware | G19: 20000 | I19: 22000 | J19: 3 | K19: =B19 -> JPM General Mdse. & Hardware | P19: =G19 -> 20000 | R19: =I19 -> 22000
A20: 4 | B20: E.A.Amboy General Merchandise | G20: 20000 | I20: none | J20: 4 | K20: =B20 -> E.A.Amboy General Merchandise | P20: =G20 -> 20000 | R20: =I20 -> none
A21: 5 | J21: 5 | K21: =B21 -> 0 | P21: =G21 -> 0 | R21: =I21 -> 0
A22: 6 | G22: 13000 | I22: none | J22: 6 | K22: =B22 -> 0 | P22: =G22 -> 13000 | R22: =I22 -> none
A23: 7 | G23: 13000 | I23: none | J23: 7 | K23: =B23 -> 0 | P23: =G23 -> 13000 | R23: =I23 -> none
A24: 8 | J24: 8 | K24: =B24 -> 0 | P24: =G24 -> 0 | R24: =I24 -> 0
