Workbook

Sheet PMR-Data
A2: MONTH | B2: (Multiple Items)
A3: YEAR | B3: (Multiple Items)
A5: PR# | B5: Purpose | C5: End-User | D5: Modality | E5: Delivery Date | F5: IAR Date | G5: Fund Code | H5: Class | I5: Status | J5: Sum of Estimated Total | K5: Sum of Total
A6: 202-013A | B6: supplies for the repair & maintenance of the building | C6: JERSHON RALPH F. CASTANO | D6: SVP | E6: August 23, 2021 | F6: August 23, 2021 | G6: 101 | H6: MOOE | I6: complete | J6: 85520 | K6: 65665
A7: 2021-001A | B7: snacks for the "Internal Quality Audit" on January 19-21, 2021 | J7: 17850 | K7: 17850
A8: 2021-002 | B8: Supply and installation of CCTV for Academic Building, Dormitory and Agriculture Building | C8: ALETH A. MEORA | D8: SVP | E8: April 27, 2021 | F8: May 26, 2021` | G8: 101 | H8: CO | I8: complete | J8: 435000 | K8: 397860
A9: 2021-002A | B9: to be used in the different activities and internet communication needs of BSC | C9: RANDALL G. CASTILLO | D9: SVP | E9: 5/19 & 7/19/2021 | F9: 5/26 & 7/21/2021 | G9: 101 | H9: (blank) | I9: complete | J9: 25500 | K9: 25480
A10: 2021-003 | B10: Purchase of Academic Equipment | C10: ALETH A. MEORA | D10: SVP | E10: 5/19 & 7/19/2021 | F10: 5/19 & 7/21/2021 | G10: 101 | H10: CO | I10: complete | J10: 947218.62 | K10: 928620
A11: 2021-003A | B11: for PBB compliance specifically transparency seal and BSC publication | C11: RANDALL G. CASTILLO | D11: SVP | E11: February 16, 2021 | F11: March 2, 2021 | G11: 165 | H11: MOOE | I11: complete | J11: 49000 | K11: 45560
A12: 2021-004 | B12: for the purchase of Academic Equipments | C12: ALETH A. MEORA | D12: SVP | E12: January 12, 2021 | F12: April 27, 2021 | G12: 101 | H12: CO | I12: complete | J12: 972105.5 | K12: 791000
A13: 2021-004A | B13: for the purchase of enrollment forms | C13: RHEA ANGELLICA B. ADDATU | D13: SVP | E13: August 23, 2021 | F13: August 23, 2021 | G13: 101 | H13: (blank) | I13: (blank) | J13: 22500 | K13: 22500
A14: 2021-005 | B14: Purchase of Academic Equipment | C14: ALETH A. MEORA | D14: SVP | E14: 44396 | F14: 44403 | G14: 101 | H14: CO | I14: reimbursement | J14: 378961.7 | K14: 359780
A15: 2021-005A | B15: to be used in the different activities and internet communication needs of BSC | C15: RANDALL G. CASTILLO | D15: SVP | E15: May 19, 2021 | F15: May 26, 2021 | G15: 101 | H15: MOOE | I15: complete | J15: 30250 | K15: 29960
A16: 2021-006 | B16: Supply and Delivery of Academic Equipment | C16: ALETH A. MEORA | D16: SVP | E16: January 12, 2021 | F16: January 25, 2021 | G16: 101 | H16: CO | I16: complete | J16: 315813.75 | K16: 195700
E17: January 25, 2021 | F17: January 25, 2021 | G17: 101 | H17: CO | I17: complete | J17: 45000 | K17: 42000
A18: 2021-006A | B18: for the ISO Activity Management Review on Feb. 3, 2021 | C18: ROMINA KATRINA C. BAYARAS | D18: SVP | E18: 44230 | F18: February 16, 2021 | G18: 164 | H18: MOOE | I18: complete | J18: 14000 | K18: 11800
A19: 2021-007A | B19: Internet data/Regular load Allocation of Administrative & Finance staff of the college to support online submission of reports & other related activities for the Fiscal Year 2021 | C19: DJOVI R. DURANTE | D19: SVP | E19: March 29, 2021 | F19: March 31, 2021 | G19: 101 | H19: MOOE | I19: complete | J19: 107880 | K19: 107880
A20: 2021-008A | B20: for the "ISO Documentation" | C20: ROMINA KATRINA C. BAYARAS | D20: SVP | E20: March 15, 2021 | F20: March 15, 2021 | G20: 164 | H20: MOOE | I20: complete | J20: 3960 | K20: 3885
A21: 2021-009 | B21: Purchase of Academic Furniture Fixtures | C21: ALETH A. MEORA | D21: SVP | E21: August 23, 2021 | F21: August 23, 2021 | G21: 101 | H21: MOOE | I21: complete | J21: 200000 | K21: 199680
A22: 2021-009A | B22: stamp use for the filing of ISO documents | C22: ROMINA KATRINA C. BAYARAS | D22: SVP | E22: - | F22: - | G22: 165 | H22: (blank) | I22: FAILED | J22: 28000 | K22: 0
A23: 2021-0100 | B23: for the Implementation of "ADOPT through Varied R & D of Ivatan Endemic Resources" research project | C23: JANE S. CASTILLO | D23: SVP | E23: August 23, 2021 | F23: August 23, 2021 | G23: 165 | H23: MOOE | I23: for delivery | J23: 30950 | K23: 29315
A24: 2021-0101 | B24: office supplies for the Administrative & Finance Services Units | C24: DJOVI R. DURANTE | D24: SVP | E24: August 23, 2021 | F24: August 23, 2021 | G24: 165 | H24: MOOE | I24: for delivery | J24: 30840 | K24: 28941.9
A25: 2021-0102 | B25: supplies for Budget office | C25: BRYAN DAVE P. REVILLA | D25: SVP | E25: August 23, 2021 | F25: August 23, 2021 | G25: 101 | H25: MOOE | I25: for delivery | J25: 3500 | K25: 2990
A26: 2021-0103 | B26: supplies for Budget office | C26: BRYAN DAVE P. REVILLA | D26: SVP | E26: July 1, 2021 | F26: July 1, 2021 | G26: 101 | H26: MOOE | I26: complete | J26: 790 | K26: 600
A27: 2021-0104 | B27: supplies for the Budget office | C27: BRYAN DAVE P. REVILLA | D27: SVP | E27: August 23, 2021 | F27: August 23, 2021 | G27: 101 | H27: MOOE | I27: for delivery | J27: 1000 | K27: 800
A28: 2021-0105 | B28: repair of 2 units floor type airconditioner at Faculty Room | C28: JERSHON RALPH F. CASTANO | D28: SVP | E28: August 23, 2021 | F28: August 23, 2021 | G28: (blank) | H28: (blank) | I28: FAILED | J28: 13000
A29: 2021-0106 | B29: GSO Supplies | C29: JERSHON RALPH F. CASTANO | D29: SVP | E29: July 19 & 26, 2021 | F29: July 21 & 26, 2021 | G29: 101 | H29: MOOE | I29: complete | J29: 10950 | K29: 8314
A30: 2021-0107 | B30: GSO Supplies | C30: JERSHON RALPH F. CASTANO | D30: SVP | E30: 44399 | F30: 44411 | G30: 101 | H30: MOOE | I30: reimbursement | J30: 18500 | K30: 15780
A31: 2021-0108 | B31: Snack for the Preparatory Board Meeting on June 25, 2021 at 10:00 a.m | C31: GERZON R. ABAD | D31: SVP | E31: August 23, 2021 | F31: August 23, 2021 | G31: (blank) | H31: (blank) | I31: FAILED | J31: 3000 | K31: 0
A32: 2021-0109 | B32: PM snack and dinner for the 52nd Board of Trustees Meeting on June 25, 2021 | C32: GERZON R. ABAD | D32: SVP | E32: June 25, 2021 | F32: 44377 | G32: 101 | H32: MOOE | I32: reimbursement | J32: 13000 | K32: 9000
A33: 2021-010A | B33: ink use for enrollment | C33: RHEA ANGELLICA B. ADDATU | D33: SVP | E33: August 23, 2021 | F33: August 23, 2021 | G33: 101 | H33: (blank) | I33: FAILED | J33: 1500
A34: 2021-0110 | B34: Lunch, PM Snack and Dinner of Commissioner Lilian A. De Las Llagas and Staff for the 52nd BOT Meeting on 25 June 2021 | C34: GERZON R. ABAD | D34: SVP | E34: August 23, 2021 | F34: August 23, 2021 | G34: (blank) | H34: (blank) | I34: reimbursement | J34: 12597.5 | K34: 12597.5
A35: 2021-0111 | B35: repair & maintenance of A/C units of Registrar's, Cashier's, Accountant's & President's office | C35: JERSHON RALPH F. CASATANO | D35: SVP | E35: August 23, 2021 | F35: August 23, 2021 | G35: 101 | H35: MOOE | I35: on-going | J35: 8000 | K35: 8000
A36: 2021-0112 | B36: supplies for the rewiring of faculty room electrical system | C36: JERSHON RALPH F. CASATANO | D36: SVP | E36: July 21, 2021 | F36: July 26, 2021 | G36: 101 | H36: MOOE | I36: complete | J36: 23700 | K36: 21624
A37: 2021-0113 | B37: for the purchase of Semi-expendable equipments purposes | C37: JERSHON RALPH F. CASATANO | D37: SVP | E37: August 23, 2021 | F37: August 23, 2021 | G37: 101 | H37: MOOE | I37: on-going | J37: 10000 | K37: 10000
A38: 2021-011A | B38: for the Pre Assessment Audit Plan on Feb. 10-11, 2021 | C38: ROMINA KATRINA C. BAYARAS | D38: SVP | E38: February 10-11, 2021 | F38: March 2, 2021 | G38: 164 | H38: MOOE | I38: complete | J38: 7500 | K38: 7125
A39: 2021-012A | B39: supplies for the repair & maintenance of transportation vehicle | C39: JERSHON RALPH F. CASTANO | D39: SVP | E39: March 31, 2021 | F39: April 5, 2021 | G39: 101 | H39: MOOE | I39: on-going | J39: 49399.99 | K39: 42550
A40: 2021-013 | B40: Puchase of drafting tables and chairs for the Academiic Furnitures and Fixtures | C40: ALETH A. MEORA | D40: SVP | E40: January 26, 2021 | F40: January 26, 2021 | G40: 101 | H40: CO | I40: complete | J40: 277500 | K40: 195000
A41: 2021-014A | B41: office machinery & equipment | C41: JERSHON RALPH F. CASTANO | D41: SVP | E41: March 29, 2021 | F41: March 30, 2021 | G41: 101 | H41: MOOE | I41: complete | J41: 47002 | K41: 42500
A42: 2021-015A | B42: supplies for janitorial services | C42: JERSHON RALPH F. CASTANO | D42: SVP | E42: April 15, 2021 | F42: April 15, 2021 | G42: 101 | H42: MOOE | I42: complete | J42: 5000 | K42: 3000
...

Sheet Suppliers TIN
B1: Business Name | C1: Name/Owner | D1: TIN # | E1: Scope of Business
A2: 1 | B2: Apostol General Merchandise | C2: Leo A. Apostol | D2: 183-008-448 | E2: Food,beverages,computers,gas fuel products,agri.farm
A3: 2 | B3: Bartilad's Feeds Trading | C3: Roldan Q. Bartilad | D3: 771-272-422 | E3: agricultural farm supplies, & equipment
A4: 3 | B4: Bitstop Network Services Inc. | C4: JC James P. Jihay | D4: 005-931-291
A5: 4 | B5: Casa Del Basco | D5: 107-549-729
A6: 5 | B6: Crisel General Merchandise | C6: Cresencio M. Verana | D6: 135-792-662
A7: 6 | B7: Claire's Drugstore | C7: Claire H. Abad | D7: 264-438-671
A8: 7 | B8: Davocol's General Merchandise | C8: Lilibeth T. Davocol | D8: 116-311-342
A9: 8 | B9: Davocol's Inn | C9: Dan Ardie T. Davocol | D9: 739-884-154
A10: 9 | B10: D' Islands Gasoline Station | C10: Lito Doroteo A. Adarme | D10: 124-072-664
A11: 10 | B11: Doque's Congie Hauz | C11: Glenda L. Gordo | D11: 922-904-311
A12: 11 | B12: D. Michael Co Industrial Supply (DMC) Corp. | C12: Eunelyn O. Ramilla | D12: 007-776-953
A13: 12 | B13: E. A. Amboy General Merchandise | C13: Cesar Edgardo Amboy | D13: 928-655-269 | E13: repair of personal & household goods,tailoring,dressmaking printing,beverages
A14: 13 | B14: Enrinar Trading | C14: Narcisa Co Melad | D14: 123-394-221
A15: 14 | B15: FMG Trading & Construction Supply | C15: Frederick Gari | D15: 219-884-940
A16: 15 | B16: GDP Trading | C16: George D. Peralta | D16: 150-214-534 | E16: beverages,pharmaceutical,medical,computers,agri.farm
A17: 16 | B17: Hubalde's Drugstore | C17: Marilyn G. Hubalde | D17: 914-979-941
A18: 17 | B18: Hudzan Café & Catering Services | C18: Susan Villegas | D18: 290-315-057 | E18: **
A19: 18 | B19: I.B.S Pharmacy & General Merchadise | C19: Dale Anthony C. Gutierrez | D19: 411-599-160 | E19: pharmaceutical,medical,and other sale in specialized stores
A20: 19 | B20: IAM'J Graphic Design & Printing | C20: Jaycy S. Alina | D20: 318-666-833
A21: 20 | B21: JPM General Merchandise & Hardware | C21: Emma P. Adarme | D21: 160-183-814
A22: 21 | B22: J-Tech Trading & Services | C22: Cecilia C. De Sagon | D22: 933-429-635 | E22: office supplies,computers,office machines,other service activities
A23: 22 | B23: M.G. Hubalde's General Merchandise | C23: Marilyn G. Hubalde | D23: 914-979-941-001 | E23: clothing,appliances,hardware,computers,fuel products,agri.farm
A24: 23 | B24: MDAC Trading & Compuserve | C24: Florescita A. Cruz | D24: 100-194-776 | E24: printing,office & school supplies,medical supplies & equipments
A25: 24 | B25: NRA Hardware | C25: Neil Bernardo Ordas | D25: 196-062-499
A26: 25 | B26: One-Touch Technology Trading | C26: Janice A. Alasco | D26: 283-009-327 | E26: office machines,equipments,pharmaceutical & medical,construction supplies,sports & athletic
A27: 26 | B27: Pension Ivatan | C27: Teresita D. Valiente | D27: 106-115-883
A28: 27 | B28: Sophia Marie Store | C28: Regina B. Gabaldon | D28: 279-057-542
A29: 28 | B29: Twixbiz General Merchandise | C29: Charles B. Domingo | D29: 118-687-531
A30: 29 | B30: Northern Star General Merchandise | C30: Cesar A. Calma | D30: 151-407-774 | E30: retail of Agri farm supplies & equipment,other retail sale in specialized stores
A31: 30 | B31: SKR Furiture & Fixture Trading | C31: Delma M. Abad | D31: 443-694-557 | E31: sale of computer,various merchandise,hardware,construction supplies,household appliances,office supplies,machines & equipment
A32: 31 | B32: Philippine Red Cross | C32: Waldimar C. Ballada | D32: 000-804-271-096
A33: 32 | B33: Marconine's Food Catering Services | C33: Winefredo C. Maduro | D33: 917-830-052
A34: 33 | B34: Korner Hauz Café | C34: Zharmaine C. Guttierez | D34: 431-974-729
A35: 34 | B35: J. F. Gabotero, Inc. | C35: Quirino Crisanto F. Gabotero | D35: 770-322-881
A36: 35 | B36: KCM hardware & Construction Supplies | C36: Kathleen Enica Co Melad | D36: 466-514-463
A37: 36 | B37: MKM Hardware | C37: Enrique Abuyo Melad Jr. | D37: 148-780-907
A38: 37 | B38: NSGB Books Trading | C38: Nica Sandra Go Banag
A39: 38 | B39: ONPREM2CLOUD IT SOLUTIONS CO. | C39: Emmanuel B. Mamayson | D39: 101-626-582
A40: 39 | B40: Petonio's Kitchen Food Services | C40: Ramona C. Tabuso | D40: 013-000-080-045-720-21
...

Sheet FundCodes
A1: CODE | B1: CATEGORY | C1: OFFICE/UNIT | D1: Fund
A2: GAS1 | B2: General Administration Services | C2: Office of the President | D2: 01-101
A3: GAS2 | B3: General Administration Services | C3: Office of the Board Secretary | D3: 05-164
A4: GAS3 | B4: General Administration Services | C4: Office of the College Secretary | D4: 06-162
A5: GAS4 | B5: General Administration Services | C5: Information & Communications Technology Unit | D5: 07-165
A6: GAS5 | B6: General Administration Services | C6: Information Unit
A7: GAS6 | B7: General Administration Services | C7: Internal Audit Unit
A8: GAS7 | B8: General Administration Services | C8: Legal Unit
A9: GAS8 | B9: General Administration Services | C9: Planning Unit
A10: GAS9 | B10: General Administration Services | C10: Project Management Unit
A11: GAS10 | B11: General Administration Services | C11: Quality Assurance Office
A12: GAS11 | B12: General Administration Services | C12: Administrative Office
A13: GAS12 | B13: General Administration Services | C13: Cash Unit
A14: GAS13 | B14: General Administration Services | C14: General Services Unit
A15: GAS14 | B15: General Administration Services | C15: Human Resource Management Unit
A16: GAS15 | B16: General Administration Services | C16: Procurement Unit
A17: GAS16 | B17: General Administration Services | C17: Records Unit
... A45: Acad9 | B45: Director for Instruction | C45: DI
A46: 1005 | B46: Research & Extension Office | C46: RDET
A47: 1006 | B47: College Business Affairs Office | C47: CBAO
A48: 1006A | B48: College Assessment Center | C48: College Assessment Center
A49: 1006B | B49: College Business Affairs Office | C49: CBAO-IGP
A50: 1006C | B50: College Business Affairs Office | C50: CBAO-Dorm
A51: 1006D | B51: College Business Affairs Office | C51: CBAO-Hostel

Sheet DATA
A1: YEAR | B1: MONTH | C1: End-User | D1: Position/Designation | E1: Fund Code | F1: Class | G1: PR# | H1: Modality | I1: Item | J1: Qty | K1: Unit of Issue | L1: Unit Budget | M1: Estimated Total | N1: Unit LCRB | O1: Total | P1: Purpose | Q1: Office | R1: Date of LON | S1: Date of BAC Award | T1: PO/Contract Date | U1: PO/Contract Date Received | V1: Delivery Date | W1: Supplier | X1: IAR Date | Y1: Section Code/Dept. | Z1: Released Date | AA1: Status | AB1: Remarks | AC1: ObR # | AD1: # of RFQ's printed | AE1: Sales/Charge Invoice/Billing
A2: 2025 | B2: July | C2: WARLITO M. TOMAS JR. | D2: Project Leader | E2: 165 | G2: 2025-234 | I2: Feeds (lactation) | J2: 20 | K2: sacks | L2: 1950 | M2: =SUM(J2*L2) -> 39000 | N2: 1970 | O2: =SUM(J2*N2) -> 39400 | P2: feeds for native pigs (Feeds Formulation) | Q2: Agri-DOST-PCAARRD | R2: July 23, 2025 | S2: July 30, 2025 | T2: July 31, 2025 | U2: August 12, 2025 | V2: August 18, 2025 | W2: Bartilad Feeds Trading | X2: August 18, 2025 | Y2: 1005 | Z2: September 3, 2025 | AA2: complete | AB2: for payment-Acctg. | AC2: 07-02-2025-07-0255 | AD2: 3 RFQ's + 1Blank | AE2: 043/8/18/2025
A3: 2025 | B3: July | C3: WARLITO M. TOMAS JR. | D3: Project Leader | E3: 165 | G3: 2025-234 | I3: Gestation | J3: 20 | K3: sacks | L3: 1900 | M3: =SUM(J3*L3) -> 38000 | N3: 1900 | O3: =SUM(J3*N3) -> 38000 | P3: feeds for native pigs (Feeds Formulation) | Q3: Agri-DOST-PCAARRD | R3: July 23, 2025 | S3: July 30, 2025 | T3: July 31, 2025 | U3: August 12, 2025 | V3: August 18, 2025 | W3: Bartilad Feeds Trading | X3: August 18, 2025 | Y3: 1005 | Z3: September 3, 2025 | AA3: complete | AB3: for payment-Acctg. | AC3: 07-02-2025-07-0255
A4: 2025 | B4: July | C4: WARLITO M. TOMAS JR. | D4: Project Leader | E4: 165 | G4: 2025-234 | I4: Grower | J4: 10 | K4: sacks | L4: 2000 | M4: =SUM(J4*L4) -> 20000 | N4: 2000 | O4: =SUM(J4*N4) -> 20000 | P4: feeds for native pigs (Feeds Formulation) | Q4: Agri-DOST-PCAARRD | R4: July 23, 2025 | S4: July 30, 2025 | T4: July 31, 2025 | U4: August 12, 2025 | V4: August 18, 2025 | W4: Bartilad Feeds Trading | X4: August 18, 2025 | Y4: 1005 | Z4: September 3, 2025 | AA4: complete | AB4: for payment-Acctg. | AC4: 07-02-2025-07-0255
A5: 2025 | B5: July | C5: WARLITO M. TOMAS JR. | D5: Project Leader | E5: 165 | G5: 2025-234 | I5: Starter | J5: 5 | K5: sacks | L5: 2200 | M5: =SUM(J5*L5) -> 11000 | N5: 2070 | O5: =SUM(J5*N5) -> 10350 | P5: feeds for native pigs (Feeds Formulation) | Q5: Agri-DOST-PCAARRD | R5: July 23, 2025 | S5: July 30, 2025 | T5: July 31, 2025 | U5: August 12, 2025 | V5: August 18, 2025 | W5: Bartilad Feeds Trading | X5: August 18, 2025 | Y5: 1005 | Z5: September 3, 2025 | AA5: complete | AB5: for payment-Acctg. | AC5: 07-02-2025-07-0255
A6: 2025 | B6: July | C6: KLARISSE KEITH M. COBICO | D6: Administrative Assistant III | G6: 2025-235 | I6: Self-inking Dater Stamp -- Date Format: month/day/year, Year starts at 2025 | J6: 2 | K6: pcs | L6: 350 | M6: =SUM(J6*L6) -> 700 | O6: =SUM(J6*N6) -> 0 | P6: for office use | Q6: OOP | Y6: GAS1 | AA6: FAILED | AB6: quotation exceeded the budget | AD6: 4 RFQ's
A7: 2025 | B7: July | C7: KLARISSE KEITH M. COBICO | D7: Administrative Assistant III | G7: 2025-235 | I7: Stamp Pad (purple)- medium (125mm x 85mm) | J7: 1 | K7: pc | L7: 110 | M7: =SUM(J7*L7) -> 110 | O7: =SUM(J7*N7) -> 0 | P7: for office use | Q7: OOP | Y7: GAS1
A8: 2025 | B8: July | C8: KLARISSE KEITH M. COBICO | D8: Administrative Assistant III | G8: 2025-235 | I8: Transparent Tape (3/4 inch) | J8: 5 | K8: pcs | L8: 20 | M8: =SUM(J8*L8) -> 100 | O8: =SUM(J8*N8) -> 0 | P8: for office use | Q8: OOP | Y8: GAS1
A9: 2025 | B9: July | C9: KLARISSE KEITH M. COBICO | D9: Administrative Assistant III | G9: 2025-235 | I9: Certificate Holder, A4-size (green) | J9: 20 | K9: pcs | L9: 75 | M9: =SUM(J9*L9) -> 1500 | O9: =SUM(J9*N9) -> 0 | P9: for office use | Q9: OOP | Y9: GAS1
A10: 2025 | B10: July | C10: KLARISSE KEITH M. COBICO | D10: Administrative Assistant III | G10: 2025-235 | I10: Ruler (12 inches) | J10: 1 | K10: pc | L10: 15 | M10: =SUM(J10*L10) -> 15 | O10: =SUM(J10*N10) -> 0 | P10: for office use | Q10: OOP | Y10: GAS1
A11: 2025 | B11: July | C11: KLARISSE KEITH M. COBICO | D11: Administrative Assistant III | G11: 2025-235 | I11: Ruler (18 inches) | J11: 1 | K11: pc | L11: 55 | M11: =SUM(J11*L11) -> 55 | O11: =SUM(J11*N11) -> 0 | P11: for office use | Q11: OOP | Y11: GAS1
A12: 2025 | B12: July | C12: KLARISSE KEITH M. COBICO | D12: Administrative Assistant III | G12: 2025-235 | I12: Tower Extension Cord 12 outlets with switch WTE-512 Heavy Duty | J12: 2 | K12: unit | L12: 1700 | M12: =SUM(J12*L12) -> 3400 | O12: =SUM(J12*N12) -> 0 | P12: for office use | Q12: OOP | Y12: GAS1
A13: 2025 | B13: July | C13: KLARISSE KEITH M. COBICO | D13: Administrative Assistant III | G13: 2025-235 | I13: White Glue (130gms) | J13: 2 | K13: bottle | L13: 80 | M13: =SUM(J13*L13) -> 160 | O13: =SUM(J13*N13) -> 0 | P13: for office use | Q13: OOP | Y13: GAS1
A14: 2025 | B14: July | C14: KLARISSE KEITH M. COBICO | D14: Administrative Assistant III | G14: 2025-235 | I14: BT D100 (black,magenta,cyan,yellow) | J14: 2 | K14: set | L14: 2200 | M14: =SUM(J14*L14) -> 4400 | O14: =SUM(J14*N14) -> 0 | P14: for office use | Q14: OOP | Y14: GAS1
A15: 2025 | B15: July | C15: KLARISSE KEITH M. COBICO | D15: Administrative Assistant III | G15: 2025-235 | I15: Mailing Envelop (long) | J15: 1 | K15: box | L15: 530 | M15: =SUM(J15*L15) -> 530 | O15: =SUM(J15*N15) -> 0 | P15: for office use | Q15: OOP | Y15: GAS1
A16: 2025 | B16: July | C16: KLARISSE KEITH M. COBICO | D16: Administrative Assistant III | G16: 2025-235 | I16: Humidifier Scent (lavender) | J16: 1 | K16: bottle | L16: 820 | M16: =SUM(J16*L16) -> 820 | O16: =SUM(J16*N16) -> 0 | P16: for office use | Q16: OOP | Y16: GAS1
A17: 2025 | B17: July | C17: KLARISSE KEITH M. COBICO | D17: Administrative Assistant III | G17: 2025-235 | I17: Humidifier Scent (black ice) | J17: 1 | K17: bottle | L17: 820 | M17: =SUM(J17*L17) -> 820 | O17: =SUM(J17*N17) -> 0 | P17: for office use | Q17: OOP | Y17: GAS1
A18: 2025 | B18: July | C18: RICHARD B. VINALAY | D18: PM IGP Printing Services | G18: 2025-236 | I18: Desktop Computer - Specs: *Processor;Intel® Core™ i5 12th Gen.* RAM Memory; 16GB DDR4-2666MHz * Internal Storage; 1TB SSD * Graphics Card (integrate); Intel® UHD Graphics 770 *24 inches Full HD display monitor * Pre-Install; Windows 11 & MS Office * Includes; Mouse, Keyboard, Speaker *WiFi ready | J18: 1 | K18: unit | L18: 50000 | M18: =SUM(J18*L18) -> 50000 | O18: =SUM(J18*N18) -> 0 | P18: use for IGP Printing Services & Book Binding | Q18: CBAO-IGP | Y18: 1006B | AA18: FAILED | AB18: quotation exceeded the budget | AD18: 5 RFQ's + 1blank
A19: 2025 | B19: July | C19: RICHARD B. VINALAY | D19: PM IGP Printing Services | G19: 2025-236 | I19: Desktop Glue Binding Machine - Maximum size; 210*297mm, Copy Thickness; 20-500 pages (A4 paper), Format; A4 Digital, Temperature Control; Yes, Machine size; 560*360*510mm, Preheating Time; about 10 minutes, Display Mode; LCD display, Machine Power; 220V (500W),Includes; 2 packs of 5kg Hot Melt Glue Pellet for Book Binding | J19: 1 | K19: unit | L19: 34000 | M19: =SUM(J19*L19) -> 34000 | O19: =SUM(J19*N19) -> 0 | P19: use for IGP Printing Services & Book Binding | Q19: CBAO-IGP | Y19: 1006B
A20: 2025 | B20: July | C20: RICHARD B. VINALAY | D20: PM IGP Printing Services | G20: 2025-236 | I20: A3 Paper Creasing Machine - manual paper creaser multi-function indentation dashing machine | J20: 1 | K20: unit | L20: 9000 | M20: =SUM(J20*L20) -> 9000 | O20: =SUM(J20*N20) -> 0 | P20: use for IGP Printing Services & Book Binding | Q20: CBAO-IGP | Y20: 1006B
A21: 2025 | B21: July | C21: JERSHON RALPH F. CASTANO | D21: Admin. Aide III | E21: 101 | G21: 2025-237 | I21: Premium Gasoline | J21: 420 | K21: L | L21: 104 | M21: =SUM(J21*L21) -> 43680 | N21: 92 | O21: =SUM(J21*N21) -> 38640 | P21: fuel for collge motorcycle and other laboratory machines | Q21: GSO | R21: July 23, 2025 | S21: July 24, 2025 | T21: July 25, 2025 | U21: August 5, 2025 | V21: August 13, 2025 | W21: D'Island Gasoline Station | X21: August 15, 2025 | Y21: GAS20 | Z21: August 22, 2025 | AA21: complete | AB21: for payment-Acctg. | AC21: 02-101101-2025-07-00530 | AD21: 3 RFQ's | AE21: 11855/8/5/2025
A22: 2025 | B22: July | C22: JERSHON RALPH F. CASTANO | D22: Admin. Aide III | E22: 101 | G22: 2025-238 | I22: Diesel, Company Sealed | J22: 420 | K22: L | L22: 100 | M22: =SUM(J22*L22) -> 42000 | N22: 94 | O22: =SUM(J22*N22) -> 39480 | P22: fuel for collge motorcycle and other laboratory machines | Q22: GSO | R22: July 23, 2025 | S22: July 28, 2025 | T22: July 30, 2025 | U22: August 11, 2025 | V22: August 14, 2025 | W22: D'Island Gasoline Station | X22: August 14, 2025 | Y22: GAS20 | Z22: August 22, 2025 | AA22: complete | AB22: for payment-Acctg. | AC22: 02-101101-2025-07-00534 | AD22: 3 RFQ's | AE22: 11856/8/14/2025
A23: 2025 | B23: July | C23: JERSHON RALPH F. CASTANO | D23: Admin. Aide III | E23: 101 | G23: 2025-239 | I23: Multi-purpose bleach for home and laundry, (1000ml / bottle) | J23: 96 | K23: bottle | L23: 50 | M23: =SUM(J23*L23) -> 4800 | N23: 70 | O23: =SUM(J23*N23) -> 6720 | P23: supplies & materials for the upkeeping of comfort rooms | Q23: GSO | R23: July 23, 2025 | S23: July 24, 2025 | T23: July 25, 2025 | U23: August 5, 2025 | V23: Aug. 11 & Sept. 5, 2025 | W23: GDP Trading | X23: Aug. 11 & Sept. 5, 2025 | Y23: GAS20 | Z23: September 19, 2025 | AA23: complete | AB23: for payment-Acctg. | AC23: 02-101101-2025-07-00531 | AD23: 4 RFQ's | AE23: 23602/9/8/2025
A24: 2025 | B24: July | C24: JERSHON RALPH F. CASTANO | D24: Admin. Aide III | E24: 101 | G24: 2025-239 | I24: 100mm x 70mm Scrub Sponge | J24: 10 | K24: pc | L24: 55 | M24: =SUM(J24*L24) -> 550 | N24: 65 | O24: =SUM(J24*N24) -> 650 | P24: supplies & materials for the upkeeping of comfort rooms | Q24: GSO | R24: July 23, 2025 | S24: July 24, 2025 | T24: July 25, 2025 | U24: August 5, 2025 | V24: Aug. 11 & Sept. 5, 2025 | W24: GDP Trading | X24: Aug. 11 & Sept. 5, 2025 | Y24: GAS20 | Z24: September 19, 2025 | AA24: complete | AB24: for payment-Acctg. | AC24: 02-101101-2025-07-00531 | AD24: 4 RFQ's
A25: 2025 | B25: July | C25: JERSHON RALPH F. CASTANO | D25: Admin. Aide III | E25: 101 | G25: 2025-239 | I25: Toilet Hand-held bidet sprayer w/ hose | J25: 10 | K25: set | L25: 700 | M25: =SUM(J25*L25) -> 7000 | N25: 310 | O25: =SUM(J25*N25) -> 3100 | P25: supplies & materials for the upkeeping of comfort rooms | Q25: GSO | R25: July 23, 2025 | S25: July 24, 2025 | T25: July 25, 2025 | U25: August 5, 2025 | V25: Aug. 11 & Sept. 5, 2025 | W25: GDP Trading | X25: Aug. 11 & Sept. 5, 2025 | Y25: GAS20 | Z25: September 19, 2025 | AA25: complete | AB25: for payment-Acctg. | AC25: 02-101101-2025-07-00531
A26: 2025 | B26: July | C26: JERSHON RALPH F. CASTANO | D26: Admin. Aide III | E26: 101 | G26: 2025-239 | I26: Male Urinal push button flush valve | J26: 10 | K26: pc | L26: 650 | M26: =SUM(J26*L26) -> 6500 | N26: 385 | O26: =SUM(J26*N26) -> 3850 | P26: supplies & materials for the upkeeping of comfort rooms | Q26: GSO | R26: July 23, 2025 | S26: July 24, 2025 | T26: July 25, 2025 | U26: August 5, 2025 | V26: Aug. 11 & Sept. 5, 2025 | W26: GDP Trading | X26: Aug. 11 & Sept. 5, 2025 | Y26: GAS20 | Z26: September 19, 2025 | AA26: complete | AB26: for payment-Acctg. | AC26: 02-101101-2025-07-00531
A27: 2025 | B27: July | C27: ARNEL D. PABLEO | D27: Information Systems Analyst 1 | E27: 101 | G27: 2025-240 | I27: Stamp Pad Ink | J27: 2 | K27: pc | L27: 150 | M27: =SUM(J27*L27) -> 300 | N27: 30 | O27: =SUM(J27*N27) -> 60 | P27: for use on enrollment | Q27: Registrar | R27: July 24, 2025 | S27: July 31, 2025 | T27: July 31, 2025 | U27: August 12, 2025 | W27: GDP Trading | Y27: SS05 | AA27: inc. delivery | AB27: 0.82 | AC27: 02-101101-2025-07-00535 | AD27: 5 RFQ's
A28: 2025 | B28: July | C28: ARNEL D. PABLEO | D28: Information Systems Analyst 1 | E28: 101 | G28: 2025-240 | I28: Self-inking Personalized Stamp (30mm x 60mm) | J28: 1 | K28: pc | L28: 2000 | M28: =SUM(J28*L28) -> 2000 | N28: 575 | O28: =SUM(J28*N28) -> 575 | P28: for use on enrollment | Q28: Registrar | R28: July 24, 2025 | S28: July 31, 2025 | T28: July 31, 2025 | U28: August 12, 2025 | W28: GDP Trading | Y28: SS05 | AC28: 02-101101-2025-07-00535
A29: 2025 | B29: July | C29: ARNEL D. PABLEO | D29: Information Systems Analyst 1 | E29: 101 | G29: 2025-240 | I29: Pastel Stamp Ink | J29: 1 | K29: pc | L29: 350 | M29: =SUM(J29*L29) -> 350 | N29: 105 | O29: =SUM(J29*N29) -> 105 | P29: for use on enrollment | Q29: Registrar | R29: July 24, 2025 | S29: July 31, 2025 | T29: July 31, 2025 | U29: August 12, 2025 | W29: GDP Trading | Y29: SS05 | AC29: 02-101101-2025-07-00535
A30: 2025 | B30: July | C30: ARNEL D. PABLEO | D30: Information Systems Analyst 1 | E30: 101 | G30: 2025-240 | I30: Correction Tape (5mm x 10mm) | J30: 10 | K30: pc | L30: 50 | M30: =SUM(J30*L30) -> 500 | N30: 45 | O30: =SUM(J30*N30) -> 450 | P30: for use on enrollment | Q30: Registrar | R30: July 24, 2025 | S30: July 31, 2025 | T30: July 31, 2025 | U30: August 12, 2025 | W30: GDP Trading | Y30: SS05 | AC30: 02-101101-2025-07-00535
A31: 2025 | B31: July | C31: ARNEL D. PABLEO | D31: Information Systems Analyst 1 | E31: 101 | G31: 2025-240 | I31: Sign Pen (blue) | J31: 10 | K31: pc | L31: 50 | M31: =SUM(J31*L31) -> 500 | N31: 40 | O31: =SUM(J31*N31) -> 400 | P31: for use on enrollment | Q31: Registrar | R31: July 24, 2025 | S31: July 31, 2025 | T31: July 31, 2025 | U31: August 12, 2025 | W31: GDP Trading | Y31: SS05 | AC31: 02-101101-2025-07-00535
A32: 2025 | B32: July | C32: ARNEL D. PABLEO | D32: Information Systems Analyst 1 | E32: 101 | G32: 2025-240 | I32: Double-sided Foam Tape ( 1 inch) | J32: 2 | K32: roll | L32: 150 | M32: =SUM(J32*L32) -> 300 | N32: 110 | O32: =SUM(J32*N32) -> 220 | P32: for use on enrollment | Q32: Registrar | R32: July 24, 2025 | S32: July 31, 2025 | T32: July 31, 2025 | U32: August 12, 2025 | W32: GDP Trading | Y32: SS05 | AC32: 02-101101-2025-07-00535
A33: 2025 | B33: July | C33: ARNEL D. PABLEO | D33: Information Systems Analyst 1 | E33: 101 | G33: 2025-240 | I33: Double-sided Tape ( 1 inch) | J33: 5 | K33: roll | L33: 60 | M33: =SUM(J33*L33) -> 300 | N33: 40 | O33: =SUM(J33*N33) -> 200 | P33: for use on enrollment | Q33: Registrar | R33: July 24, 2025 | S33: July 31, 2025 | T33: July 31, 2025 | U33: August 12, 2025 | W33: GDP Trading | Y33: SS05 | AC33: 02-101101-2025-07-00535
A34: 2025 | B34: July | C34: ARNEL D. PABLEO | D34: Information Systems Analyst 1 | E34: 101 | G34: 2025-240 | I34: Paper Clips (vinyl coated, 33mm) | J34: 3 | K34: box | L34: 25 | M34: =SUM(J34*L34) -> 75 | N34: 25 | O34: =SUM(J34*N34) -> 75 | P34: for use on enrollment | Q34: Registrar | R34: July 24, 2025 | S34: July 31, 2025 | T34: July 31, 2025 | U34: August 12, 2025 | W34: GDP Trading | Y34: SS05 | AC34: 02-101101-2025-07-00535
A35: 2025 | B35: July | C35: ARNEL D. PABLEO | D35: Information Systems Analyst 1 | E35: 101 | G35: 2025-240 | I35: Paper Clips (vinyl coated, 50mm) | J35: 2 | K35: box | L35: 30 | M35: =SUM(J35*L35) -> 60 | N35: 35 | O35: =SUM(J35*N35) -> 70 | P35: for use on enrollment | Q35: Registrar | R35: July 24, 2025 | S35: July 31, 2025 | T35: July 31, 2025 | U35: August 12, 2025 | W35: GDP Trading | Y35: SS05 | AC35: 02-101101-2025-07-00535
A36: 2025 | B36: July | C36: ARNEL D. PABLEO | D36: Information Systems Analyst 1 | E36: 101 | G36: 2025-240 | I36: Binder Clip (2") | J36: 2 | K36: dozen | L36: 300 | M36: =SUM(J36*L36) -> 600 | N36: 105 | O36: =SUM(J36*N36) -> 210 | P36: for use on enrollment | Q36: Registrar | R36: July 24, 2025 | S36: July 31, 2025 | T36: July 31, 2025 | U36: August 12, 2025 | W36: GDP Trading | Y36: SS05 | AC36: 02-101101-2025-07-00535
A37: 2025 | B37: July | C37: ARNEL D. PABLEO | D37: Information Systems Analyst 1 | E37: 101 | G37: 2025-240 | I37: Binder Clip (1") | J37: 2 | K37: dozen | L37: 120 | M37: =SUM(J37*L37) -> 240 | N37: 30 | O37: =SUM(J37*N37) -> 60 | P37: for use on enrollment | Q37: Registrar | R37: July 24, 2025 | S37: July 31, 2025 | T37: July 31, 2025 | U37: August 12, 2025 | W37: GDP Trading | Y37: SS05 | AC37: 02-101101-2025-07-00535
A38: 2025 | B38: July | C38: ARNEL D. PABLEO | D38: Information Systems Analyst 1 | E38: 101 | G38: 2025-240 | I38: Binder Clip (3/4") | J38: 3 | K38: dozen | L38: 72 | M38: =SUM(J38*L38) -> 216 | N38: 25 | O38: =SUM(J38*N38) -> 75 | P38: for use on enrollment | Q38: Registrar | R38: July 24, 2025 | S38: July 31, 2025 | T38: July 31, 2025 | U38: August 12, 2025 | W38: GDP Trading | Y38: SS05 | AC38: 02-101101-2025-07-00535
A39: 2025 | B39: July | C39: ARNEL D. PABLEO | D39: Information Systems Analyst 1 | E39: 101 | G39: 2025-240 | I39: Binder Clip (5/8") | J39: 3 | K39: dozen | L39: 60 | M39: =SUM(J39*L39) -> 180 | N39: 60 | O39: =SUM(J39*N39) -> 180 | P39: for use on enrollment | Q39: Registrar | R39: July 24, 2025 | S39: July 31, 2025 | T39: July 31, 2025 | U39: August 12, 2025 | W39: GDP Trading | Y39: SS05 | AC39: 02-101101-2025-07-00535
... A53: 2025 | B53: July | C53: ARNEL D. PABLEO | D53: Information Systems Analyst 1 | E53: 101 | G53: 2025-240 | I53: Scotch Tape (1") | J53: 3 | K53: roll | L53: 100 | M53: =SUM(J53*L53) -> 300 | N53: 30 | O53: =SUM(J53*N53) -> 90 | P53: for use on enrollment | Q53: Registrar | R53: July 24, 2025 | S53: July 31, 2025 | T53: July 31, 2025 | U53: August 12, 2025 | W53: GDP Trading | Y53: SS05 | AC53: 02-101101-2025-07-00535
...

Sheet PR
A7: PURCHASE REQUEST
D9: PR No. | E9: =DATA!G114 -> 2025-251 | F9: Date
A10: Department: | D10: SAI No.:
A11: Section: | B11: =DATA!Y114 -> SS02 | D11: OBR#
A12: Ref. No.: | B12: 2507-SS02-251
A14: Qty | B14: Unit of Issue | D14: Item Description | F14: Stock No. | G14: Estimated
G15: Unit Cost | H15: Total Cost
A16: =DATA!J114 -> 900 | B16: =DATA!K114 -> pcs | D16: =DATA!I114 -> Health Insurance Coverage: Accidental Death & Disablement,Unprovoked Murder & Assault Medical Expense or Reimbursement,Burial Benefits due to Accident/Natural Death,Daily Hospital Benefits due to Accident or illness,Dengue Cash Assistance,Ambulance Cash Assistance,Fire Cash Assistance,COVID-19 Cash Assistance for "Death Only",Combined Single Limit for Bodily Injury & Property Damage within premises of the school campus | G16: =DATA!L114 -> 200 | H16: =SUM(A16*G16) -> 180000
H17: =SUM(A17*G17) -> 0
H18: =SUM(A18*G18) -> 0
H19: =SUM(A19*G19) -> 0
H20: =SUM(A20*G20) -> 0
H21: =SUM(A21*G21) -> 0
H22: =SUM(A22*G22) -> 0
H23: =SUM(A23*G23) -> 0
H24: =SUM(A24*G24) -> 0
H25: =SUM(A25*G25) -> 0
H26: =SUM(A26*G26) -> 0
H27: =SUM(A27*G27) -> 0
H28: =SUM(A28*G28) -> 0
... H38: =SUM(A38*G38) -> 0
A39: =DATA!J50 -> 4 | B39: =DATA!K50 -> bottle | D39: =DATA!I179 -> Rotary Hammer 850 W 3-Mode Function, with Drill Bit & Chisel included, 220V-240V | G39: =DATA!L50 -> 650 | H39: =SUM(A39*G39) -> 2600
A40: =DATA!J51 -> 4 | B40: =DATA!K51 -> bottle | D40: =DATA!I180 -> Rotary Hammer 28mm, 1300W with Drill Bit & Chisel included, 220V-240V | G40: =DATA!L51 -> 650 | H40: =SUM(A40*G40) -> 2600
A41: =DATA!J52 -> 2 | B41: =DATA!K52 -> roll | D41: =DATA!I181 -> 45-135˚ Multi Angel Miter Shear Cutter, Adjustable angle cutter for cutting plastic, PVC & Molding Trim | G41: =DATA!L52 -> 150 | H41: =SUM(A41*G41) -> 300
A42: =DATA!J53 -> 3 | B42: =DATA!K53 -> roll | D42: =DATA!I182 -> U Type Edge trimming scissor 45 degrees 90 degrees Trunking Pliers (Large Edge Clamp) | G42: =DATA!L53 -> 100 | H42: =SUM(A42*G42) -> 300
A43: =DATA!J54 -> 140 | B43: =DATA!K100 -> copy | D43: =DATA!I183 -> U Type Edge trimming scissor 45 degrees 90 degrees Trunking Pliers (Small size Edge Clamp) | G43: =DATA!L183 -> 700 | H43: =SUM(A43*G43) -> 98000
A44: =DATA!J55 -> 10.5 | B44: =DATA!K101 -> copy | D44: =DATA!I184 -> 9000KPA Portable Pressure Washer set: with Pressure Gauge & Adjustable Pressure, PW Gun, High Pressure Hose, Water Inlet connector & filter, Foam spray bottle | G44: =DATA!L184 -> 4000 | H44: =SUM(A44*G44) -> 42000
A45: =DATA!J56 -> 9.5 | B45: =DATA!K102 -> copy | D45: =DATA!I185 -> Electric Air Blower 650W Hand Dust Cleaner Blow Machine, 650W - AB6038, Dust Bag Included, Max Blowing Rate 0-4.0m/min., input power 650W | G45: =DATA!L185 -> 3000 | H45: =SUM(A45*G45) -> 28500
A46: =DATA!J57 -> 1 | D46: =DATA!I186 -> Aircon Coli Cleaner | G46: =DATA!L186 -> 1500 | H46: =SUM(A46*G46) -> 1500
A47: =DATA!J58 -> 1 | D47: =DATA!I187 -> Aircon Fin Straightener/Fin Comb, Condenser Evaporator Fin | G47: =DATA!L187 -> 500 | H47: =SUM(A47*G47) -> 500
A48: =DATA!J59 -> 1 | D48: =DATA!I188 -> 2 Liter Hand Pressure Pump Sprayer (LTGT2000HSX) | G48: =DATA!L188 -> 1000 | H48: =SUM(A48*G48) -> 1000
A49: =DATA!J60 -> 1 | D49: =DATA!I189 -> 5L Shoulder Hand-Operated Sprayer (LTGT5000PSX) | G49: =DATA!L189 -> 2000 | H49: =SUM(A49*G49) -> 2000
A50: =DATA!J61 -> 10 | D50: =DATA!I190 -> Wet & Dry Vaccuum Cleaner, 3 in 1 Carpet Extractor Cleaner, Power: 1034 W, Voltage: 230 v, 40 Liter | G50: =DATA!L190 -> 23000 | H50: =SUM(A50*G50) -> 230000
A51: =DATA!J62 -> 2 | D51: =DATA!I191 -> BSC medal (diameter: 9cm, Gold Plated) | G51: =DATA!L191 -> 1200 | H51: =SUM(A51*G51) -> 2400
A52: =DATA!J63 -> 2 | D52: =DATA!I192 -> Molder | G52: =DATA!L192 -> 9850 | H52: =SUM(A52*G52) -> 19700
A53: =DATA!J64 -> 3 | D53: =DATA!I193 -> Plaque for Loyalty Award - made of premium quality MDF wood, size: 30cm-35cm; inclusive of design and lay-out logo of Batanes State College,customized with recipient's name, award title and events details; mounted on a sturdy wooden base; | G53: =DATA!L193 -> 950 | H53: =SUM(A53*G53) -> 2850
A54: =DATA!J65 -> 3 | D54: =DATA!I194 -> Shovel | G54: =DATA!L194 -> 500 | H54: =SUM(A54*G54) -> 1500
A55: =DATA!J66 -> 2 | D55: =DATA!I195 -> Construction Reflectorized Vest (yellow green) | G55: =DATA!L195 -> 180 | H55: =SUM(A55*G55) -> 360
A56: =DATA!J67 -> 1 | D56: =DATA!I196 -> Gold Spray Paint | G56: =DATA!L196 -> 160 | H56: =SUM(A56*G56) -> 160
A57: =DATA!J68 -> 2 | D57: =DATA!I197 -> 2 x 3 Palochina | G57: =DATA!L197 -> 400 | H57: =SUM(A57*G57) -> 800
...

Sheet Direct Acq.-Res
A7: BAC Resolution Recommending use of New Mode of Procurement under Direct Acquisition
B8: BAC Resolution No. | D8: =PR!B12 -> 2507-SS02-251
A10: WHEREAS, Section 26 Rule IV of the Implementing Rules and Regulations of RA 12009 allows the use of New Modes of Procurement consistent with the Fit-for-Purpose approach;
A11: WHEREAS, Section 32 allows Direct Acquisition as a mode of procurement of CSE not available in the PS-DBM, Non-CSE, and services with ABC not exceeding Two Hundred Thousand Pesos (₱200,000.00);
A12: WHEREAS, the Procuring Entity, without need to conduct a canvass or request for quotations, may procure directly from any known and reputable sources;
A13: WHEREAS, Goods covered under this mode may be procured from stores, such as but not limited to, department store,depot, fast food chain, grocery and supermarket, wholesale and retail store, convenience store, clothing and apparel store,bookstore, drugstore and pharmacy, automotive parts and accessories store, construction and hardware store, and online stores.
A14: WHEREAS, The HoPE may authorize the End-User or Implementing Unit to directly purchase from any known and reputable source with legal, technical, and financial capacity, based on any of the following: a)The Suppliers are registered with the PhilGEPS as verified from the PhilGEPS website; b) The goods are available in electronic commerce platforms for delivery or pick up at such date and time identified by the Procuring Entity; and c) The goods are readily available off-the-shelf and can be picked up or delivered immediately;
A15: WHEREAS, Purchase Request No. | D15: =PR!E9 -> 2025-251 | E15: involves the procurement of
A16: Sustainable Farming: Nurturing the Earth for Future Generations,Kushwaha, 2024, 9781774699515, The Genetic Manipulation in Plants, Singh, 2023, 9789394137646,,etc,.-- the list of book titles have been carefully selected by the program chairpersons to enhance the learning resources
A17: with the approved budget of | D17: =PR!H110 -> 180000
A18: WHEREAS, Procuring Entities shall procure only from sources that issue invoices compliant with the rules of the BIR or other documents evidencing delivery and payment acceptable to the COA;
A20: NOW THEREFORE, we, the members of the Bids and Awards Committee hereby RESOLVE as it is hereby RESOLVED to recommend to the College President to adopt Direct Acquisition as Mode of Procurement for the said transaction;
A22: RESOLVED FINALLY, at the Batanes State College, this
A23: Recommending Approval:
A26: RHOUPHELINE AYA A. CADIZ | C26: FORTUNATO PHILIP A. CABUGAO | F26: EMILYN D. ALUETA
A27: BAC Member | C27: BAC Member | F27: BAC Member
A30: =PR!B115 -> JENNY S. ALINA | C30: PHILIP ULYSSES T. CASTILLO | F30: DOREEN C. CASTILLO
A31: End-User/Provisional Member | C31: BAC Vice Chairperson | E31: BAC Chairperson
A32: BRYAN H. CIELO
A33: DELMA G. MALUPA-ABAD
A34: EDWIN F.MACABALLUG, Ph.D.
A35: LIEZL P. DELA CRUZ
A36: RODERICK Y. ABAD
A37: VILMA D. BACCAY
A38: ESTEBAN C. BADAJOS
A39: LEOBERT L. BANZALI
A40: MIAH DAPHNIE B. BUENAFE
A41: GLORIA N. CABIZON
A42: FORTUNATO PHILIP A. CABUGAO
A43: RICARDO Q. CABUGAO, JR.
... A83: DARYL ALVA C. BATIN

Sheet ResoSVP (3)
A7: BAC Resolution Recommending Alternative Mode of Procurement under Small Value Procurement
B8: BAC Resolution No. | D8: =PR!B12 -> 2507-SS02-251
A10: WHEREAS, Section 48 Rule XVI of the Revised Implementing Rules and Regulations of RA 9184 allows Alternative Mode of Procurement subject to prior approval of the HOPE thru Annual Procurement Plan (APP) and only to promote economy and efficiency;
A11: WHEREAS, Section 53.9 allows Small Value Procurement provided that the procurement does not fall under shopping in Section 52 of this IRR and the amount involved does not exceed the thresholds prescribed in Annex "H" of this IRR;
A12: WHEREAS, Appendix 18, Section 3.e on the Guidelines for Shopping and Small Value Procurement provides an Abstract of Quotations shall be prepared setting forth the names of those who responded to the RFQ's right after the deadline for submission except for shopping under Section 52.1(b), where at least three (3) price quotations (RFQ) must be obtained;
A13: WHEREAS, Annex "H" of the Consolidated Guidelines for the Alternative Methods of Procurement prescribed under Section V, Paragraph D.8.b.ii that the BAC shall prepare and send the RFQs/RFPs to at least three (3) suppliers, contractors or consultants of known qualifications where receipt of at least one (1) quotations is sufficient to proceed with the evaluation thererof;
A14: WHEREAS, Purchase Request No. | D14: =PR!E9 -> 2025-251 | E14: involves the procurement of
A15: Refill Ink (BT5000-C,M,Y),BTD60BK-black,Air Freshener,Trash Bag (small),Dishwashing Paste --to be use for printing of Certification of Registration during enrollment for 1st Sem AY 2025-2026,printing of documents & other office purposes
A16: with the approved budget of | D16: =PR!H110 -> 180000
A17: WHEREAS, the default mode of evaluation shall be on a lot basis which means that the determination of the single/lowest calculated and responsive bid (S/LCRB) is the total amount of offered unit price multiply by the required quantity;
A19: NOW THEREFORE, we, the members of the Bids and Awards Committee hereby RESOLVE as it is hereby RESOLVED to recommend to the College President to adopt Alternative Mode of Procurement under Small Value Procurement for the said transaction;
A21: RESOLVED FINALLY, at the Batanes State College, this
A22: Recommending Approval:
A25: RHOUPHELINE AYA A. CADIZ | C25: FORTUNATO PHILIP A. CABUGAO | E25: EMILYN D. ALUETA
A26: BAC Member | C26: BAC Member | E26: BAC Member
A29: =PR!B115 -> JENNY S. ALINA | C29: PHILIP ULYSSES T. CASTILLO | E29: DOREEN C. CASTILLO
A30: End-User/Provisional Member | C30: BAC Vice Chairperson | E30: BAC Chairperson
A31: BRYAN H. CIELO
A32: DELMA G. MALUPA-ABAD
A33: EDWIN F.MACABALLUG, Ph.D.
A34: LIEZL P. DELA CRUZ
A35: RODERICK Y. ABAD
A36: VILMA D. BACCAY
A37: ESTEBAN C. BADAJOS
A38: LEOBERT L. BANZALI
A39: MIAH DAPHNIE B. BUENAFE
A40: GLORIA N. CABIZON
A41: FORTUNATO PHILIP A. CABUGAO
A42: RICARDO Q. CABUGAO, JR.
... A82: DARYL ALVA C. BATIN

Sheet Direct Acq.-App
A4: Approval of BAC Resolution Recommending Mode of Procurement under Direct Acquisition
B6: BAC Resolution No. | D6: =PR!B12 -> 2507-SS02-251
A8: WHEREAS, Section 48 Rule XVI of the Revised Implementing Rules and Regulations of RA 9184 allows Alternative Mode of Procurement subject to prior approval of the HOPE thru Annual Procurement Plan (APP) and only to promote economy and efficiency;
A9: WHEREAS, Section 53.9 allows Small Value Procurement provided that the procurement does not fall under shopping in Section 52 of this IRR and the amount involved does not exceed the thresholds prescribed in Annex "H" of this IRR;
A10: WHEREAS, Appendix 18, Section 3.e on the Guidelines for Shopping and Small Value Procurement provides an Abstract of Quotations shall be prepared setting forth the names of those who responded to the RFQ's right after the deadline for submission except for shopping under Section 52.1(b), where at least three (3) price quotations (RFQ) must be obtained;
A11: WHEREAS, Annex "H" of the Consolidated Guidelines for the Alternative Methods of Procurement prescribed under Section V, Paragraph D.8.b.ii that the BAC shall prepare and send the RFQs/RFPs to at least three (3) suppliers, contractors or consultants of known qualifications where receipt of at least one (1) quotations is sufficient to proceed with the evaluation thererof;
A12: WHEREAS, Purchase Request No. | D12: =PR!E9 -> 2025-251 | E12: involves the procurement of
A13: Sustainable Farming: Nurturing the Earth for Future Generations,Kushwaha, 2024, 9781774699515, The Genetic Manipulation in Plants, Singh, 2023, 9789394137646,,etc,.-- the list of book titles have been carefully selected by the program chairpersons to enhance the learning resources | H13: Items:
A14: with the approved budget of | D14: =PR!H110 -> 180000
A15: WHEREAS, the default mode of evaluation shall be on a lot basis which means that the determination of the single/lowest calculated and responsive bid (S/LCRB) is the total amount of offered unit price multiply by the required quantity;
A16: NOW THEREFORE, I,DR.DJOVI R. DURANTE, Head of the Procuring Entity (HOPE) by virtue of the authority vested in me by the Board of Trustees of this Institution and after taking into consideration the merits and legal bases of the recommendation of the members of the Bids and Awards Committee (BAC) do hereby APPROVE the foregoing recommendation and adoption of Alternative Mode of Procurement under Small Value Procurement;
A18: APPROVED FINALLY, at the Batanes State College, this | F18: ___________________
D22: DJOVI REGALA DURANTE,DPA
D23: SUC President I
A30: BRYAN H. CIELO
A85: EMILYN D. ALUETA
A86: EMILYN D. ALUETA

Sheet AResoSVP
A5: Approval of BAC Resolution Recommending Alternative Mode of Procurement under Small Value Procurement
B7: BAC Resolution No. | D7: =PR!B12 -> 2507-SS02-251
A9: WHEREAS, Section 48 Rule XVI of the Revised Implementing Rules and Regulations of RA 9184 allows Alternative Mode of Procurement subject to prior approval of the HOPE thru Annual Procurement Plan (APP) and only to promote economy and efficiency;
A10: WHEREAS, Section 53.9 allows Small Value Procurement provided that the procurement does not fall under shopping in Section 52 of this IRR and the amount involved does not exceed the thresholds prescribed in Annex "H" of this IRR;
A11: WHEREAS, Appendix 18, Section 3.e on the Guidelines for Shopping and Small Value Procurement provides an Abstract of Quotations shall be prepared setting f+A1:S11orth the names of those who responded to the RFQ's right after the deadline for submission except for shopping under Section 52.1(b), where at least three (3) price quotations (RFQ) must be obtained;
A12: WHEREAS, Annex "H" of the Consolidated Guidelines for the Alternative Methods of Procurement prescribed under Section V, Paragraph D.8.b.ii that the BAC shall prepare and send the RFQs/RFPs to at least three (3) suppliers, contractors or consultants of known qualifications where receipt of at least one (1) quotations is sufficient to proceed with the evaluation thererof;
A13: WHEREAS, Purchase Request No. | D13: =PR!E9 -> 2025-251 | E13: involves the procurement of
A14: Refill Ink (BT5000-C,M,Y),BTD60BK-black,Air Freshener,Trash Bag (small),Dishwashing Paste --to be use for printing of Certification of Registration during enrollment for 1st Sem AY 2025-2026,printing of documents & other office purposes | H14: Items:
A15: with the approved budget of | D15: =PR!H110 -> 180000
A16: WHEREAS, the default mode of evaluation shall be on a lot basis which means that the determination of the single/lowest calculated and responsive bid (S/LCRB) is the total amount of offered unit price multiply by the required quantity;
A17: NOW THEREFORE, I,DR.DJOVI R. DURANTE, Head of the Procuring Entity (HOPE) by virtue of the authority vested in me by the Board of Trustees of this Institution and after taking into consideration the merits and legal bases of the recommendation of the members of the Bids and Awards Committee (BAC) do hereby APPROVE the foregoing recommendation and adoption of Alternative Mode of Procurement under Small Value Procurement;
A19: APPROVED FINALLY, at the Batanes State College, this | F19: ___________________
C23: DJOVI REGALA DURANTE,DPA
C24: SUC President I
A31: BRYAN H. CIELO
A86: EMILYN D. ALUETA
A87: EMILYN D. ALUETA

Sheet RFQ_ (2)
E6: Date: | F6: =NOW() -> 46148.741
A7: REQUEST FOR PRICE QUOTATION
A8: CMVILL Trading
A9: Please give us your best and final price offer for the item/s listed below, have this signed and submit this by you or by your duly authorized representative WITHIN SEVEN (7) CALENDAR DAYS upon receipt to Procurement Section, Batanes State College.
A11: NOTE: | B11: 1. THE DEFAULT MODE OF PRICE EVALUATION SHALL BE ON A LOT BASIS, OTHERWISE PER ITEMS EVALUATION SHALL BE USED IF THERE WILL BE LACKING ITEMS IN ALL RFQ's AND SUBJECT TO END-USER APPROVAL., (Clause 15.2, Section I, Instruction to Bidders of the Philippine Bidding Documents for goods and infrastructure projects)
B12: 2. DELIVERY PERIOD: Thirty (30) calendar days.
B13: 3. Submission of price quotation shall be in sealed envelope.
B14: 4. THE APPROVED BUDGET FOR THIS PROCUREMENT IS
B15: =PR!H110 -> 180000 | D15: (GPPB Resolution No. 09-2009)
B16: 5. PURSUANT TO ANNEX "H", APPENDIX A, SECTION II, SUBMISSION OF APPLICABLE DOCUMENTS (e.g.MAYORS/BUSINESS PERMIT, PROFESSIONAL LICENSE/CURRICULUM VITAE (CONSULTING SEERVICES),PHILGEPS CERT. NO., PCAB LICENSE (INFRA), INCOME/BUSINESS TAX RETURN,OMNIBUS SWORN STATEMENT SHALL BE REQUIRED BEFORE THE ISSUANCE OF NOA OR PRIOR TO PAYMENT.
B17: 6. In case the item is not availble, please write "None".
A18: Item # | B18: Qty. | C18: Unit | D18: PARTICULAR | E18: Unit Price | F18: Total
A19: 001 | B19: =PR!A16 -> 900 | C19: =PR!B16 -> pcs | D19: =PR!D16 -> Health Insurance Coverage: Accidental Death & Disablement,Unprovoked Murder & Assault Medical Expense or Reimbursement,Burial Benefits due to Accident/Natural Death,Daily Hospital Benefits due to Accident or illness,Dengue Cash Assistance,Ambulance Cash Assistance,Fire Cash Assistance,COVID-19 Cash Assistance for "Death Only",Combined Single Limit for Bodily Injury & Property Damage within premises of the school campus
A20: 002 | B20: =PR!A17 -> 0 | C20: =PR!B17 -> 0 | D20: =PR!D17 -> 0
A21: 003 | B21: =PR!A18 -> 0 | C21: =PR!B18 -> 0 | D21: =PR!D18 -> 0
A22: 004 | B22: =PR!A19 -> 0 | C22: =PR!B19 -> 0 | D22: =PR!D19 -> 0
A23: 005 | B23: =PR!A20 -> 0 | C23: =PR!B20 -> 0 | D23: =PR!D20 -> 0
A24: 006 | B24: =PR!A21 -> 0 | C24: =PR!B21 -> 0 | D24: =PR!D21 -> 0
A25: 007 | B25: =PR!A22 -> 0 | C25: =PR!B22 -> 0 | D25: =PR!D22 -> 0
A26: 008
A27: 009
A28: 010 | B28: =PR!A25 -> 0
A29: 011 | B29: =PR!A26 -> 0
A30: 012 | B30: =PR!A27 -> 0
A31: 013 | B31: =PR!A28 -> 0
A32: 014 | B32: =PR!A29 -> 0
A33: 015 | B33: =PR!A30 -> 0
A34: 016 | B34: =PR!A31 -> 0
A35: 017 | B35: =PR!A32 -> 0
A36: 018 | B36: =PR!A33 -> 0
A37: 019 | B37: =PR!A34 -> 0
A38: 020 | B38: =PR!A35 -> 0
A39: 021 | B39: =PR!A36 -> 0
... A41: 023 | B41: =PR!A38 -> 0
A42: 024 | B42: =PR!A39 -> 4 | C42: =[1]PR!B39 -> copy | D42: =PR!D39 -> Rotary Hammer 850 W 3-Mode Function, with Drill Bit & Chisel included, 220V-240V
A43: 025 | B43: =PR!A40 -> 4 | C43: =[1]PR!B40 -> copy | D43: =PR!D40 -> Rotary Hammer 28mm, 1300W with Drill Bit & Chisel included, 220V-240V
A44: 026 | B44: =PR!A41 -> 2 | C44: =[1]PR!B41 -> copy | D44: =PR!D41 -> 45-135˚ Multi Angel Miter Shear Cutter, Adjustable angle cutter for cutting plastic, PVC & Molding Trim
A45: 027 | B45: =PR!A42 -> 3 | C45: =[1]PR!B43 -> sets | D45: =PR!D42 -> U Type Edge trimming scissor 45 degrees 90 degrees Trunking Pliers (Large Edge Clamp)
A46: 028 | B46: =PR!A43 -> 140 | C46: =[1]PR!B44 -> pcs | D46: =PR!D43 -> U Type Edge trimming scissor 45 degrees 90 degrees Trunking Pliers (Small size Edge Clamp)
A47: 029 | B47: =PR!A44 -> 10.5 | C47: =[1]PR!B45 -> pcs | D47: =PR!D44 -> 9000KPA Portable Pressure Washer set: with Pressure Gauge & Adjustable Pressure, PW Gun, High Pressure Hose, Water Inlet connector & filter, Foam spray bottle
...

Sheet RFQ_
E5: Date: | F5: =NOW() -> 46148.741
A6: REQUEST FOR PRICE QUOTATION
A7: One-Touch Technology Trading | B7: MOJR Construction Trading & General Services, Ltd, Co. | C7: MOJR Construction Trading & General Services, Ltd, Co. | D7: MOJR Construction Trading & General Services, Ltd, Co.
A8: Please give us your best and final price offer for the item/s listed below, have this signed and submit this by you or by your duly authorized representative WITHIN SEVEN (7) CALENDAR DAYS upon receipt to Procurement Section, Batanes State College.
A10: NOTE: | B10: 1. THE DEFAULT MODE OF PRICE EVALUATION SHALL BE ON A LOT BASIS, OTHERWISE PER ITEMS EVALUATION SHALL BE USED IF THERE WILL BE LACKING ITEMS IN ALL RFQ's AND SUBJECT TO END-USER APPROVAL., (Clause 15.2, Section I, Instruction to Bidders of the Philippine Bidding Documents for goods and infrastructure projects)
B11: 2. DELIVERY PERIOD: Thirty (30) calendar days.
B12: 3. Submission of price quotation shall be in sealed envelope.
B13: 4. THE APPROVED BUDGET FOR THIS PROCUREMENT IS
B14: =PR!H110 -> 180000 | D14: (GPPB Resolution No. 09-2009)
B15: 5. PURSUANT TO ANNEX "H", APPENDIX A, SECTION II, SUBMISSION OF APPLICABLE DOCUMENTS (e.g.MAYORS/BUSINESS PERMIT, PROFESSIONAL LICENSE/CURRICULUM VITAE (CONSULTING SEERVICES),PHILGEPS CERT. NO., PCAB LICENSE (INFRA), INCOME/BUSINESS TAX RETURN,OMNIBUS SWORN STATEMENT SHALL BE REQUIRED BEFORE THE ISSUANCE OF NOA OR PRIOR TO PAYMENT.
B16: 6. In case the item is not availble, please write "None".
A17: Item # | B17: Qty. | C17: Unit | D17: PARTICULAR | E17: Unit Price | F17: Total
A18: 001 | B18: =PR!A16 -> 900 | C18: =PR!B16 -> pcs | D18: =PR!D16 -> Health Insurance Coverage: Accidental Death & Disablement,Unprovoked Murder & Assault Medical Expense or Reimbursement,Burial Benefits due to Accident/Natural Death,Daily Hospital Benefits due to Accident or illness,Dengue Cash Assistance,Ambulance Cash Assistance,Fire Cash Assistance,COVID-19 Cash Assistance for "Death Only",Combined Single Limit for Bodily Injury & Property Damage within premises of the school campus
A19: 002
A20: 003
A21: 004
A22: 005
A23: 006
A24: 007
A25: 008
A26: 009
A27: 010
A28: 011
A29: 012
A30: 013
... A32: 015
A33: 019 | B33: =PR!A33 -> 0 | C33: =PR!B33 -> 0 | D33: =PR!D34 -> 0
A34: 019 | B34: =PR!A34 -> 0 | C34: =PR!B34 -> 0 | D34: =PR!D34 -> 0
A35: 020 | B35: =PR!A35 -> 0 | C35: =PR!B35 -> 0 | D35: =PR!D35 -> 0
A36: 021 | B36: =PR!A36 -> 0 | C36: =PR!B36 -> 0 | D36: =PR!D36 -> 0
A37: 022 | B37: =PR!A37 -> 0 | C37: =PR!B37 -> 0 | D37: =PR!D37 -> 0
A38: 023 | B38: =PR!A38 -> 0 | C38: =PR!B38 -> 0 | D38: =PR!D38 -> 0
A39: 024 | B39: =PR!A39 -> 4 | C39: =PR!B39 -> bottle | D39: =PR!D39 -> Rotary Hammer 850 W 3-Mode Function, with Drill Bit & Chisel included, 220V-240V
A40: 025 | B40: =PR!A40 -> 4 | C40: =PR!B40 -> bottle | D40: =PR!D40 -> Rotary Hammer 28mm, 1300W with Drill Bit & Chisel included, 220V-240V
A41: 026 | B41: =PR!A41 -> 2 | C41: =PR!B41 -> roll | D41: =PR!D41 -> 45-135˚ Multi Angel Miter Shear Cutter, Adjustable angle cutter for cutting plastic, PVC & Molding Trim
A42: 027 | B42: =PR!A42 -> 3 | C42: =PR!B42 -> roll | D42: =PR!D42 -> U Type Edge trimming scissor 45 degrees 90 degrees Trunking Pliers (Large Edge Clamp)
A43: 028 | B43: =PR!A43 -> 140 | C43: =PR!B43 -> copy | D43: =PR!D43 -> U Type Edge trimming scissor 45 degrees 90 degrees Trunking Pliers (Small size Edge Clamp)
A44: 029 | B44: =PR!A44 -> 10.5 | C44: =PR!B44 -> copy | D44: =PR!D44 -> 9000KPA Portable Pressure Washer set: with Pressure Gauge & Adjustable Pressure, PW Gun, High Pressure Hose, Water Inlet connector & filter, Foam spray bottle
A45: 030 | B45: =PR!A45 -> 9.5 | C45: =PR!B45 -> copy | D45: =PR!D45 -> Electric Air Blower 650W Hand Dust Cleaner Blow Machine, 650W - AB6038, Dust Bag Included, Max Blowing Rate 0-4.0m/min., input power 650W
... A85: 070 | B85: =PR!A85 -> 1 | C85: =PR!B85 -> 0 | D85: =PR!D85 -> 9 Watts LED Bulb, Warm White, E27
...

Sheet AckReceipt
A1: Acknowledgement for Request for Quotation
A2: RIS# | B2: =PR!B12 -> 2507-SS02-251
A3: No. | B3: Supplier | F3: Received by: | G3: Date & Time:
B4: JPM Gen. Mdse. & Hardware
B5: Thine-line Trading
B6: J-Tech Trading & Services
B7: MDAC Trading & Compuserve
B8: FVA Gen Mdse & Construction Supply
B10: GDP Trading
B11: EA Amboy Gen Mdse
B12: L & R's Hontomin Gen Mdse
B13: Davocol's Gen. Mdse.
B14: RCJ Hardware & Gen Mdse
B15: Fitero's Gen Mdse & Electronic Supply
B16: Lar & San's Store
... B18: Wilmerson Gen Mdse
B19: FMG Trading & Construction Supply | C19: q
B20: MG Hubalde Gen Mdse
B21: Basco Cable TV Services, Inc.
B22: Berlen's Store
B23: Melad's Gen. Mdse
B24: R. A. Electronics
B25: RJ General Merchandise
B26: Batanes Multi-Purpose Cooperative, Inc.
B27: Romy & Ava's Store
B28: J-nell's Gen Mdse
B29: Impression Digital Printing Solutions
B30: Golden Press
B31: Tawsen's Agri-Venture & Souvenirs
... B60: Sophia Marie Store
A61: 1 | B61: Apostol's General Merchandise
A62: 2 | B62: CMVILL Trading
A63: 3 | B63: JPM General Merchandise & Hardware
A64: 4 | B64: One-Touch Technology Trading
A65: 5 | B65: YCA Office Supplies & Equipment | J65: zz
A66: 6
A67: 7
A68: NOTE: | B68: 1. MODE OF PRICE EVALUATION SHALL BE ON A LOT BASIS, OTHERWISE PER ITEMS EVALUATION SHALL BE USED IF THERE WILL BE LACKING ITEMS IN ALL RFQ'S AND THE END-USER AGREED, . (Clause 15.2, Section II, Instructions to Bidders of the Philippine Bidding Documents for goods and infrastructure projects)
B69: 2. DELIVERY PERIOD: Thirty (30) calendar days.
B70: 3. WARRANTY SHALL BE FOR A PERIOD OF SIX (6) MONTHS FOR SUPPLIES AND MATERIALS, ONE (1) YEAR FOR EQUIPMENT, FROM THE DATE OF ACCEPTANCE BY THE PROCURING ENTITY.
...

Sheet Abstract 
B4: ABSTRACT OF QUOTATIONS
B6: (x) Furnishing/delivery of supplies, and materials or equipment | G6: Bids opened at Basco, Batanes
B7: ( x ) Furnishing Labor, services, etc. | I7: =NOW() -> 46148.741
B8: ( ) Rental or use of transportation facilities equipment, quarters, rooms, lot or space, etc.
B10: To be furnished at the | D10: BATANES STATE COLLEGE
C11: (State place or site of Office or project where articles or services be furnished or returned)
A13: NAME OF ARTICLES OR SERVICES TO BE FURNISHED, RENDERED OR FACILITIES TO BE RENTED
F16: JPM Gen. Mdse. & Hardware
F17: Thine-line Trading
F18: J-Tech Trading & Services
F19: Mulong Ydel
F20: MDAC Trading & Compuserve
F21: FVA Gen Mdse & Construction Supply
F22: MKM Hardware
F23: GDP Trading
F24: EA Amboy Gen Mdse
F25: L & R's Hontomin Gen Mdse
F26: Davocol's Gen. Mdse.
F27: RCJ Hardware & Gen Mdse
... F88: Valiente Food Producer
F89: =DATA!W114 -> Bethel General Insurance & Surety Corporation | G89: AlliedBankers Insurance Corporation | H89: Philippine Redcross
N90: JPM General Merchandise & Hardware
A91: =PR!D16 -> Health Insurance Coverage: Accidental Death & Disablement,Unprovoked Murder & Assault Medical Expense or Reimbursement,Burial Benefits due to Accident/Natural Death,Daily Hospital Benefits due to Accident or illness,Dengue Cash Assistance,Ambulance Cash Assistance,Fire Cash Assistance,COVID-19 Cash Assistance for "Death Only",Combined Single Limit for Bodily Injury & Property Damage within premises of the school campus | B91: Bond paper, A4 size | C91: Bond paper, A4 size | D91: Bond paper, A4 size | E91: Bond paper, A4 size | F91: =DATA!O114 -> 117000 | G91: No Philgeps Registration | H91: No Philgeps Registration | L91: none
L92: none
L93: none
B100: Bond paper, A4 size | C100: Bond paper, A4 size | D100: Bond paper, A4 size | E100: Bond paper, A4 size
A114: =DATA!I179 -> Rotary Hammer 850 W 3-Mode Function, with Drill Bit & Chisel included, 220V-240V | B114: Bond paper, A4 size | C114: Bond paper, A4 size | D114: Bond paper, A4 size | E114: Bond paper, A4 size | F114: =DATA!O50 -> 2620 | G114: 2200 | H114: 2320 | I114: 2320
