Workbook

Sheet PMR-Data
A2: MONTH | B2: (Multiple Items)
A3: YEAR | B3: (Multiple Items)
A5: PR# | B5: Purpose | C5: End-User | D5: Modality | E5: Delivery Date | F5: IAR Date | G5: Fund Code | H5: Class | I5: Status | J5: Sum of Estimated Total | K5: Sum of Total
A6: 202-013A | B6: supplies for the repair & maintenance of the building | C6: JERSHON RALPH F. CASTANO | D6: SVP | E6: August 23, 2021 | F6: August 23, 2021 | G6: 101 | H6: MOOE | I6: complete | J6: 85520 | K6: 65665
A7: 2021-001A | B7: snacks for the "Internal Quality Audit" on January 19-21, 2021 | J7: 17850 | K7: 17850
A8: 2021-002 | B8: Supply and installation of CCTV for Academic Building, Dormitory and Agriculture Building | C8: ALETH A. MEORA | D8: SVP | E8: April 27, 2021 | F8: May 26, 2021` | G8: 101 | H8: CO | I8: complete | J8: 435000 | K8: 397860
A9: 2021-002A | B9: to be used in the different activities and internet communication needs of BSC | C9: RANDALL G. CASTILLO | D9: SVP | E9: 5/19 & 7/19/2021 | F9: 5/26 & 7/21/2021 | G9: 101 | H9: (blank) | I9: complete | J9: 25500 | K9: 25480
A10: 2021-003 | B10: Purchase of Academic Equipment | C10: ALETH A. MEORA | D10: SVP | E10: 5/19 & 7/19/2021 | F10: 5/19 & 7/21/2021 | G10: 101 | H10: CO | I10: complete | J10: 947218.62 | K10: 928620
A11: 2021-003A | B11: for PBB compliance specifically transparency seal and BSC publication | C11: RANDALL G. CASTILLO | D11: SVP | E11: February 16, 2021 | F11: March 2, 2021 | G11: 165 | H11: MOOE | I11: complete | J11: 49000 | K11: 45560
A12: 2021-004 | B12: for the purchase of Academic Equipments | C12: ALETH A. MEORA | D12: SVP | E12: January 12, 2021 | F12: April 27, 2021 | G12: 101 | H12: CO | I12: complete | J12: 972105.5 | K12: 791000
A13: 2021-004A | B13: for the purchase of enrollment forms | C13: RHEA ANGELLICA B. ADDATU | D13: SVP | E13: August 23, 2021 | F13: August 23, 2021 | G13: 101 | H13: (blank) | I13: (blank) | J13: 22500 | K13: 22500
A14: 2021-005 | B14: Purchase of Academic Equipment | C14: ALETH A. MEORA | D14: SVP | E14: 44396 | F14: 44403 | G14: 101 | H14: CO | I14: reimbursement | J14: 378961.7 | K14: 359780
A15: 2021-005A | B15: to be used in the different activities and internet communication needs of BSC | C15: RANDALL G. CASTILLO | D15: SVP | E15: May 19, 2021 | F15: May 26, 2021 | G15: 101 | H15: MOOE | I15: complete | J15: 30250 | K15: 29960
A16: 2021-006 | B16: Supply and Delivery of Academic Equipment | C16: ALETH A. MEORA | D16: SVP | E16: January 12, 2021 | F16: January 25, 2021 | G16: 101 | H16: CO | I16: complete | J16: 315813.75 | K16: 195700
E17: January 25, 2021 | F17: January 25, 2021 | G17: 101 | H17: CO | I17: complete | J17: 45000 | K17: 42000
A18: 2021-006A | B18: for the ISO Activity Management Review on Feb. 3, 2021 | C18: ROMINA KATRINA C. BAYARAS | D18: SVP | E18: 44230 | F18: February 16, 2021 | G18: 164 | H18: MOOE | I18: complete | J18: 14000 | K18: 11800
A19: 2021-007A | B19: Internet data/Regular load Allocation of Administrative & Finance staff of the college to support online submission of reports & other related activities for the Fiscal Year 2021 | C19: DJOVI R. DURANTE | D19: SVP | E19: March 29, 2021 | F19: March 31, 2021 | G19: 101 | H19: MOOE | I19: complete | J19: 107880 | K19: 107880
A20: 2021-008A | B20: for the "ISO Documentation" | C20: ROMINA KATRINA C. BAYARAS | D20: SVP | E20: March 15, 2021 | F20: March 15, 2021 | G20: 164 | H20: MOOE | I20: complete | J20: 3960 | K20: 3885
A21: 2021-009 | B21: Purchase of Academic Furniture Fixtures | C21: ALETH A. MEORA | D21: SVP | E21: August 23, 2021 | F21: August 23, 2021 | G21: 101 | H21: MOOE | I21: complete | J21: 200000 | K21: 199680
A22: 2021-009A | B22: stamp use for the filing of ISO documents | C22: ROMINA KATRINA C. BAYARAS | D22: SVP | E22: - | F22: - | G22: 165 | H22: (blank) | I22: FAILED | J22: 28000 | K22: 0
A23: 2021-0100 | B23: for the Implementation of "ADOPT through Varied R & D of Ivatan Endemic Resources" research project | C23: JANE S. CASTILLO | D23: SVP | E23: August 23, 2021 | F23: August 23, 2021 | G23: 165 | H23: MOOE | I23: for delivery | J23: 30950 | K23: 29315
A24: 2021-0101 | B24: office supplies for the Administrative & Finance Services Units | C24: DJOVI R. DURANTE | D24: SVP | E24: August 23, 2021 | F24: August 23, 2021 | G24: 165 | H24: MOOE | I24: for delivery | J24: 30840 | K24: 28941.9
A25: 2021-0102 | B25: supplies for Budget office | C25: BRYAN DAVE P. REVILLA | D25: SVP | E25: August 23, 2021 | F25: August 23, 2021 | G25: 101 | H25: MOOE | I25: for delivery | J25: 3500 | K25: 2990
A26: 2021-0103 | B26: supplies for Budget office | C26: BRYAN DAVE P. REVILLA | D26: SVP | E26: July 1, 2021 | F26: July 1, 2021 | G26: 101 | H26: MOOE | I26: complete | J26: 790 | K26: 600
A27: 2021-0104 | B27: supplies for the Budget office | C27: BRYAN DAVE P. REVILLA | D27: SVP | E27: August 23, 2021 | F27: August 23, 2021 | G27: 101 | H27: MOOE | I27: for delivery | J27: 1000 | K27: 800
A28: 2021-0105 | B28: repair of 2 units floor type airconditioner at Faculty Room | C28: JERSHON RALPH F. CASTANO | D28: SVP | E28: August 23, 2021 | F28: August 23, 2021 | G28: (blank) | H28: (blank) | I28: FAILED | J28: 13000
A29: 2021-0106 | B29: GSO Supplies | C29: JERSHON RALPH F. CASTANO | D29: SVP | E29: July 19 & 26, 2021 | F29: July 21 & 26, 2021 | G29: 101 | H29: MOOE | I29: complete | J29: 10950 | K29: 8314
A30: 2021-0107 | B30: GSO Supplies | C30: JERSHON RALPH F. CASTANO | D30: SVP | E30: 44399 | F30: 44411 | G30: 101 | H30: MOOE | I30: reimbursement | J30: 18500 | K30: 15780
A31: 2021-0108 | B31: Snack for the Preparatory Board Meeting on June 25, 2021 at 10:00 a.m | C31: GERZON R. ABAD | D31: SVP | E31: August 23, 2021 | F31: August 23, 2021 | G31: (blank) | H31: (blank) | I31: FAILED | J31: 3000 | K31: 0
A32: 2021-0109 | B32: PM snack and dinner for the 52nd Board of Trustees Meeting on June 25, 2021 | C32: GERZON R. ABAD | D32: SVP | E32: June 25, 2021 | F32: 44377 | G32: 101 | H32: MOOE | I32: reimbursement | J32: 13000 | K32: 9000
A33: 2021-010A | B33: ink use for enrollment | C33: RHEA ANGELLICA B. ADDATU | D33: SVP | E33: August 23, 2021 | F33: August 23, 2021 | G33: 101 | H33: (blank) | I33: FAILED | J33: 1500
A34: 2021-0110 | B34: Lunch, PM Snack and Dinner of Commissioner Lilian A. De Las Llagas and Staff for the 52nd BOT Meeting on 25 June 2021 | C34: GERZON R. ABAD | D34: SVP | E34: August 23, 2021 | F34: August 23, 2021 | G34: (blank) | H34: (blank) | I34: reimbursement | J34: 12597.5 | K34: 12597.5
A35: 2021-0111 | B35: repair & maintenance of A/C units of Registrar's, Cashier's, Accountant's & President's office | C35: JERSHON RALPH F. CASATANO | D35: SVP | E35: August 23, 2021 | F35: August 23, 2021 | G35: 101 | H35: MOOE | I35: on-going | J35: 8000 | K35: 8000
A36: 2021-0112 | B36: supplies for the rewiring of faculty room electrical system | C36: JERSHON RALPH F. CASATANO | D36: SVP | E36: July 21, 2021 | F36: July 26, 2021 | G36: 101 | H36: MOOE | I36: complete | J36: 23700 | K36: 21624
A37: 2021-0113 | B37: for the purchase of Semi-expendable equipments purposes | C37: JERSHON RALPH F. CASATANO | D37: SVP | E37: August 23, 2021 | F37: August 23, 2021 | G37: 101 | H37: MOOE | I37: on-going | J37: 10000 | K37: 10000
A38: 2021-011A | B38: for the Pre Assessment Audit Plan on Feb. 10-11, 2021 | C38: ROMINA KATRINA C. BAYARAS | D38: SVP | E38: February 10-11, 2021 | F38: March 2, 2021 | G38: 164 | H38: MOOE | I38: complete | J38: 7500 | K38: 7125
A39: 2021-012A | B39: supplies for the repair & maintenance of transportation vehicle | C39: JERSHON RALPH F. CASTANO | D39: SVP | E39: March 31, 2021 | F39: April 5, 2021 | G39: 101 | H39: MOOE | I39: on-going | J39: 49399.99 | K39: 42550
A40: 2021-013 | B40: Puchase of drafting tables and chairs for the Academiic Furnitures and Fixtures | C40: ALETH A. MEORA | D40: SVP | E40: January 26, 2021 | F40: January 26, 2021 | G40: 101 | H40: CO | I40: complete | J40: 277500 | K40: 195000
A41: 2021-014A | B41: office machinery & equipment | C41: JERSHON RALPH F. CASTANO | D41: SVP | E41: March 29, 2021 | F41: March 30, 2021 | G41: 101 | H41: MOOE | I41: complete | J41: 47002 | K41: 42500
A42: 2021-015A | B42: supplies for janitorial services | C42: JERSHON RALPH F. CASTANO | D42: SVP | E42: April 15, 2021 | F42: April 15, 2021 | G42: 101 | H42: MOOE | I42: complete | J42: 5000 | K42: 3000
...

Sheet FundCodes (2)
A1: CODE | B1: CATEGORY | C1: OFFICE/UNIT | D1: Fund
A2: GAS1 | B2: General Administration Services | C2: Office of the President | D2: 01-101
A3: GAS2 | B3: General Administration Services | C3: Office of the Board Secretary | D3: 05-164
A4: GAS3 | B4: General Administration Services | C4: Office of the College Secretary | D4: 06-162
A5: GAS4 | B5: General Administration Services | C5: Information & Communications Technology Unit | D5: 07-165
A6: GAS5 | B6: General Administration Services | C6: Information Unit
A7: GAS6 | B7: General Administration Services | C7: Internal Audit Unit
A8: GAS7 | B8: General Administration Services | C8: Legal Unit
A9: GAS8 | B9: General Administration Services | C9: Planning Unit
A10: GAS9 | B10: General Administration Services | C10: Project Management Unit
A11: GAS10 | B11: General Administration Services | C11: Quality Assurance Office
A12: GAS11 | B12: General Administration Services | C12: Administrative Office
A13: GAS12 | B13: General Administration Services | C13: Cash Unit
A14: GAS13 | B14: General Administration Services | C14: General Services Unit
A15: GAS14 | B15: General Administration Services | C15: Human Resource Management Unit
A16: GAS15 | B16: General Administration Services | C16: Procurement Unit
A17: GAS16 | B17: General Administration Services | C17: Records Unit
... A46: Acad9 | B46: Director for Instruction | C46: DI
A47: 1005 | B47: Research & Extension Services | C47: Research & Extension Office
A48: 1006 | B48: College Business Affairs Office | C48: CBAO
A49: 1006A | B49: College Assessment Center | C49: College Assessment Center
A50: 1006B | B50: College Business Affairs Office | C50: CBAO-IGP
A51: 1006C | B51: College Business Affairs Office | C51: CBAO-Dorm
A52: 1006D | B52: College Business Affairs Office | C52: CBAO-Hostel

Sheet Suppliers TIN
B1: Business Name | C1: Name/Owner | D1: TIN #
A2: 1 | B2: Apostol General Merchandise | C2: Leo A. Apostol | D2: 183-008-448
A3: 2 | B3: Bartilad's Feeds Trading | C3: Roldan Q. Bartilad | D3: 771-272-422
A4: 3 | B4: Bitstop Network Services Inc. | C4: JC James P. Jihay | D4: 005-931-291
A5: 4 | B5: Casa Del Basco | D5: 107-549-729
A6: 5 | B6: Crisel General Merchandise | C6: Cresencio M. Verana | D6: 135-792-662
A7: 6 | B7: Claire's Drugstore | C7: Claire H. Abad | D7: 264-438-671
A8: 7 | B8: Davocol's General Merchandise | C8: Lilibeth T. Davocol | D8: 116-311-342
A9: 8 | B9: Davocol's Inn | C9: Dan Ardie T. Davocol | D9: 739-884-154
A10: 9 | B10: D' Islands gasoline Station | C10: Lito Doroteo A. Adarme | D10: 124-072-664
A11: 10 | B11: Doque's Congie Hauz | C11: Glenda L. Gordo | D11: 922-904-311
A12: 11 | B12: D. Michael Co Industrial Supply (DMC) Corp. | C12: Eunelyn O. Ramilla | D12: 007-776-953
A13: 12 | B13: E. A. Amboy General Merchandise | C13: Cesar Edgardo Amboy | D13: 928-655-269
A14: 13 | B14: Enrinar Trading | C14: Narcisa Co Melad | D14: 123-394-221
A15: 14 | B15: FMG Trading & Construction Supply | C15: Frederick Gari | D15: 219-884-940
A16: 15 | B16: GDP Trading | C16: George D. Peralta | D16: 150-214-534
A17: 16 | B17: Hubalde's Drugstore | C17: Marilyn G. Hubalde | D17: 914-979-941
A18: 17 | B18: Hudzan Café & Catering Services | C18: Susan Villegas | D18: 290-315-057 | E18: **
A19: 18 | B19: I.B.S Pharmacy & General Merchadise | C19: Dale Anthony C. Gutierrez | D19: 411-599-160
A20: 19 | B20: IAM'J Graphic Design & Printing | C20: Jaycy S. Alina | D20: 318-666-833
A21: 20 | B21: JPM General Merchandise & Hardware | C21: Emma P. Adarme | D21: 160-183-814
A22: 21 | B22: J-Tech Trading & Services | C22: Cecilia C. De Sagon | D22: 933-429-635
A23: 22 | B23: M.G. Hubalde's General Merchandise | C23: Marilyn G. Hubalde | D23: 914-979-941-001
A24: 23 | B24: MDAC Trading & Compuserve | C24: Florescita A. Cruz | D24: 100-194-776
A25: 24 | B25: NRA Hardware | C25: Neil Bernardo Ordas | D25: 196-062-499
A26: 25 | B26: One-Touch Technology Trading | C26: Janice A. Alasco | D26: 283-009-327
A27: 26 | B27: Pension Ivatan | C27: Teresita D. Valiente | D27: 106-115-883
A28: 27 | B28: Sophia Marie Store | C28: Regina B. Gabaldon | D28: 279-057-542
A29: 28 | B29: Twixbiz General Merchandise | C29: Charles B. Domingo | D29: 118-687-531
A30: 29 | B30: Northern Star General Merchandise | C30: Cesar A. Calma | D30: 151-407-774
... A37: 36 | B37: MKM Hardware | C37: Enrique Abuyo Melad Jr. | D37: 148-780-907
A38: 37 | B38: NSGB Books Trading | C38: Nica Sandra Go Banag
A39: 38 | B39: ONPREM2CLOUD IT SOLUTIONS CO. | C39: Emmanuel B. Mamayson | D39: 101-626-582
A40: 39 | B40: Petonio's Kitchen Food Services | C40: Ramona C. Tabuso | D40: 013-000-080-045-720-21
A41: 40 | B41: Tiger Consulting and Software Devt Inc. | D41: 007-073-548
A42: 41 | B42: MOJR Construction Trading & General Services, Ltd, Co. | C42: Manuel S. Obedoza Jr.
A43: 42 | B43: Batanes Electric Cooperative Inc. | C43: Victoria A. Mata | D43: 005-641-216-000
A44: 43 | B44: Maddies Fashion Design Services | C44: Madeline Palencia Palustre
A45: 44 | B45: CMVILL Trading | C45: Zariffe G. Villanueva | D45: 421-603-862-000
A46: 45 | B46: VL Mini Canteen | C46: Estela N. Lizardo | D46: 930-779-799
...

Sheet DATA
A1: YEAR | B1: MONTH | C1: End-User | D1: Position/Designation | E1: Fund Code | F1: Class | G1: PR# | H1: Modality | I1: Item | J1: Qty | K1: Unit of Issue | L1: Unit Budget | M1: Estimated Total | N1: Unit LCRB | O1: Total | P1: Purpose | Q1: Office | R1: Date of LON | S1: Date of BAC Award | T1: PO/Contract Date | U1: PO/Contract Date Received | V1: Delivery Date | W1: Supplier | X1: IAR Date | Y1: Section Code/Dept. | Z1: Released Date | AA1: Status | AB1: Remarks | AC1: ObR # | AD1: # of RFQ's printed | AE1: Sales/Charge Invoice/Billing
A2: 2025 | B2: September | C2: ANNE MARIELLE V. TEVES | D2: BAC Secretariat | E2: 101 | G2: 2025-298 | I2: Ink-LC462XL | J2: 1 | K2: cartridge | L2: 2700 | M2: =SUM(J2*L2) -> 2700 | N2: 2680 | O2: =SUM(J2*N2) -> 2680 | P2: for office use | Q2: BAC | R2: September 16, 2025 | S2: September 17, 2025 | T2: September 18, 2025 | U2: October 1, 2025 | V2: October 2, 2025 | W2: One-Touch Technology Trading | X2: October 2, 2025 | Y2: GAS22 | Z2: 45938 | AA2: complete | AB2: for payment-Acctg. | AC2: 02-101101-2025-09-00754 | AD2: 5 RFQ's | AE2: 7955/10/2/2025
A3: 2025 | B3: September | C3: ANNE MARIELLE V. TEVES | D3: BAC Secretariat | E3: 101 | G3: 2025-298 | I3: Ink-LC462-yellow | J3: 1 | K3: cartridge | L3: 2000 | M3: =SUM(J3*L3) -> 2000 | N3: 880 | O3: =SUM(J3*N3) -> 880 | P3: for office use | Q3: BAC | R3: September 16, 2025 | S3: September 17, 2025 | T3: September 18, 2025 | U3: October 1, 2025 | V3: October 2, 2025 | W3: One-Touch Technology Trading | X3: October 2, 2025 | Y3: GAS22 | Z3: 45938 | AA3: complete | AB3: for payment-Acctg. | AC3: 02-101101-2025-09-00754
A4: 2025 | B4: September | C4: ANNE MARIELLE V. TEVES | D4: BAC Secretariat | E4: 101 | G4: 2025-298 | I4: Ink-LC462-magenta | J4: 1 | K4: cartridge | L4: 2000 | M4: =SUM(J4*L4) -> 2000 | N4: 880 | O4: =SUM(J4*N4) -> 880 | P4: for office use | Q4: BAC | R4: September 16, 2025 | S4: September 17, 2025 | T4: September 18, 2025 | U4: October 1, 2025 | V4: October 2, 2025 | W4: One-Touch Technology Trading | X4: October 2, 2025 | Y4: GAS22 | Z4: 45938 | AA4: complete | AB4: for payment-Acctg. | AC4: 02-101101-2025-09-00754
A5: 2025 | B5: September | C5: ANNE MARIELLE V. TEVES | D5: BAC Secretariat | E5: 101 | G5: 2025-298 | I5: Ink-LC462-cyan | J5: 1 | K5: cartridge | L5: 2000 | M5: =SUM(J5*L5) -> 2000 | N5: 880 | O5: =SUM(J5*N5) -> 880 | P5: for office use | Q5: BAC | R5: September 16, 2025 | S5: September 17, 2025 | T5: September 18, 2025 | U5: October 1, 2025 | V5: October 2, 2025 | W5: One-Touch Technology Trading | X5: October 2, 2025 | Y5: GAS22 | Z5: 45938 | AA5: complete | AB5: for payment-Acctg. | AC5: 02-101101-2025-09-00754
A6: 2025 | B6: September | C6: SYRA KARLA C. GORDO | D6: Project Technical Specialist 1 | E6: 165 | G6: 2025-298-A | I6: Heavy Snack (spaghetti,chicken fingers canned juice) | J6: 60 | K6: pax | L6: 350 | M6: =SUM(J6*L6) -> 21000 | N6: 350 | O6: =SUM(J6*N6) -> 21000 | P6: for the implementation of the project 2 - charge to S & T based interventions for sustainable tourism in Batanes-MOOE-Direct-Represenattion Expenses | Q6: RDET-S & T | R6: September 11, 2025 | S6: September 16, 2025 | T6: September 17, 2025 | U6: September 18, 2025 | V6: September 19, 2025 | W6: Doque's Congie Hauz | X6: September 19, 2025 | Y6: 1005 | Z6: February 6, 2026 | AA6: complete | AB6: for payment-Acctg. | AC6: 07-02-2025-09-0320A | AD6: 3 RFQ's | AE6: 25-09-001/10/23/2025 0802/9/17/2025
A7: 2025 | B7: September | C7: SYRA KARLA C. GORDO | D7: Project Technical Specialist 1 | E7: 165 | G7: 2025-299 | I7: Medium Roast Coffee 200g | J7: 5 | K7: jar | L7: 950 | M7: =SUM(J7*L7) -> 4750 | N7: 850 | O7: =SUM(J7*N7) -> 4250 | P7: supplies for the project/RDET office-charged to Sustainable Tourism Project (Representation Expenses) | Q7: RDET-S & T | R7: September 11, 2025 | S7: September 16, 2025 | T7: September 17, 2025 | U7: October 1, 2025 | V7: October 2, 2025 | W7: Sophia Marie Store | X7: October 2, 2025 | Y7: 1005 | Z7: October 28, 2025 | AA7: complete | AB7: for payment-Acctg. | AC7: 07-02-2025-09-0320 | AD7: 3 RFQ's | AE7: 1323/10/6/2025
A8: 2025 | B8: September | C8: SYRA KARLA C. GORDO | D8: Project Technical Specialist 1 | E8: 165 | G8: 2025-299 | I8: Washed Sugar | J8: 4 | K8: kg | L8: 100 | M8: =SUM(J8*L8) -> 400 | N8: 130 | O8: =SUM(J8*N8) -> 520 | P8: supplies for the project/RDET office-charged to Sustainable Tourism Project (Representation Expenses) | Q8: RDET-S & T | R8: September 11, 2025 | S8: September 16, 2025 | T8: September 17, 2025 | U8: October 1, 2025 | V8: October 2, 2025 | W8: Sophia Marie Store | X8: October 2, 2025 | Y8: 1005 | Z8: October 28, 2025 | AA8: complete | AB8: for payment-Acctg. | AC8: 07-02-2025-09-0320
A9: 2025 | B9: September | C9: SYRA KARLA C. GORDO | D9: Project Technical Specialist 1 | E9: 165 | G9: 2025-299 | I9: Creamer 400g | J9: 5 | K9: pouch | L9: 185 | M9: =SUM(J9*L9) -> 925 | N9: 178 | O9: =SUM(J9*N9) -> 890 | P9: supplies for the project/RDET office-charged to Sustainable Tourism Project (Representation Expenses) | Q9: RDET-S & T | R9: September 11, 2025 | S9: September 16, 2025 | T9: September 17, 2025 | U9: October 1, 2025 | V9: October 2, 2025 | W9: Sophia Marie Store | X9: October 2, 2025 | Y9: 1005 | Z9: October 28, 2025 | AA9: complete | AB9: for payment-Acctg. | AC9: 07-02-2025-09-0320
A10: 2025 | B10: September | C10: SYRA KARLA C. GORDO | D10: Project Technical Specialist 1 | E10: 165 | G10: 2025-299 | I10: Concentrated Powdered Tea drink mix | J10: 2 | K10: doz | L10: 150 | M10: =SUM(J10*L10) -> 300 | N10: 288 | O10: =SUM(J10*N10) -> 576 | P10: supplies for the project/RDET office-charged to Sustainable Tourism Project (Representation Expenses) | Q10: RDET-S & T | R10: September 11, 2025 | S10: September 16, 2025 | T10: September 17, 2025 | U10: October 1, 2025 | V10: October 2, 2025 | W10: Sophia Marie Store | X10: October 2, 2025 | Y10: 1005 | Z10: October 28, 2025 | AA10: complete | AB10: for payment-Acctg. | AC10: 07-02-2025-09-0320
A11: 2025 | B11: September | C11: SHEILA H. YDEL | D11: Admin. Officer IV | E11: 101 | G11: 2025-300 | I11: Office Laptop, CPU: AMD Ryzen 7 7000 series, RAM; 16GB DORS, Graphics: AMD Radeon Graphics (Integrated), Storage 1TB SSD, Wireless; Wi-Fi 6E(802.11ax) (Dual Band) 1*1 + bluetooth 5.3 wireless card, Pheripherals; Keyboard and mouse combo, Operating System: Windows 11 | J11: 1 | K11: unit | L11: 72000 | M11: =SUM(J11*L11) -> 72000 | N11: 68500 | O11: =SUM(J11*N11) -> 68500 | P11: for General Services Office use | Q11: GSO | R11: September 18, 2025 | S11: September 25, 2025 | T11: September 26, 2025 | U11: October 3, 2025 | V11: March 31, 2026 | W11: M.G. Hubalde's General Merchandise | X11: April 6, 2026 | Y11: GAS20 | Z11: April 14, 2026 | AA11: complete | AB11: for payment-Acctg. | AC11: 06-101101-2025-09-00787 | AD11: 5 RFQ's + 1 blank | AE11: 13387-13388/11/18/2025
A12: 2025 | B12: September | C12: SHEILA H. YDEL | D12: Admin. Officer IV | G12: 2025-301 | I12: Supply,Delivery and Installation of Wooden Door with Wooden Jamb and Doorknob with Key, Overall Dimension: Height - 98.5 inches, Width - 42 inches, Upper Clear Tempered Glass; Height - 8 inches, Width - 38 inches, Middle Clear Glass Acrylic; Height - 15 inches, Width - 10 inches | J12: 6 | K12: pcs | L12: 20000 | M12: =SUM(J12*L12) -> 120000 | O12: =SUM(J12*N12) -> 0 | P12: replacement of doors in 2nd floor classrooms (Rm. 210,211, & 213) | Q12: GSO | Y12: GAS20 | AA12: FAILED | AB12: winning supplier cancel the project due to financial challenges | AD12: 3 RFQ's + 1 blank
A13: 2025 | B13: September | C13: MICHEL A. CABRERA | D13: Assistant Professor IV | G13: 2025-302 | I13: A3 Wi-Fi Duplex All-In-One Ink Tank Printer | J13: 1 | K13: pc | L13: 55000 | M13: =SUM(J13*L13) -> 55000 | O13: =SUM(J13*N13) -> 0 | P13: to be used for instruction and office supplies | Q13: ICT | Y13: GAS4 | AA13: FAILED | AB13: quotation exceeded the budget | AD13: 4 RFQ's + 1 blank
A14: 2025 | B14: September | C14: MICHEL A. CABRERA | D14: Assistant Professor IV | G14: 2025-302 | I14: 70-180mm f/2.8 Di III VC G2 Camera Lens (Sony E) - for A7RIII | J14: 1 | K14: pc | L14: 70000 | M14: =SUM(J14*L14) -> 70000 | O14: =SUM(J14*N14) -> 0 | P14: to be used for instruction and office supplies | Q14: ICT | Y14: GAS4
A15: 2025 | B15: September | C15: MICHEL A. CABRERA | D15: Assistant Professor IV | G15: 2025-302 | I15: Z-series Rechargeable Battery Pack NP-FZ100 - for A7RIII | J15: 1 | K15: pc | L15: 6000 | M15: =SUM(J15*L15) -> 6000 | O15: =SUM(J15*N15) -> 0 | P15: to be used for instruction and office supplies | Q15: ICT | Y15: GAS4
A16: 2025 | B16: September | C16: MICHEL A. CABRERA | D16: Assistant Professor IV | G16: 2025-302 | I16: Mini Gimbal Stabilizer | J16: 1 | K16: pc | L16: 15000 | M16: =SUM(J16*L16) -> 15000 | O16: =SUM(J16*N16) -> 0 | P16: to be used for instruction and office supplies | Q16: ICT | Y16: GAS4
A17: 2025 | B17: September | C17: MICHEL A. CABRERA | D17: Assistant Professor IV | G17: 2025-302 | I17: Cat6 UTP LAN Ethernet Cable 305 meters | J17: 1 | K17: box | L17: 10000 | M17: =SUM(J17*L17) -> 10000 | O17: =SUM(J17*N17) -> 0 | P17: to be used for instruction and office supplies | Q17: ICT | Y17: GAS4
A18: 2025 | B18: September | C18: MICHEL A. CABRERA | D18: Assistant Professor IV | G18: 2025-302 | I18: 100pcs set RJ45 Connector Network Cat5e/Cat6 | J18: 5 | K18: box | L18: 200 | M18: =SUM(J18*L18) -> 1000 | O18: =SUM(J18*N18) -> 0 | P18: to be used for instruction and office supplies | Q18: ICT | Y18: GAS4
A19: 2025 | B19: September | C19: MARVIN KEITH C. ALAVADO | D19: Information Systems Analyst II/ ITO Officer | E19: 165 | G19: 2025-303 | I19: Camera cleaning kit 47pcs set | J19: 1 | K19: set | L19: 939 | M19: =SUM(J19*L19) -> 939 | N19: 320 | O19: =SUM(J19*N19) -> 320 | P19: for Programs, Activities and Projects of IT Unit charged under PRE 2025 | Q19: ITU | R19: October 7, 2025 | S19: October 13, 2025 | T19: October 14, 2025 | U19: October 21, 2025 | V19: 74% | W19: YCA Office Supplies & Equipment Trading | Y19: GAS5 | AA19: inc. delivery | AB19: 0.74 | AC19: 07-02-2025-10-0368 | AD19: 5 RFQ's + 1 blank
A20: 2025 | B20: September | C20: MARVIN KEITH C. ALAVADO | D20: Information Systems Analyst II/ ITO Officer | E20: 165 | G20: 2025-303 | I20: Magnifying glass with 30x magnification repair lamp | J20: 1 | K20: unit | L20: 750 | M20: =SUM(J20*L20) -> 750 | N20: 495 | O20: =SUM(J20*N20) -> 495 | P20: for Programs, Activities and Projects of IT Unit charged under PRE 2025 | Q20: ITU | R20: October 7, 2025 | S20: October 13, 2025 | T20: October 14, 2025 | U20: October 21, 2025 | W20: YCA Office Supplies & Equipment Trading | Y20: GAS5 | AC20: 07-02-2025-10-0368
A21: 2025 | B21: September | C21: MARVIN KEITH C. ALAVADO | D21: Information Systems Analyst II/ ITO Officer | E21: 165 | G21: 2025-303 | I21: 4pcs/set Syringe with hose | J21: 3 | K21: set | L21: 172.5 | M21: =SUM(J21*L21) -> 517.5 | N21: 120 | O21: =SUM(J21*N21) -> 360 | P21: for Programs, Activities and Projects of IT Unit charged under PRE 2025 | Q21: ITU | R21: October 7, 2025 | S21: October 13, 2025 | T21: October 14, 2025 | U21: October 21, 2025 | W21: YCA Office Supplies & Equipment Trading | Y21: GAS5 | AC21: 07-02-2025-10-0368
A22: 2025 | B22: September | C22: MARVIN KEITH C. ALAVADO | D22: Information Systems Analyst II/ ITO Officer | E22: 165 | G22: 2025-303 | I22: 2.5"/3.5" SATA docking station | J22: 1 | K22: pc | L22: 6000 | M22: =SUM(J22*L22) -> 6000 | N22: 2000 | O22: =SUM(J22*N22) -> 2000 | P22: for Programs, Activities and Projects of IT Unit charged under PRE 2025 | Q22: ITU | R22: October 7, 2025 | S22: October 13, 2025 | T22: October 14, 2025 | U22: October 21, 2025 | W22: YCA Office Supplies & Equipment Trading | Y22: GAS5 | AC22: 07-02-2025-10-0368
A23: 2025 | B23: September | C23: MARVIN KEITH C. ALAVADO | D23: Information Systems Analyst II/ ITO Officer | E23: 165 | G23: 2025-303 | I23: M.2 enclosure (Dual Protocol) | J23: 1 | K23: pc | L23: 4050 | M23: =SUM(J23*L23) -> 4050 | N23: 1700 | O23: =SUM(J23*N23) -> 1700 | P23: for Programs, Activities and Projects of IT Unit charged under PRE 2025 | Q23: ITU | R23: October 7, 2025 | S23: October 13, 2025 | T23: October 14, 2025 | U23: October 21, 2025 | W23: YCA Office Supplies & Equipment Trading | Y23: GAS5 | AC23: 07-02-2025-10-0368
A24: 2025 | B24: September | C24: MARVIN KEITH C. ALAVADO | D24: Information Systems Analyst II/ ITO Officer | E24: 165 | G24: 2025-303 | I24: 100's/box Black nitril disposable gloves powder free (Medium) | J24: 1 | K24: box | L24: 396 | M24: =SUM(J24*L24) -> 396 | N24: 210 | O24: =SUM(J24*N24) -> 210 | P24: for Programs, Activities and Projects of IT Unit charged under PRE 2025 | Q24: ITU | R24: October 7, 2025 | S24: October 13, 2025 | T24: October 14, 2025 | U24: October 21, 2025 | W24: YCA Office Supplies & Equipment Trading | Y24: GAS5 | AC24: 07-02-2025-10-0368
A25: 2025 | B25: September | C25: MARVIN KEITH C. ALAVADO | D25: Information Systems Analyst II/ ITO Officer | E25: 165 | G25: 2025-303 | I25: Ultrasonic Cleaning Machine 0.8L | J25: 1 | K25: unit | L25: 5548.5 | M25: =SUM(J25*L25) -> 5548.5 | N25: 4500 | O25: =SUM(J25*N25) -> 4500 | P25: for Programs, Activities and Projects of IT Unit charged under PRE 2025 | Q25: ITU | R25: October 7, 2025 | S25: October 13, 2025 | T25: October 14, 2025 | U25: October 21, 2025 | W25: YCA Office Supplies & Equipment Trading | Y25: GAS5 | AC25: 07-02-2025-10-0368
A26: 2025 | B26: September | C26: MARVIN KEITH C. ALAVADO | D26: Information Systems Analyst II/ ITO Officer | E26: 165 | G26: 2025-303 | I26: Cleaning solution 1000ml | J26: 1 | K26: bottle | L26: 735 | M26: =SUM(J26*L26) -> 735 | N26: 650 | O26: =SUM(J26*N26) -> 650 | P26: for Programs, Activities and Projects of IT Unit charged under PRE 2025 | Q26: ITU | R26: October 7, 2025 | S26: October 13, 2025 | T26: October 14, 2025 | U26: October 21, 2025 | W26: YCA Office Supplies & Equipment Trading | Y26: GAS5 | AC26: 07-02-2025-10-0368
A27: 2025 | B27: September | C27: MARVIN KEITH C. ALAVADO | D27: Information Systems Analyst II/ ITO Officer | E27: 165 | G27: 2025-303 | I27: Tool belt (6 slots, 1 pocket) | J27: 3 | K27: pcs | L27: 591 | M27: =SUM(J27*L27) -> 1773 | N27: 200 | O27: =SUM(J27*N27) -> 600 | P27: for Programs, Activities and Projects of IT Unit charged under PRE 2025 | Q27: ITU | R27: October 7, 2025 | S27: October 13, 2025 | T27: October 14, 2025 | U27: October 21, 2025 | W27: YCA Office Supplies & Equipment Trading | Y27: GAS5 | AC27: 07-02-2025-10-0368
A28: 2025 | B28: September | C28: MARVIN KEITH C. ALAVADO | D28: Information Systems Analyst II/ ITO Officer | E28: 165 | G28: 2025-303 | I28: 2000w Electric heat gun with Nozzle (w/ rotating back for precise temperature control) | J28: 1 | K28: unit | L28: 4185 | M28: =SUM(J28*L28) -> 4185 | N28: 3500 | O28: =SUM(J28*N28) -> 3500 | P28: for Programs, Activities and Projects of IT Unit charged under PRE 2025 | Q28: ITU | R28: October 7, 2025 | S28: October 13, 2025 | T28: October 14, 2025 | U28: October 21, 2025 | W28: YCA Office Supplies & Equipment Trading | Y28: GAS5 | AC28: 07-02-2025-10-0368
A29: 2025 | B29: September | C29: MARVIN KEITH C. ALAVADO | D29: Information Systems Analyst II/ ITO Officer | E29: 165 | G29: 2025-303 | I29: Silicone repair work mat (60x35 cm) | J29: 2 | K29: pcs | L29: 2340 | M29: =SUM(J29*L29) -> 4680 | N29: 1300 | O29: =SUM(J29*N29) -> 2600 | P29: for Programs, Activities and Projects of IT Unit charged under PRE 2025 | Q29: ITU | R29: October 7, 2025 | S29: October 13, 2025 | T29: October 14, 2025 | U29: October 21, 2025 | W29: YCA Office Supplies & Equipment Trading | Y29: GAS5 | AC29: 07-02-2025-10-0368
A30: 2025 | B30: September | C30: MARVIN KEITH C. ALAVADO | D30: Information Systems Analyst II/ ITO Officer | E30: 165 | G30: 2025-303 | I30: High performance thermal paste for CPU and GPU with spreader (20g) | J30: 1 | K30: tube | L30: 900 | M30: =SUM(J30*L30) -> 900 | N30: 1800 | O30: =SUM(J30*N30) -> 1800 | P30: for Programs, Activities and Projects of IT Unit charged under PRE 2025 | Q30: ITU | R30: October 7, 2025 | S30: October 13, 2025 | T30: October 14, 2025 | U30: October 21, 2025 | W30: YCA Office Supplies & Equipment Trading | Y30: GAS5 | AC30: 07-02-2025-10-0368
A31: 2025 | B31: September | C31: MARVIN KEITH C. ALAVADO | D31: Information Systems Analyst II/ ITO Officer | E31: 165 | G31: 2025-303 | I31: RJ45 Crimping tool | J31: 1 | K31: pc | L31: 553.5 | M31: =SUM(J31*L31) -> 553.5 | N31: 300 | O31: =SUM(J31*N31) -> 300 | P31: for Programs, Activities and Projects of IT Unit charged under PRE 2025 | Q31: ITU | R31: October 7, 2025 | S31: October 13, 2025 | T31: October 14, 2025 | U31: October 21, 2025 | W31: YCA Office Supplies & Equipment Trading | Y31: GAS5 | AC31: 07-02-2025-10-0368
... A52: 2025 | B52: September | C52: MARVIN KEITH C. ALAVADO | D52: Information Systems Analyst II/ ITO Officer | E52: 165 | G52: 2025-303 | I52: Foldable garden saw (18m blade) | J52: 1 | K52: pc | L52: 585 | M52: =SUM(J52*L52) -> 585 | N52: 380 | O52: =SUM(J52*N52) -> 380 | P52: for Programs, Activities and Projects of IT Unit charged under PRE 2025 | Q52: ITU | R52: October 7, 2025 | S52: October 13, 2025 | T52: October 14, 2025 | U52: October 21, 2025 | W52: YCA Office Supplies & Equipment Trading | Y52: GAS5 | AC52: 07-02-2025-10-0368
A53: 2025 | B53: September | C53: MARVIN KEITH C. ALAVADO | D53: Information Systems Analyst II/ ITO Officer | E53: 165 | G53: 2025-303 | H53: 35 | I53: Standard wall mount for Starlink Gen 3 | J53: 1 | K53: pc | L53: 8490 | M53: =SUM(J53*L53) -> 8490 | N53: 16000 | O53: =SUM(J53*N53) -> 16000 | P53: for Programs, Activities and Projects of IT Unit charged under PRE 2025 | Q53: ITU | R53: October 7, 2025 | S53: October 13, 2025 | T53: October 14, 2025 | U53: October 21, 2025 | W53: YCA Office Supplies & Equipment Trading | Y53: GAS5 | AC53: 07-02-2025-10-0368
A54: 2025 | B54: September | C54: GLORIA N. CABIZON | D54: ITD Chairperson | G54: 2025-304 | I54: Acrylic Based Paint - Red | J54: 1 | K54: liter | L54: 400 | M54: =SUM(J54*L54) -> 400 | O54: =SUM(J54*N54) -> 0 | P54: materials for ASEAN program (ASEAN mural wall painting) | Q54: ITD | Y54: Acad5 | AA54: CANCELLED | AB54: Re-PR
A55: 2025 | B55: September | C55: GLORIA N. CABIZON | D55: ITD Chairperson | G55: 2025-304 | I55: Acrylic Based Paint - Blue | J55: 1 | K55: liter | L55: 400 | M55: =SUM(J55*L55) -> 400 | O55: =SUM(J55*N55) -> 0 | P55: materials for ASEAN program (ASEAN mural wall painting) | Q55: ITD | Y55: Acad5
A56: 2025 | B56: September | C56: GLORIA N. CABIZON | D56: ITD Chairperson | G56: 2025-304 | I56: Acrylic Based Paint - Yellow | J56: 1 | K56: liter | L56: 400 | M56: =SUM(J56*L56) -> 400 | O56: =SUM(J56*N56) -> 0 | P56: materials for ASEAN program (ASEAN mural wall painting) | Q56: ITD | Y56: Acad5
A57: 2025 | B57: September | C57: GLORIA N. CABIZON | D57: ITD Chairperson | G57: 2025-304 | I57: Acrylic Based Paint - Black | J57: 1 | K57: liter | L57: 400 | M57: =SUM(J57*L57) -> 400 | O57: =SUM(J57*N57) -> 0 | P57: materials for ASEAN program (ASEAN mural wall painting) | Q57: ITD | Y57: Acad5
A58: 2025 | B58: September | C58: GLORIA N. CABIZON | D58: ITD Chairperson | G58: 2025-304 | I58: Acrylic Based Paint - White | J58: 1 | K58: pail | L58: 3200 | M58: =SUM(J58*L58) -> 3200 | O58: =SUM(J58*N58) -> 0 | P58: materials for ASEAN program (ASEAN mural wall painting) | Q58: ITD | Y58: Acad5
A59: 2025 | B59: September | C59: GLORIA N. CABIZON | D59: ITD Chairperson | G59: 2025-304 | I59: Artist Paint Brush | J59: 1 | K59: set | L59: 1200 | M59: =SUM(J59*L59) -> 1200 | O59: =SUM(J59*N59) -> 0 | P59: materials for ASEAN program (ASEAN mural wall painting) | Q59: ITD | Y59: Acad5
A60: 2025 | B60: September | C60: GLORIA N. CABIZON | D60: ITD Chairperson | G60: 2025-304 | I60: Paint Roller (4 inches) | J60: 4 | K60: pcs | L60: 200 | M60: =SUM(J60*L60) -> 800 | O60: =SUM(J60*N60) -> 0 | P60: materials for ASEAN program (ASEAN mural wall painting) | Q60: ITD | Y60: Acad5
...

Sheet PR
A3: Republic of the Philippines
A4: BATANES STATE COLLEGE
A5: Basco, Batanes
A7: PURCHASE REQUEST
D9: PR No. | E9: =DATA!G204 -> 2025-343 | F9: Date
A10: Department: | D10: SAI No.: | E10: .
A11: Section: | B11: =DATA!Y204 -> SS09 | D11: OBR#
A12: Ref. No.: | B12: 2509-SS09-343
A14: Qty | B14: Unit of Issue | D14: Item Description | F14: Stock No. | G14: Estimated
G15: Unit Cost | H15: Total Cost
A16: =DATA!J204 -> 0 | B16: =DATA!K204 -> 0 | D16: =DATA!I204 -> DAY 1-Opening Day | G16: =DATA!L204 -> 0 | H16: =SUM(A16*G16) -> 0
A17: =DATA!J205 -> 12 | B17: =DATA!K205 -> kls | D17: =DATA!I205 -> Chicken (whole) | G17: =DATA!L205 -> 280 | H17: =SUM(A17*G17) -> 3360
A18: =DATA!J206 -> 2 | B18: =DATA!K206 -> bottle | D18: =DATA!I206 -> Vinegar (1 Ltr.) | G18: =DATA!L206 -> 90 | H18: =SUM(A18*G18) -> 180
A19: =DATA!J207 -> 1 | B19: =DATA!K207 -> bottle | D19: =DATA!I207 -> Soy Sauce (1Ltr) | G19: =DATA!L207 -> 90 | H19: =SUM(A19*G19) -> 90
A20: =DATA!J208 -> 1 | B20: =DATA!K208 -> pack | D20: =DATA!I208 -> Juice (Blue Lemonade) | G20: =DATA!L208 -> 200 | H20: =SUM(A20*G20) -> 200
A21: =DATA!J209 -> 0 | B21: =DATA!K209 -> 0 | D21: =DATA!I209 -> DAY 2- Activity Day | G21: =DATA!L209 -> 0 | H21: =SUM(A21*G21) -> 0
A22: =DATA!J210 -> 10 | B22: =DATA!K210 -> kls | D22: =DATA!I210 -> Pork & Pork Liver | G22: =DATA!L210 -> 380 | H22: =SUM(A22*G22) -> 3800
A23: =DATA!J211 -> 1 | B23: =DATA!K211 -> kls | D23: =DATA!I211 -> Carrots | G23: =DATA!L211 -> 320 | H23: =SUM(A23*G23) -> 320
A24: =DATA!J212 -> 1 | B24: =DATA!K212 -> pack | D24: =DATA!I212 -> Juice (Blue Lemonade) | G24: =DATA!L212 -> 200 | H24: =SUM(A24*G24) -> 200
A25: =DATA!J213 -> 2 | B25: =DATA!K213 -> pcs | D25: =DATA!I213 -> Yellow Ginger (Hama-100g) | G25: =DATA!L213 -> 150 | H25: =SUM(A25*G25) -> 300
A26: =DATA!J214 -> 50 | B26: =DATA!K214 -> pcs | D26: =DATA!I214 -> Coffee (Twin Pack) | G26: =DATA!L214 -> 20 | H26: =SUM(A26*G26) -> 1000
A27: =DATA!J215 -> 10 | B27: =DATA!K215 -> ballots | D27: =DATA!I215 -> Assorted Biscuits | G27: =DATA!L215 -> 100 | H27: =SUM(A27*G27) -> 1000
H28: =SUM(A28*G28) -> 0
H29: =SUM(A29*G29) -> 0
H30: =SUM(A30*G30) -> 0
H31: =SUM(A31*G31) -> 0
H32: =SUM(A32*G32) -> 0
H33: =SUM(A33*G33) -> 0
H34: =SUM(A34*G34) -> 0
H35: =SUM(A35*G35) -> 0
H36: =SUM(A36*G36) -> 0
H37: =SUM(A37*G37) -> 0
H38: =SUM(A38*G38) -> 0
H39: =SUM(A39*G39) -> 0
... H50: =SUM(A50*G50) -> 0
A51: =DATA!J260 -> 0 | B51: =DATA!K54 -> liter | D51: =DATA!I54 -> Acrylic Based Paint - Red | G51: =DATA!L260 -> 0 | H51: =SUM(A51*G51) -> 0
A52: =DATA!J261 -> 0 | B52: =DATA!K55 -> liter | D52: =DATA!I55 -> Acrylic Based Paint - Blue | G52: =DATA!L261 -> 0 | H52: =SUM(A52*G52) -> 0
A53: =DATA!J262 -> 0 | B53: =DATA!K56 -> liter | D53: =DATA!I56 -> Acrylic Based Paint - Yellow | G53: =DATA!L262 -> 0 | H53: =SUM(A53*G53) -> 0
A54: =DATA!J263 -> 0 | B54: =DATA!K57 -> liter | D54: =DATA!I57 -> Acrylic Based Paint - Black | G54: =DATA!L263 -> 0 | H54: =SUM(A54*G54) -> 0
A55: =DATA!J264 -> 0 | B55: =DATA!K58 -> pail | D55: =DATA!I58 -> Acrylic Based Paint - White | G55: =DATA!L264 -> 0 | H55: =SUM(A55*G55) -> 0
...

Sheet ResoSVP (2)
A6: BAC Resolution Recommending Alternative Mode of Procurement under Small Value Procurement
B7: BAC Resolution No. | D7: =PR!B12 -> 2509-SS09-343
A9: WHEREAS, Section 48 Rule XVI of the Revised Implementing Rules and Regulations of RA 9184 allows Alternative Mode of Procurement subject to prior approval of the HOPE thru Annual Procurement Plan (APP) and only to promote economy and efficiency;
A10: WHEREAS, Section 53.9 allows Small Value Procurement provided that the procurement does not fall under shopping in Section 52 of this IRR and the amount involved does not exceed the thresholds prescribed in Annex "H" of this IRR;
A11: WHEREAS, Appendix 18, Section 3.e on the Guidelines for Shopping and Small Value Procurement provides an Abstract of Quotations shall be prepared setting forth the names of those who responded to the RFQ's right after the deadline for submission except for shopping under Section 52.1(b), where at least three (3) price quotations (RFQ) must be obtained;
A12: WHEREAS, Annex "H" of the Consolidated Guidelines for the Alternative Methods of Procurement prescribed under Section V, Paragraph D.8.b.ii that the BAC shall prepare and send the RFQs/RFPs to at least three (3) suppliers, contractors or consultants of known qualifications where receipt of at least one (1) quotations is sufficient to proceed with the evaluation thererof;
A13: WHEREAS, Purchase Request No. | D13: =PR!E9 -> 2025-343 | E13: involves the procurement of
A14: Health Insurance (Age Range: 20-65 years old) Covers the following: Accidental Medical Reimbursement,Daily Hos[ital Allowance (Max 60 days),Accidental Death,Disablement and Disemberment,Unprovoked Murder & Assault, Accidental Burial Assistance--for medical insurance of the Bread & Pastry Production participants for (Batch 1, TWSP)
A15: with the approved budget of | D15: =PR!H75 -> 10450
A16: WHEREAS, the default mode of evaluation shall be on a lot basis which means that the determination of the single/lowest calculated and responsive bid (S/LCRB) is the total amount of offered unit price multiply by the required quantity;
A18: NOW THEREFORE, we, the members of the Bids and Awards Committee hereby RESOLVE as it is hereby RESOLVED to recommend to the College President to adopt Alternative Mode of Procurement under Small Value Procurement for the said transaction;
A20: RESOLVED FINALLY, at the Batanes State College, this
A21: Recommending Approval:
A24: RHOUPHELINE AYA A. CADIZ | C24: FORTUNATO PHILIP A. CABUGAO | E24: EMILYN D. ALUETA
A25: BAC Member | C25: BAC Member | E25: BAC Member
A28: =PR!B80 -> ELEIN T. ESPERANZA | C28: PHILIP ULYSSES T. CASTILLO | E28: DOREEN C. CASTILLO
A29: End-User/Provisional Member | C29: BAC Vice Chairperson | E29: BAC Chairperson
A30: BRYAN H. CIELO
A31: DELMA G. MALUPA-ABAD
A32: EDWIN F.MACABALLUG, Ph.D.
A33: LIEZL P. DELA CRUZ
A34: RODERICK Y. ABAD
A35: VILMA D. BACCAY
A36: ESTEBAN C. BADAJOS
A37: LEOBERT L. BANZALI
A38: MIAH DAPHNIE B. BUENAFE
A39: GLORIA N. CABIZON
A40: FORTUNATO PHILIP A. CABUGAO
A41: RICARDO Q. CABUGAO, JR.
... A83: LEONARDO CABRERA

Sheet AResoSVP (2)
A6: Approval of BAC Resolution Recommending Alternative Mode of Procurement under Small Value Procurement
B7: BAC Resolution No. | D7: =PR!B12 -> 2509-SS09-343
A9: WHEREAS, Section 48 Rule XVI of the Revised Implementing Rules and Regulations of RA 9184 allows Alternative Mode of Procurement subject to prior approval of the HOPE thru Annual Procurement Plan (APP) and only to promote economy and efficiency;
A10: WHEREAS, Section 53.9 allows Small Value Procurement provided that the procurement does not fall under shopping in Section 52 of this IRR and the amount involved does not exceed the thresholds prescribed in Annex "H" of this IRR;
A11: WHEREAS, Appendix 18, Section 3.e on the Guidelines for Shopping and Small Value Procurement provides an Abstract of Quotations shall be prepared setting forth the names of those who responded to the RFQ's right after the deadline for submission except for shopping under Section 52.1(b), where at least three (3) price quotations (RFQ) must be obtained;
A12: WHEREAS, Annex "H" of the Consolidated Guidelines for the Alternative Methods of Procurement prescribed under Section V, Paragraph D.8.b.ii that the BAC shall prepare and send the RFQs/RFPs to at least three (3) suppliers, contractors or consultants of known qualifications where receipt of at least one (1) quotations is sufficient to proceed with the evaluation thererof;
A13: WHEREAS, Purchase Request No. | D13: =PR!E9 -> 2025-343 | E13: involves the procurement of
A14: Health Insurance (Age Range: 20-65 years old) Covers the following: Accidental Medical Reimbursement,Daily Hos[ital Allowance (Max 60 days),Accidental Death,Disablement and Disemberment,Unprovoked Murder & Assault, Accidental Burial Assistance--for medical insurance of the Bread & Pastry Production participants for (Batch 1, TWSP) | H14: Items:
A15: with the approved budget of | D15: =PR!H75 -> 10450
A16: WHEREAS, the default mode of evaluation shall be on a lot basis which means that the determination of the single/lowest calculated and responsive bid (S/LCRB) is the total amount of offered unit price multiply by the required quantity;
A17: NOW THEREFORE, I,DR.DJOVI R. DURANTE, Head of the Procuring Entity (HOPE) by virtue of the authority vested in me by the Board of Trustees of this Institution and after taking into consideration the merits and legal bases of the recommendation of the members of the Bids and Awards Committee (BAC) do hereby APPROVE the foregoing recommendation and adoption of Alternative Mode of Procurement under Small Value Procurement;
A19: APPROVED FINALLY, at the Batanes State College, this | F19: ___________________
B25: DJOVI REGALA DURANTE,DPA
B26: SUC President I

Sheet RFQ_ (2)
E6: Date:
A7: REQUEST FOR PRICE QUOTATION
A8: Biang's Catering Services
A9: Please give us your best and final price offer for the item/s listed below, have this signed and submit this by you or by your duly authorized representative WITHIN SEVEN (7) CALENDAR DAYS upon receipt to Procurement Section, Batanes State College.
A11: NOTE: | B11: 1. THE DEFAULT MODE OF PRICE EVALUATION SHALL BE ON A LOT BASIS, OTHERWISE PER ITEMS EVALUATION SHALL BE USED IF THERE WILL BE LACKING ITEMS IN ALL RFQ's AND SUBJECT TO END-USER APPROVAL., (Clause 15.2, Section I, Instruction to Bidders of the Philippine Bidding Documents for goods and infrastructure projects)
B12: 2. DELIVERY PERIOD: Thirty (30) calendar days.
B13: 3. Submission of price quotation shall be in sealed envelope.
B14: 4. THE APPROVED BUDGET FOR THIS PROCUREMENT IS
B15: =PR!H75 -> 10450 | D15: (GPPB Resolution No. 09-2009)
B16: 5. PURSUANT TO ANNEX "H", APPENDIX A, SECTION II, SUBMISSION OF APPLICABLE DOCUMENTS (e.g.MAYORS/BUSINESS PERMIT, PROFESSIONAL LICENSE/CURRICULUM VITAE (CONSULTING SEERVICES),PHILGEPS CERT. NO., PCAB LICENSE (INFRA), INCOME/BUSINESS TAX RETURN,OMNIBUS SWORN STATEMENT SHALL BE REQUIRED BEFORE THE ISSUANCE OF NOA OR PRIOR TO PAYMENT.
B17: 6. In case the item is not availble, please write "None".
A18: Item # | B18: Qty. | C18: Unit | D18: PARTICULAR | E18: Unit Price | F18: Total
A19: 001 | B19: =PR!A16 -> 0 | C19: =PR!B16 -> 0 | D19: =PR!D16 -> DAY 1-Opening Day
A20: 002
A21: 003
A22: 004
A23: 005
A24: 006
A25: 007
A26: 008
A27: 009
A28: 010
A29: 011
A30: 012
A31: 013
... A33: 015
A34: 016 | B34: =[1]PR!A31 -> 0 | C34: =[1]PR!B31 -> 0 | D34: =[1]PR!D31 -> 0
A35: 017 | B35: =[1]PR!A32 -> 0 | C35: =[1]PR!B32 -> 0 | D35: =[1]PR!D32 -> 0
A36: 018 | B36: =[1]PR!A33 -> 0 | C36: =[1]PR!B33 -> 0 | D36: =[1]PR!D33 -> 0
A37: 019 | B37: =[1]PR!A34 -> 0 | C37: =[1]PR!B34 -> 0 | D37: =[1]PR!D34 -> 0
A38: 020 | B38: =[1]PR!A35 -> 0 | C38: =[1]PR!B35 -> 0 | D38: =[1]PR!D35 -> 0
A39: 021 | B39: =[1]PR!A36 -> 0 | C39: =[1]PR!B36 -> 0 | D39: =[1]PR!D36 -> 0
A40: 022 | B40: =[1]PR!A37 -> 0 | C40: =[1]PR!B37 -> 0 | D40: =[1]PR!D37 -> 0
A41: 023 | B41: =[1]PR!A38 -> 0 | C41: =[1]PR!B38 -> 0 | D41: =[1]PR!D38 -> 0
A42: 024 | B42: =[1]PR!A39 -> 0 | C42: =[1]PR!B39 -> 0 | D42: =[1]PR!D39 -> 0
A43: 025 | B43: =[1]PR!A40 -> 0 | C43: =[1]PR!B40 -> 0 | D43: =[1]PR!D40 -> 0
A44: 026 | B44: =[1]PR!A41 -> 0 | C44: =[1]PR!B41 -> 0 | D44: =[1]PR!D41 -> 0
A45: 027 | B45: =[1]PR!A42 -> 0 | C45: =[1]PR!B42 -> 0 | D45: =[1]PR!D42 -> 0
... A57: 039 | B57: =[1]PR!A54 -> 0 | C57: =[1]PR!B54 -> 0 | D57: =[1]PR!D54 -> 0
A58: 041 | B58: =[2]PR!A55 -> 2 | C58: =[3]PR!B56 -> meter | D58: =[1]PR!D55 -> Single Face P4 HD Outdoor LED Screen (rear maintenance, Full Set Up including controller (Novastar) & receiving card (Novastar) warranty, after sales support & training controller (Novastar) & receiving card (Novastar) warranty, after sales support & training size: 2.88M x 2.88M (9 panels) screen resolution: 720 pixels (W) x 720 pixels (H) Type, movable frame Accessories,replacement module, replacement power supply, replacement receiving card power cable, signal cable
...

Sheet RFQ-Travel)
A1: Republic of the Philippines
A2: BATANES STATE COLLEGE
A3: Basco, Batanes
E4: Date:
A5: REQUEST FOR PRICE QUOTATION
B6: MOJR Construction Trading & General Services, Ltd, Co. | C6: MOJR Construction Trading & General Services, Ltd, Co. | D6: MOJR Construction Trading & General Services, Ltd, Co.
A7: Please give us your best and final price offer for the item/s listed below, have this signed and submit this by you or by your duly authorized representative WITHIN SEVEN (7) CALENDAR DAYS upon receipt to Procurement Section, Batanes State College.
A9: NOTE: | B9: 1. THE DEFAULT MODE OF PRICE EVALUATION SHALL BE ON A LOT BASIS, OTHERWISE PER ITEMS EVALUATION SHALL BE USED IF THERE WILL BE LACKING ITEMS IN ALL RFQ's AND SUBJECT TO END-USER APPROVAL., (Clause 15.2, Section I, Instruction to Bidders of the Philippine Bidding Documents for goods and infrastructure projects)
B10: 2. DELIVERY PERIOD: Thirty (30) calendar days.
B11: 3. Submission of price quotation shall be in sealed envelope.
B12: 4. THE APPROVED BUDGET FOR THIS PROCUREMENT IS
D13: (GPPB Resolution No. 09-2009)
B14: 5. PURSUANT TO ANNEX "H", APPENDIX A, SECTION II, SUBMISSION OF APPLICABLE DOCUMENTS (e.g.MAYORS/BUSINESS PERMIT, PROFESSIONAL LICENSE/CURRICULUM VITAE (CONSULTING SEERVICES),PHILGEPS CERT. NO., PCAB LICENSE (INFRA), INCOME/BUSINESS TAX RETURN,OMNIBUS SWORN STATEMENT SHALL BE REQUIRED BEFORE THE ISSUANCE OF NOA OR PRIOR TO PAYMENT.
B15: 6. In case the item is not availble, please write "None".
A16: Item # | B16: Qty. | C16: Unit | D16: PARTICULAR | E16: Unit Price | F16: Total
A17: 001 | B17: 1 | C17: pax | D17: Plane Ticket-Basco to Manila (Sept. 6, 2023)
A18: 002 | B18: 1 | C18: pax | D18: Plane Ticket-Manila to Basco (Sept. 13, 2023)
A19: 003
A20: 004
A21: 005
A22: 006
A23: 007
A24: 008
A25: 009
A26: 010
A27: 011
A28: 012
A29: 013
A30: 014
... A33: 017
A34: 018 | J34: graphite pencil 12b
A35: 019 | J35: graphite pencil 8b
A36: 020 | J36: graphite pencil 6b
A37: 021 | J37: graphite pencil 4b
A38: 022 | J38: graphite pencil 2b
A39: 023 | J39: graphite pencil HB
A40: 024
A41: 025 | B41: =PR!#REF! -> #REF! | C41: =PR!#REF! -> #REF! | D41: =PR!#REF! -> #REF!
A42: 026 | B42: =PR!#REF! -> #REF! | C42: =PR!#REF! -> #REF! | D42: =PR!#REF! -> #REF!
A43: 027 | B43: =PR!#REF! -> #REF! | C43: =PR!#REF! -> #REF! | D43: =PR!#REF! -> #REF!
...

Sheet AckReceipt
A1: Acknowledgement for Request for Quotation
A2: RIS# | B2: =PR!B12 -> 2509-SS09-343
A3: No. | B3: Supplier | F3: Received by: | G3: Date & Time:
B4: JPM Gen. Mdse. & Hardware
B5: Thine-line Trading
B6: J-Tech Trading & Services
B7: MDAC Trading & Compuserve
B8: FVA Gen Mdse & Construction Supply
B10: GDP Trading
B11: EA Amboy Gen Mdse
B12: L & R's Hontomin Gen Mdse
B13: Davocol's Gen. Mdse.
B14: RCJ Hardware & Gen Mdse
B15: Fitero's Gen Mdse & Electronic Supply
B16: Lar & San's Store
... B18: Wilmerson Gen Mdse
B19: FMG Trading & Construction Supply | C19: q
B20: MG Hubalde Gen Mdse
B21: Basco Cable TV Services, Inc.
B22: Berlen's Store
B23: Melad's Gen. Mdse
B24: R. A. Electronics
B25: RJ General Merchandise
B26: Batanes Multi-Purpose Cooperative, Inc.
B27: Romy & Ava's Store
B28: J-nell's Gen Mdse
B29: Impression Digital Printing Solutions
B30: Golden Press
B31: Tawsen's Agri-Venture & Souvenirs
... B60: Sophia Marie Store
A61: 1 | B61: Biang's Catering Services
A62: 2 | B62: AZ Blue Box Café
A63: 3 | B63: Doque's Congie Hauz café
A64: 4
A65: 5 | J65: zz
A66: 6
A67: 7
A68: NOTE: | B68: 1. MODE OF PRICE EVALUATION SHALL BE ON A LOT BASIS, OTHERWISE PER ITEMS EVALUATION SHALL BE USED IF THERE WILL BE LACKING ITEMS IN ALL RFQ'S AND THE END-USER AGREED, . (Clause 15.2, Section II, Instructions to Bidders of the Philippine Bidding Documents for goods and infrastructure projects)
B69: 2. DELIVERY PERIOD: Thirty (30) calendar days.
B70: 3. WARRANTY SHALL BE FOR A PERIOD OF SIX (6) MONTHS FOR SUPPLIES AND MATERIALS, ONE (1) YEAR FOR EQUIPMENT, FROM THE DATE OF ACCEPTANCE BY THE PROCURING ENTITY.
...

Sheet Abstract  (2)
A2: ABSTRACT OF QUOTATION
B4: (x) Furnishing/delivery of supplies, and materials or equipment | G4: Bids opened at Basco, Batanes
B5: ( x ) Furnishing Labor, services, etc. | I5: 45910
B6: ( ) Rental or use of transportation facilities equipment, quarters, rooms, lot or space, etc.
B8: To be furnished at the | D8: BATANES STATE COLLEGE
D9: (State place or site of Office or project where articles or services be furnished or returned)
A11: NAME OF ARTICLES OR SERVICES TO BE FURNISHED, RENDERED OR FACILITIES TO BE RENTED
F14: JPM Gen. Mdse. & Hardware
F15: Thine-line Trading
F16: J-Tech Trading & Services
F17: Mulong Ydel
F18: MDAC Trading & Compuserve
F19: FVA Gen Mdse & Construction Supply
F20: MKM Hardware
F21: GDP Trading
F22: EA Amboy Gen Mdse
F23: L & R's Hontomin Gen Mdse
F24: Davocol's Gen. Mdse.
F25: RCJ Hardware & Gen Mdse
... F86: Valiente Food Producer
F87: =DATA!W6 -> Doque's Congie Hauz | G87: Biang's Catering Services | H87: AZ Blue Box Café
A89: =PR!D16 -> DAY 1-Opening Day | F89: =DATA!O6 -> 21000 | G89: not available | H89: none
A103: =PR!D30 -> 0 | F103: =DATA!O219 -> 3500 | G103: 5200 | H103: 7600 | I103: none | J103: none
A104: =PR!D31 -> 0 | F104: =DATA!O220 -> 200 | G104: 600 | H104: 960 | I104: none | J104: none
A105: =PR!D32 -> 0 | B105: Bond paper, A4 size | C105: Bond paper, A4 size | D105: Bond paper, A4 size | E105: Bond paper, A4 size | F105: =DATA!O221 -> 900 | G105: 4800 | H105: 5960 | I105: none | J105: none
A106: =PR!D33 -> 0 | B106: Bond paper, A4 size | C106: Bond paper, A4 size | D106: Bond paper, A4 size | E106: Bond paper, A4 size | F106: =DATA!O222 -> 1500 | G106: 4400 | H106: 3960 | I106: none | J106: none
A107: =PR!D34 -> 0 | B107: Bond paper, A4 size | C107: Bond paper, A4 size | D107: Bond paper, A4 size | E107: Bond paper, A4 size | F107: =DATA!O223 -> 800 | G107: 11500 | H107: 6800 | I107: none | J107: none
A108: =PR!D35 -> 0 | B108: Bond paper, A4 size | C108: Bond paper, A4 size | D108: Bond paper, A4 size | E108: Bond paper, A4 size | F108: =DATA!O224 -> 1800 | G108: 8400 | H108: 13480 | I108: none | J108: none
A109: =PR!D36 -> 0 | B109: Bond paper, A4 size | C109: Bond paper, A4 size | D109: Bond paper, A4 size | E109: Bond paper, A4 size | F109: =DATA!O225 -> 500 | G109: 11000 | H109: 17600 | I109: none | J109: none
A110: =PR!D37 -> 0 | B110: Bond paper, A4 size | C110: Bond paper, A4 size | D110: Bond paper, A4 size | E110: Bond paper, A4 size | F110: =DATA!O226 -> 315 | G110: 100 | H110: 1360 | I110: none | J110: none
A111: =PR!D38 -> 0 | B111: Bond paper, A4 size | C111: Bond paper, A4 size | D111: Bond paper, A4 size | E111: Bond paper, A4 size | F111: =DATA!O227 -> 330 | G111: 5600 | H111: 5800 | I111: none | J111: none
A112: =PR!D39 -> 0 | B112: Bond paper, A4 size | C112: Bond paper, A4 size | D112: Bond paper, A4 size | E112: Bond paper, A4 size | F112: =DATA!O228 -> 6600 | G112: 45600 | H112: 35880 | I112: none | J112: none
A113: =PR!D40 -> 0 | B113: Bond paper, A4 size | C113: Bond paper, A4 size | D113: Bond paper, A4 size | E113: Bond paper, A4 size | F113: =DATA!O229 -> 1300 | G113: 18000 | H113: 14800 | I113: none | J113: none
A114: =PR!D41 -> 0 | B114: Bond paper, A4 size | C114: Bond paper, A4 size | D114: Bond paper, A4 size | E114: Bond paper, A4 size | F114: =DATA!O230 -> 150 | G114: 3200 | H114: 5600 | I114: none | J114: none
A115: =PR!D42 -> 0 | B115: Bond paper, A4 size | C115: Bond paper, A4 size | D115: Bond paper, A4 size | E115: Bond paper, A4 size | F115: =DATA!O231 -> 110 | G115: 7500 | H115: 3240 | I115: none | J115: none
A116: =PR!D43 -> 0 | B116: Bond paper, A4 size | C116: Bond paper, A4 size | D116: Bond paper, A4 size | E116: Bond paper, A4 size | F116: =DATA!O232 -> 275 | G116: 1200 | H116: 2970 | I116: none | J116: none
... A123: =PR!D50 -> 0 | B123: Bond paper, A4 size | C123: Bond paper, A4 size | D123: Bond paper, A4 size | E123: Bond paper, A4 size | F123: =DATA!O239 -> 225 | G123: 5200 | H123: 8800 | I123: none | J123: none
A124: =PR!D51 -> Acrylic Based Paint - Red | B124: Bond paper, A4 size | C124: Bond paper, A4 size | D124: Bond paper, A4 size | E124: Bond paper, A4 size | F124: =DATA!O240 -> 275 | G124: none | H124: none
A125: =PR!D52 -> Acrylic Based Paint - Blue | B125: Bond paper, A4 size | C125: Bond paper, A4 size | D125: Bond paper, A4 size | E125: Bond paper, A4 size | F125: =DATA!O241 -> 250 | G125: none | H125: none
A126: =PR!D53 -> Acrylic Based Paint - Yellow | B126: Bond paper, A4 size | C126: Bond paper, A4 size | D126: Bond paper, A4 size | E126: Bond paper, A4 size | F126: =DATA!O242 -> 180 | G126: none | H126: none
...

Sheet AOQ Failed
A2: ABSTRACT OF QUOTATION
B4: (x) Furnishing/delivery of supplies, and materials or equipment | G4: Bids opened at Basco, Batanes
B5: ( x ) Furnishing Labor, services, etc. | I5: =NOW() -> 46128.641
B6: ( ) Rental or use of transportation facilities equipment, quarters, rooms, lot or space, etc.
B8: To be furnished at the | D8: BATANES STATE COLLEGE
D9: (State place or site of Office or project where articles or services be furnished or returned)
A11: NAME OF ARTICLES OR SERVICES TO BE FURNISHED, RENDERED OR FACILITIES TO BE RENTED
F14: JPM Gen. Mdse. & Hardware
F15: Thine-line Trading
F16: J-Tech Trading & Services
F17: Mulong Ydel
F18: MDAC Trading & Compuserve
F19: FVA Gen Mdse & Construction Supply
F20: MKM Hardware
F21: GDP Trading
F22: EA Amboy Gen Mdse
F23: L & R's Hontomin Gen Mdse
F24: Davocol's Gen. Mdse.
F25: RCJ Hardware & Gen Mdse
... F86: Valiente Food Producer
F87: GMPI Construction OPC | G87: REMAR Construction | H87: Swift Devt. & Supplies Corp. | I87: JF Gabotero Inc. | J87: MOJR Construction Trading & General Services, Ltd, Co.
A89: =PR!D16 -> DAY 1-Opening Day | F89: withdrawn their quotation | G89: none | H89: no bid | I89: none | J89: no bid
A99: =PR!D26 -> Coffee (Twin Pack)
A100: =PR!D27 -> Assorted Biscuits
A103: =[1]PR!D30 -> 0 | B103: Bond paper, A4 size | C103: Bond paper, A4 size | D103: Bond paper, A4 size | E103: Bond paper, A4 size | F103: =[1]DATA!O29 -> 1400 | G103: none | H103: none
A104: =[1]PR!D31 -> 0 | B104: Bond paper, A4 size | C104: Bond paper, A4 size | D104: Bond paper, A4 size | E104: Bond paper, A4 size | F104: =[1]DATA!O30 -> 1300 | G104: none | H104: none
A105: =[1]PR!D32 -> 0 | B105: Bond paper, A4 size | C105: Bond paper, A4 size | D105: Bond paper, A4 size | E105: Bond paper, A4 size | F105: =[1]DATA!O31 -> 3600 | G105: none | H105: none
A106: =[1]PR!D33 -> 0 | B106: Bond paper, A4 size | C106: Bond paper, A4 size | D106: Bond paper, A4 size | E106: Bond paper, A4 size | F106: 1100 | G106: none | H106: none
A107: =[1]PR!D34 -> 0 | B107: Bond paper, A4 size | C107: Bond paper, A4 size | D107: Bond paper, A4 size | E107: Bond paper, A4 size | F107: =[1]DATA!O33 -> 2400 | G107: none | H107: none
A108: =[1]PR!D35 -> 0 | B108: Bond paper, A4 size | C108: Bond paper, A4 size | D108: Bond paper, A4 size | E108: Bond paper, A4 size | F108: =[1]DATA!O34 -> 150 | G108: none | H108: none
A109: =[1]PR!D36 -> 0 | B109: Bond paper, A4 size | C109: Bond paper, A4 size | D109: Bond paper, A4 size | E109: Bond paper, A4 size | F109: =[1]DATA!O35 -> 165 | G109: none | H109: none
A110: =[1]PR!D37 -> 0 | B110: Bond paper, A4 size | C110: Bond paper, A4 size | D110: Bond paper, A4 size | E110: Bond paper, A4 size | F110: =[1]DATA!O36 -> 1225 | G110: none | H110: none
A111: =[1]PR!D38 -> 0 | B111: Bond paper, A4 size | C111: Bond paper, A4 size | D111: Bond paper, A4 size | E111: Bond paper, A4 size | F111: =[1]DATA!O37 -> 1350 | G111: none | H111: none
A112: =[1]PR!D39 -> 0 | B112: Bond paper, A4 size | C112: Bond paper, A4 size | D112: Bond paper, A4 size | E112: Bond paper, A4 size | F112: =[1]DATA!O38 -> 1225 | G112: none | H112: none
A113: =[1]PR!D40 -> 0 | B113: Bond paper, A4 size | C113: Bond paper, A4 size | D113: Bond paper, A4 size | E113: Bond paper, A4 size | F113: =[1]DATA!O39 -> 2200 | G113: none | H113: none
A114: =[1]PR!D41 -> 0 | B114: Bond paper, A4 size | C114: Bond paper, A4 size | D114: Bond paper, A4 size | E114: Bond paper, A4 size | F114: =[1]DATA!O40 -> 1050 | G114: none | H114: none
A115: =[1]PR!D42 -> 0 | B115: Bond paper, A4 size | C115: Bond paper, A4 size | D115: Bond paper, A4 size | E115: Bond paper, A4 size | F115: =[1]DATA!O41 -> 440 | G115: none | H115: none
A116: =[1]PR!D43 -> 0 | B116: Bond paper, A4 size | C116: Bond paper, A4 size | D116: Bond paper, A4 size | E116: Bond paper, A4 size | F116: =[1]DATA!O42 -> 1500 | G116: none | H116: none
A117: =[1]PR!D44 -> 0 | B117: Bond paper, A4 size | C117: Bond paper, A4 size | D117: Bond paper, A4 size | E117: Bond paper, A4 size | F117: =[1]DATA!O43 -> 2200 | G117: none | H117: none
A118: =[1]PR!D45 -> 0 | B118: Bond paper, A4 size | C118: Bond paper, A4 size | D118: Bond paper, A4 size | E118: Bond paper, A4 size | F118: =[1]DATA!O44 -> 2040 | G118: none | H118: none
...

Sheet LON
A6: BIDS AND AWARDS COMMITTEE
A8: LETTER OF NOTICE
A11: DALE ANTHONY C. GUITIERREZ
A12: Owner
A13: IBS Pharmacy & General Merchandise
A14: Brgy. Kayvaluganan, Batanes
A17: Madam/Sir:
A18: We are happy to notify you that your quotation dated September 8, 2025 for the Internet Service Provider Subscription with PR # 2509-1005-306 contract price equivalent to FORTY THOUSAND FIVE HUNDRED PESOS ONLY (Php 40,500.00) is hereby accepted.
A19: You are hereby required to provide within Ten (10) days a certified photocopy of the following requirements:
A20: .
B21: 1. Updated Mayor's Permit/Business Permit
B22: 2. PhilGEPS Registration no.
B23: 3. Latest Income/Business Tax Return (ITR)
B24: 4. Duly Notarized Omnibus Sworn Statement
B25: 5. BIR 2302 Certificate of Registration (COR)
B26: 6. Updated DTI Registration
B27: 7. Landbank Account details of the business (for payment purposes)
A29: However, If you already have a maintaining and updated file of the above-mentioned requirements in the BAC Office you may no longer require its re-submission (Annex "H", Appendix "A" Section III)
A31: *For individuals engaged under Sec. 53.6, 53.7, and 53.9 of the IRR of RA 9184, only the BIR Certificate of Registration shall be submitted in lieu of DTI Registration and Mayor’s Permit.
A32: Thank you
A34: Very truly yours,
